ERROR 2024-10-29 15:11:14,326 log Internal Server Error: /front/home/
Traceback (most recent call last):
  File "C:\Users\kevin\AppData\Roaming\Python\Python312\site-packages\django\core\handlers\exception.py", line 55, in inner
    response = get_response(request)
               ^^^^^^^^^^^^^^^^^^^^^
  File "C:\Users\kevin\AppData\Roaming\Python\Python312\site-packages\django\core\handlers\base.py", line 197, in _get_response
    response = wrapped_callback(request, *callback_args, **callback_kwargs)
               ^^^^^^^^^^^^^^^^^^^^^^^^^^^^^^^^^^^^^^^^^^^^^^^^^^^^^^^^^^^^
  File "C:\Users\kevin\Desktop\pantutienda-adp\front\views.py", line 132, in home
    return render(request, '404.html')  # Si no hay un objeto landing, renderiza una página de error o similar.
           ^^^^^^^^^^^^^^^^^^^^^^^^^^^
  File "C:\Users\kevin\AppData\Roaming\Python\Python312\site-packages\django\shortcuts.py", line 25, in render
    content = loader.render_to_string(template_name, context, request, using=using)
              ^^^^^^^^^^^^^^^^^^^^^^^^^^^^^^^^^^^^^^^^^^^^^^^^^^^^^^^^^^^^^^^^^^^^^
  File "C:\Users\kevin\AppData\Roaming\Python\Python312\site-packages\django\template\loader.py", line 61, in render_to_string
    template = get_template(template_name, using=using)
               ^^^^^^^^^^^^^^^^^^^^^^^^^^^^^^^^^^^^^^^^
  File "C:\Users\kevin\AppData\Roaming\Python\Python312\site-packages\django\template\loader.py", line 19, in get_template
    raise TemplateDoesNotExist(template_name, chain=chain)
django.template.exceptions.TemplateDoesNotExist: 404.html
ERROR 2024-10-29 15:11:14,330 basehttp "GET /front/home/ HTTP/1.1" 500 93898
ERROR 2024-10-29 15:11:14,437 log Internal Server Error: /front/home/
Traceback (most recent call last):
  File "C:\Users\kevin\AppData\Roaming\Python\Python312\site-packages\django\core\handlers\exception.py", line 55, in inner
    response = get_response(request)
               ^^^^^^^^^^^^^^^^^^^^^
  File "C:\Users\kevin\AppData\Roaming\Python\Python312\site-packages\django\core\handlers\base.py", line 197, in _get_response
    response = wrapped_callback(request, *callback_args, **callback_kwargs)
               ^^^^^^^^^^^^^^^^^^^^^^^^^^^^^^^^^^^^^^^^^^^^^^^^^^^^^^^^^^^^
  File "C:\Users\kevin\Desktop\pantutienda-adp\front\views.py", line 132, in home
    return render(request, '404.html')  # Si no hay un objeto landing, renderiza una página de error o similar.
           ^^^^^^^^^^^^^^^^^^^^^^^^^^^
  File "C:\Users\kevin\AppData\Roaming\Python\Python312\site-packages\django\shortcuts.py", line 25, in render
    content = loader.render_to_string(template_name, context, request, using=using)
              ^^^^^^^^^^^^^^^^^^^^^^^^^^^^^^^^^^^^^^^^^^^^^^^^^^^^^^^^^^^^^^^^^^^^^
  File "C:\Users\kevin\AppData\Roaming\Python\Python312\site-packages\django\template\loader.py", line 61, in render_to_string
    template = get_template(template_name, using=using)
               ^^^^^^^^^^^^^^^^^^^^^^^^^^^^^^^^^^^^^^^^
  File "C:\Users\kevin\AppData\Roaming\Python\Python312\site-packages\django\template\loader.py", line 19, in get_template
    raise TemplateDoesNotExist(template_name, chain=chain)
django.template.exceptions.TemplateDoesNotExist: 404.html
ERROR 2024-10-29 15:11:14,438 basehttp "GET /front/home/ HTTP/1.1" 500 93624
ERROR 2024-10-29 15:11:45,034 log Internal Server Error: /front/home/
Traceback (most recent call last):
  File "C:\Users\kevin\AppData\Roaming\Python\Python312\site-packages\django\core\handlers\exception.py", line 55, in inner
    response = get_response(request)
               ^^^^^^^^^^^^^^^^^^^^^
  File "C:\Users\kevin\AppData\Roaming\Python\Python312\site-packages\django\core\handlers\base.py", line 197, in _get_response
    response = wrapped_callback(request, *callback_args, **callback_kwargs)
               ^^^^^^^^^^^^^^^^^^^^^^^^^^^^^^^^^^^^^^^^^^^^^^^^^^^^^^^^^^^^
  File "C:\Users\kevin\Desktop\pantutienda-adp\front\views.py", line 132, in home
    return render(request, '404.html')  # Si no hay un objeto landing, renderiza una página de error o similar.
           ^^^^^^^^^^^^^^^^^^^^^^^^^^^
  File "C:\Users\kevin\AppData\Roaming\Python\Python312\site-packages\django\shortcuts.py", line 25, in render
    content = loader.render_to_string(template_name, context, request, using=using)
              ^^^^^^^^^^^^^^^^^^^^^^^^^^^^^^^^^^^^^^^^^^^^^^^^^^^^^^^^^^^^^^^^^^^^^
  File "C:\Users\kevin\AppData\Roaming\Python\Python312\site-packages\django\template\loader.py", line 61, in render_to_string
    template = get_template(template_name, using=using)
               ^^^^^^^^^^^^^^^^^^^^^^^^^^^^^^^^^^^^^^^^
  File "C:\Users\kevin\AppData\Roaming\Python\Python312\site-packages\django\template\loader.py", line 19, in get_template
    raise TemplateDoesNotExist(template_name, chain=chain)
django.template.exceptions.TemplateDoesNotExist: 404.html
ERROR 2024-10-29 15:11:45,034 basehttp "GET /front/home/ HTTP/1.1" 500 93898
ERROR 2024-10-29 15:11:55,083 log Internal Server Error: /front/home/
Traceback (most recent call last):
  File "C:\Users\kevin\AppData\Roaming\Python\Python312\site-packages\django\core\handlers\exception.py", line 55, in inner
    response = get_response(request)
               ^^^^^^^^^^^^^^^^^^^^^
  File "C:\Users\kevin\AppData\Roaming\Python\Python312\site-packages\django\core\handlers\base.py", line 197, in _get_response
    response = wrapped_callback(request, *callback_args, **callback_kwargs)
               ^^^^^^^^^^^^^^^^^^^^^^^^^^^^^^^^^^^^^^^^^^^^^^^^^^^^^^^^^^^^
  File "C:\Users\kevin\Desktop\pantutienda-adp\front\views.py", line 132, in home
    return render(request, '404.html')  # Si no hay un objeto landing, renderiza una página de error o similar.
           ^^^^^^^^^^^^^^^^^^^^^^^^^^^
  File "C:\Users\kevin\AppData\Roaming\Python\Python312\site-packages\django\shortcuts.py", line 25, in render
    content = loader.render_to_string(template_name, context, request, using=using)
              ^^^^^^^^^^^^^^^^^^^^^^^^^^^^^^^^^^^^^^^^^^^^^^^^^^^^^^^^^^^^^^^^^^^^^
  File "C:\Users\kevin\AppData\Roaming\Python\Python312\site-packages\django\template\loader.py", line 61, in render_to_string
    template = get_template(template_name, using=using)
               ^^^^^^^^^^^^^^^^^^^^^^^^^^^^^^^^^^^^^^^^
  File "C:\Users\kevin\AppData\Roaming\Python\Python312\site-packages\django\template\loader.py", line 19, in get_template
    raise TemplateDoesNotExist(template_name, chain=chain)
django.template.exceptions.TemplateDoesNotExist: 404.html
ERROR 2024-10-29 15:11:55,086 basehttp "GET /front/home/ HTTP/1.1" 500 93761
ERROR 2024-10-29 18:55:52,168 log Internal Server Error: /front/home/
Traceback (most recent call last):
  File "C:\Users\kevin\AppData\Roaming\Python\Python312\site-packages\django\core\handlers\exception.py", line 55, in inner
    response = get_response(request)
               ^^^^^^^^^^^^^^^^^^^^^
  File "C:\Users\kevin\AppData\Roaming\Python\Python312\site-packages\django\core\handlers\base.py", line 197, in _get_response
    response = wrapped_callback(request, *callback_args, **callback_kwargs)
               ^^^^^^^^^^^^^^^^^^^^^^^^^^^^^^^^^^^^^^^^^^^^^^^^^^^^^^^^^^^^
  File "C:\Users\kevin\Desktop\pantutienda-adp\front\views.py", line 145, in home
    return render(request, 'onboarding_2.html',context)  # Si no hay un objeto landing, renderiza una página de error o similar.
           ^^^^^^^^^^^^^^^^^^^^^^^^^^^^^^^^^^^^^^^^^^^^
  File "C:\Users\kevin\AppData\Roaming\Python\Python312\site-packages\django\shortcuts.py", line 25, in render
    content = loader.render_to_string(template_name, context, request, using=using)
              ^^^^^^^^^^^^^^^^^^^^^^^^^^^^^^^^^^^^^^^^^^^^^^^^^^^^^^^^^^^^^^^^^^^^^
  File "C:\Users\kevin\AppData\Roaming\Python\Python312\site-packages\django\template\loader.py", line 62, in render_to_string
    return template.render(context, request)
           ^^^^^^^^^^^^^^^^^^^^^^^^^^^^^^^^^
  File "C:\Users\kevin\AppData\Roaming\Python\Python312\site-packages\django\template\backends\django.py", line 61, in render
    return self.template.render(context)
           ^^^^^^^^^^^^^^^^^^^^^^^^^^^^^
  File "C:\Users\kevin\AppData\Roaming\Python\Python312\site-packages\django\template\base.py", line 171, in render
    return self._render(context)
           ^^^^^^^^^^^^^^^^^^^^^
  File "C:\Users\kevin\AppData\Roaming\Python\Python312\site-packages\django\template\base.py", line 163, in _render
    return self.nodelist.render(context)
           ^^^^^^^^^^^^^^^^^^^^^^^^^^^^^
  File "C:\Users\kevin\AppData\Roaming\Python\Python312\site-packages\django\template\base.py", line 1000, in render
    return SafeString("".join([node.render_annotated(context) for node in self]))
                               ^^^^^^^^^^^^^^^^^^^^^^^^^^^^^^
  File "C:\Users\kevin\AppData\Roaming\Python\Python312\site-packages\django\template\base.py", line 961, in render_annotated
    return self.render(context)
           ^^^^^^^^^^^^^^^^^^^^
  File "C:\Users\kevin\AppData\Roaming\Python\Python312\site-packages\django\template\defaulttags.py", line 479, in render
    url = reverse(view_name, args=args, kwargs=kwargs, current_app=current_app)
          ^^^^^^^^^^^^^^^^^^^^^^^^^^^^^^^^^^^^^^^^^^^^^^^^^^^^^^^^^^^^^^^^^^^^^
  File "C:\Users\kevin\AppData\Roaming\Python\Python312\site-packages\django\urls\base.py", line 88, in reverse
    return resolver._reverse_with_prefix(view, prefix, *args, **kwargs)
           ^^^^^^^^^^^^^^^^^^^^^^^^^^^^^^^^^^^^^^^^^^^^^^^^^^^^^^^^^^^^
  File "C:\Users\kevin\AppData\Roaming\Python\Python312\site-packages\django\urls\resolvers.py", line 851, in _reverse_with_prefix
    raise NoReverseMatch(msg)
django.urls.exceptions.NoReverseMatch: Reverse for 'onboarding' not found. 'onboarding' is not a valid view function or pattern name.
ERROR 2024-10-29 18:55:52,173 basehttp "GET /front/home/ HTTP/1.1" 500 133483
ERROR 2024-10-29 19:24:07,457 log Internal Server Error: /front/onboarding/
Traceback (most recent call last):
  File "C:\Users\kevin\AppData\Roaming\Python\Python312\site-packages\django\core\handlers\exception.py", line 55, in inner
    response = get_response(request)
               ^^^^^^^^^^^^^^^^^^^^^
  File "C:\Users\kevin\AppData\Roaming\Python\Python312\site-packages\django\core\handlers\base.py", line 197, in _get_response
    response = wrapped_callback(request, *callback_args, **callback_kwargs)
               ^^^^^^^^^^^^^^^^^^^^^^^^^^^^^^^^^^^^^^^^^^^^^^^^^^^^^^^^^^^^
  File "C:\Users\kevin\Desktop\pantutienda-adp\configuracion\views.py", line 31, in onboarding
    return render(request, 'onboarding_1.html', context)
           ^^^^^^^^^^^^^^^^^^^^^^^^^^^^^^^^^^^^^^^^^^^^^
  File "C:\Users\kevin\AppData\Roaming\Python\Python312\site-packages\django\shortcuts.py", line 25, in render
    content = loader.render_to_string(template_name, context, request, using=using)
              ^^^^^^^^^^^^^^^^^^^^^^^^^^^^^^^^^^^^^^^^^^^^^^^^^^^^^^^^^^^^^^^^^^^^^
  File "C:\Users\kevin\AppData\Roaming\Python\Python312\site-packages\django\template\loader.py", line 61, in render_to_string
    template = get_template(template_name, using=using)
               ^^^^^^^^^^^^^^^^^^^^^^^^^^^^^^^^^^^^^^^^
  File "C:\Users\kevin\AppData\Roaming\Python\Python312\site-packages\django\template\loader.py", line 19, in get_template
    raise TemplateDoesNotExist(template_name, chain=chain)
django.template.exceptions.TemplateDoesNotExist: onboarding_1.html
ERROR 2024-10-29 19:24:07,460 basehttp "POST /front/onboarding/ HTTP/1.1" 500 96528
ERROR 2024-10-29 19:43:00,882 log Internal Server Error: /front/home/
Traceback (most recent call last):
  File "C:\Users\kevin\AppData\Roaming\Python\Python312\site-packages\django\core\handlers\exception.py", line 55, in inner
    response = get_response(request)
               ^^^^^^^^^^^^^^^^^^^^^
  File "C:\Users\kevin\AppData\Roaming\Python\Python312\site-packages\django\core\handlers\base.py", line 197, in _get_response
    response = wrapped_callback(request, *callback_args, **callback_kwargs)
               ^^^^^^^^^^^^^^^^^^^^^^^^^^^^^^^^^^^^^^^^^^^^^^^^^^^^^^^^^^^^
  File "C:\Users\kevin\Desktop\pantutienda-adp\front\views.py", line 132, in home
    configuracion = configuracion.objects.first()  # Asegúrate de que haya una landing en la base de datos
                    ^^^^^^^^^^^^^
UnboundLocalError: cannot access local variable 'configuracion' where it is not associated with a value
ERROR 2024-10-29 19:43:00,882 basehttp "GET /front/home/ HTTP/1.1" 500 77242
ERROR 2024-10-29 19:43:50,362 log Internal Server Error: /front/home/
Traceback (most recent call last):
  File "C:\Users\kevin\AppData\Roaming\Python\Python312\site-packages\django\core\handlers\exception.py", line 55, in inner
    response = get_response(request)
               ^^^^^^^^^^^^^^^^^^^^^
  File "C:\Users\kevin\AppData\Roaming\Python\Python312\site-packages\django\core\handlers\base.py", line 197, in _get_response
    response = wrapped_callback(request, *callback_args, **callback_kwargs)
               ^^^^^^^^^^^^^^^^^^^^^^^^^^^^^^^^^^^^^^^^^^^^^^^^^^^^^^^^^^^^
  File "C:\Users\kevin\Desktop\pantutienda-adp\front\views.py", line 132, in home
    configuracion = configuracion.objects.first()  # Asegúrate de que haya una landing en la base de datos
                    ^^^^^^^^^^^^^
UnboundLocalError: cannot access local variable 'configuracion' where it is not associated with a value
ERROR 2024-10-29 19:43:50,363 basehttp "GET /front/home/ HTTP/1.1" 500 77242
ERROR 2024-10-29 19:43:50,896 log Internal Server Error: /front/home/
Traceback (most recent call last):
  File "C:\Users\kevin\AppData\Roaming\Python\Python312\site-packages\django\core\handlers\exception.py", line 55, in inner
    response = get_response(request)
               ^^^^^^^^^^^^^^^^^^^^^
  File "C:\Users\kevin\AppData\Roaming\Python\Python312\site-packages\django\core\handlers\base.py", line 197, in _get_response
    response = wrapped_callback(request, *callback_args, **callback_kwargs)
               ^^^^^^^^^^^^^^^^^^^^^^^^^^^^^^^^^^^^^^^^^^^^^^^^^^^^^^^^^^^^
  File "C:\Users\kevin\Desktop\pantutienda-adp\front\views.py", line 132, in home
    configuracion = configuracion.objects.first()  # Asegúrate de que haya una landing en la base de datos
                    ^^^^^^^^^^^^^
UnboundLocalError: cannot access local variable 'configuracion' where it is not associated with a value
ERROR 2024-10-29 19:43:50,897 basehttp "GET /front/home/ HTTP/1.1" 500 76968
ERROR 2024-10-29 20:49:47,221 log Internal Server Error: /app/inventario/producto/
Traceback (most recent call last):
  File "C:\Users\kevin\AppData\Roaming\Python\Python312\site-packages\django\core\handlers\exception.py", line 55, in inner
    response = get_response(request)
               ^^^^^^^^^^^^^^^^^^^^^
  File "C:\Users\kevin\AppData\Roaming\Python\Python312\site-packages\django\core\handlers\base.py", line 197, in _get_response
    response = wrapped_callback(request, *callback_args, **callback_kwargs)
               ^^^^^^^^^^^^^^^^^^^^^^^^^^^^^^^^^^^^^^^^^^^^^^^^^^^^^^^^^^^^
  File "C:\Users\kevin\AppData\Roaming\Python\Python312\site-packages\django\contrib\admin\options.py", line 716, in wrapper
    return self.admin_site.admin_view(view)(*args, **kwargs)
           ^^^^^^^^^^^^^^^^^^^^^^^^^^^^^^^^^^^^^^^^^^^^^^^^^
  File "C:\Users\kevin\AppData\Roaming\Python\Python312\site-packages\django\utils\decorators.py", line 188, in _view_wrapper
    result = _process_exception(request, e)
             ^^^^^^^^^^^^^^^^^^^^^^^^^^^^^^
  File "C:\Users\kevin\AppData\Roaming\Python\Python312\site-packages\django\utils\decorators.py", line 186, in _view_wrapper
    response = view_func(request, *args, **kwargs)
               ^^^^^^^^^^^^^^^^^^^^^^^^^^^^^^^^^^^
  File "C:\Users\kevin\AppData\Roaming\Python\Python312\site-packages\django\views\decorators\cache.py", line 80, in _view_wrapper
    response = view_func(request, *args, **kwargs)
               ^^^^^^^^^^^^^^^^^^^^^^^^^^^^^^^^^^^
  File "C:\Users\kevin\AppData\Roaming\Python\Python312\site-packages\django\contrib\admin\sites.py", line 240, in inner
    return view(request, *args, **kwargs)
           ^^^^^^^^^^^^^^^^^^^^^^^^^^^^^^
  File "C:\Users\kevin\Desktop\pantutienda-adp\inventario\admin.py", line 333, in changelist_view
    moneda=configuracion.objects.first().Moneda.signo
           ^^^^^^^^^^^^^^^^^^^^^^^^^^^^^^^^^^^^
AttributeError: 'NoneType' object has no attribute 'Moneda'
ERROR 2024-10-29 20:49:47,252 basehttp "GET /app/inventario/producto/ HTTP/1.1" 500 101783
ERROR 2024-10-29 21:55:18,426 log Internal Server Error: /app/auth/user/add/
Traceback (most recent call last):
  File "C:\Users\kevin\AppData\Roaming\Python\Python312\site-packages\django\db\backends\base\base.py", line 299, in _commit
    return self.connection.commit()
           ^^^^^^^^^^^^^^^^^^^^^^^^
sqlite3.IntegrityError: FOREIGN KEY constraint failed

The above exception was the direct cause of the following exception:

Traceback (most recent call last):
  File "C:\Users\kevin\AppData\Roaming\Python\Python312\site-packages\django\core\handlers\exception.py", line 55, in inner
    response = get_response(request)
               ^^^^^^^^^^^^^^^^^^^^^
  File "C:\Users\kevin\AppData\Roaming\Python\Python312\site-packages\django\core\handlers\base.py", line 197, in _get_response
    response = wrapped_callback(request, *callback_args, **callback_kwargs)
               ^^^^^^^^^^^^^^^^^^^^^^^^^^^^^^^^^^^^^^^^^^^^^^^^^^^^^^^^^^^^
  File "C:\Users\kevin\AppData\Roaming\Python\Python312\site-packages\django\contrib\admin\options.py", line 716, in wrapper
    return self.admin_site.admin_view(view)(*args, **kwargs)
           ^^^^^^^^^^^^^^^^^^^^^^^^^^^^^^^^^^^^^^^^^^^^^^^^^
  File "C:\Users\kevin\AppData\Roaming\Python\Python312\site-packages\django\utils\decorators.py", line 188, in _view_wrapper
    result = _process_exception(request, e)
             ^^^^^^^^^^^^^^^^^^^^^^^^^^^^^^
  File "C:\Users\kevin\AppData\Roaming\Python\Python312\site-packages\django\utils\decorators.py", line 186, in _view_wrapper
    response = view_func(request, *args, **kwargs)
               ^^^^^^^^^^^^^^^^^^^^^^^^^^^^^^^^^^^
  File "C:\Users\kevin\AppData\Roaming\Python\Python312\site-packages\django\views\decorators\cache.py", line 80, in _view_wrapper
    response = view_func(request, *args, **kwargs)
               ^^^^^^^^^^^^^^^^^^^^^^^^^^^^^^^^^^^
  File "C:\Users\kevin\AppData\Roaming\Python\Python312\site-packages\django\contrib\admin\sites.py", line 240, in inner
    return view(request, *args, **kwargs)
           ^^^^^^^^^^^^^^^^^^^^^^^^^^^^^^
  File "C:\Users\kevin\AppData\Roaming\Python\Python312\site-packages\django\utils\decorators.py", line 48, in _wrapper
    return bound_method(*args, **kwargs)
           ^^^^^^^^^^^^^^^^^^^^^^^^^^^^^
  File "C:\Users\kevin\AppData\Roaming\Python\Python312\site-packages\django\views\decorators\debug.py", line 143, in sensitive_post_parameters_wrapper
    return view(request, *args, **kwargs)
           ^^^^^^^^^^^^^^^^^^^^^^^^^^^^^^
  File "C:\Users\kevin\AppData\Roaming\Python\Python312\site-packages\django\utils\decorators.py", line 48, in _wrapper
    return bound_method(*args, **kwargs)
           ^^^^^^^^^^^^^^^^^^^^^^^^^^^^^
  File "C:\Users\kevin\AppData\Roaming\Python\Python312\site-packages\django\utils\decorators.py", line 188, in _view_wrapper
    result = _process_exception(request, e)
             ^^^^^^^^^^^^^^^^^^^^^^^^^^^^^^
  File "C:\Users\kevin\AppData\Roaming\Python\Python312\site-packages\django\utils\decorators.py", line 186, in _view_wrapper
    response = view_func(request, *args, **kwargs)
               ^^^^^^^^^^^^^^^^^^^^^^^^^^^^^^^^^^^
  File "C:\Users\kevin\AppData\Roaming\Python\Python312\site-packages\django\contrib\auth\admin.py", line 120, in add_view
    with transaction.atomic(using=router.db_for_write(self.model)):
  File "C:\Users\kevin\AppData\Roaming\Python\Python312\site-packages\django\db\transaction.py", line 263, in __exit__
    connection.commit()
  File "C:\Users\kevin\AppData\Roaming\Python\Python312\site-packages\django\utils\asyncio.py", line 26, in inner
    return func(*args, **kwargs)
           ^^^^^^^^^^^^^^^^^^^^^
  File "C:\Users\kevin\AppData\Roaming\Python\Python312\site-packages\django\db\backends\base\base.py", line 323, in commit
    self._commit()
  File "C:\Users\kevin\AppData\Roaming\Python\Python312\site-packages\django\db\backends\base\base.py", line 298, in _commit
    with debug_transaction(self, "COMMIT"), self.wrap_database_errors:
  File "C:\Users\kevin\AppData\Roaming\Python\Python312\site-packages\django\db\utils.py", line 91, in __exit__
    raise dj_exc_value.with_traceback(traceback) from exc_value
  File "C:\Users\kevin\AppData\Roaming\Python\Python312\site-packages\django\db\backends\base\base.py", line 299, in _commit
    return self.connection.commit()
           ^^^^^^^^^^^^^^^^^^^^^^^^
django.db.utils.IntegrityError: FOREIGN KEY constraint failed
ERROR 2024-10-29 21:55:18,431 basehttp "POST /app/auth/user/add/?_to_field=id&_popup=1 HTTP/1.1" 500 159622
ERROR 2024-10-29 21:55:42,024 log Internal Server Error: /app/auth/user/add/
Traceback (most recent call last):
  File "C:\Users\kevin\AppData\Roaming\Python\Python312\site-packages\django\db\backends\base\base.py", line 299, in _commit
    return self.connection.commit()
           ^^^^^^^^^^^^^^^^^^^^^^^^
sqlite3.IntegrityError: FOREIGN KEY constraint failed

The above exception was the direct cause of the following exception:

Traceback (most recent call last):
  File "C:\Users\kevin\AppData\Roaming\Python\Python312\site-packages\django\core\handlers\exception.py", line 55, in inner
    response = get_response(request)
               ^^^^^^^^^^^^^^^^^^^^^
  File "C:\Users\kevin\AppData\Roaming\Python\Python312\site-packages\django\core\handlers\base.py", line 197, in _get_response
    response = wrapped_callback(request, *callback_args, **callback_kwargs)
               ^^^^^^^^^^^^^^^^^^^^^^^^^^^^^^^^^^^^^^^^^^^^^^^^^^^^^^^^^^^^
  File "C:\Users\kevin\AppData\Roaming\Python\Python312\site-packages\django\contrib\admin\options.py", line 716, in wrapper
    return self.admin_site.admin_view(view)(*args, **kwargs)
           ^^^^^^^^^^^^^^^^^^^^^^^^^^^^^^^^^^^^^^^^^^^^^^^^^
  File "C:\Users\kevin\AppData\Roaming\Python\Python312\site-packages\django\utils\decorators.py", line 188, in _view_wrapper
    result = _process_exception(request, e)
             ^^^^^^^^^^^^^^^^^^^^^^^^^^^^^^
  File "C:\Users\kevin\AppData\Roaming\Python\Python312\site-packages\django\utils\decorators.py", line 186, in _view_wrapper
    response = view_func(request, *args, **kwargs)
               ^^^^^^^^^^^^^^^^^^^^^^^^^^^^^^^^^^^
  File "C:\Users\kevin\AppData\Roaming\Python\Python312\site-packages\django\views\decorators\cache.py", line 80, in _view_wrapper
    response = view_func(request, *args, **kwargs)
               ^^^^^^^^^^^^^^^^^^^^^^^^^^^^^^^^^^^
  File "C:\Users\kevin\AppData\Roaming\Python\Python312\site-packages\django\contrib\admin\sites.py", line 240, in inner
    return view(request, *args, **kwargs)
           ^^^^^^^^^^^^^^^^^^^^^^^^^^^^^^
  File "C:\Users\kevin\AppData\Roaming\Python\Python312\site-packages\django\utils\decorators.py", line 48, in _wrapper
    return bound_method(*args, **kwargs)
           ^^^^^^^^^^^^^^^^^^^^^^^^^^^^^
  File "C:\Users\kevin\AppData\Roaming\Python\Python312\site-packages\django\views\decorators\debug.py", line 143, in sensitive_post_parameters_wrapper
    return view(request, *args, **kwargs)
           ^^^^^^^^^^^^^^^^^^^^^^^^^^^^^^
  File "C:\Users\kevin\AppData\Roaming\Python\Python312\site-packages\django\utils\decorators.py", line 48, in _wrapper
    return bound_method(*args, **kwargs)
           ^^^^^^^^^^^^^^^^^^^^^^^^^^^^^
  File "C:\Users\kevin\AppData\Roaming\Python\Python312\site-packages\django\utils\decorators.py", line 188, in _view_wrapper
    result = _process_exception(request, e)
             ^^^^^^^^^^^^^^^^^^^^^^^^^^^^^^
  File "C:\Users\kevin\AppData\Roaming\Python\Python312\site-packages\django\utils\decorators.py", line 186, in _view_wrapper
    response = view_func(request, *args, **kwargs)
               ^^^^^^^^^^^^^^^^^^^^^^^^^^^^^^^^^^^
  File "C:\Users\kevin\AppData\Roaming\Python\Python312\site-packages\django\contrib\auth\admin.py", line 120, in add_view
    with transaction.atomic(using=router.db_for_write(self.model)):
  File "C:\Users\kevin\AppData\Roaming\Python\Python312\site-packages\django\db\transaction.py", line 263, in __exit__
    connection.commit()
  File "C:\Users\kevin\AppData\Roaming\Python\Python312\site-packages\django\utils\asyncio.py", line 26, in inner
    return func(*args, **kwargs)
           ^^^^^^^^^^^^^^^^^^^^^
  File "C:\Users\kevin\AppData\Roaming\Python\Python312\site-packages\django\db\backends\base\base.py", line 323, in commit
    self._commit()
  File "C:\Users\kevin\AppData\Roaming\Python\Python312\site-packages\django\db\backends\base\base.py", line 298, in _commit
    with debug_transaction(self, "COMMIT"), self.wrap_database_errors:
  File "C:\Users\kevin\AppData\Roaming\Python\Python312\site-packages\django\db\utils.py", line 91, in __exit__
    raise dj_exc_value.with_traceback(traceback) from exc_value
  File "C:\Users\kevin\AppData\Roaming\Python\Python312\site-packages\django\db\backends\base\base.py", line 299, in _commit
    return self.connection.commit()
           ^^^^^^^^^^^^^^^^^^^^^^^^
django.db.utils.IntegrityError: FOREIGN KEY constraint failed
ERROR 2024-10-29 21:55:42,026 basehttp "POST /app/auth/user/add/?_to_field=id&_popup=1 HTTP/1.1" 500 159615
ERROR 2024-10-29 21:55:59,027 log Internal Server Error: /app/auth/user/add/
Traceback (most recent call last):
  File "C:\Users\kevin\AppData\Roaming\Python\Python312\site-packages\django\db\backends\base\base.py", line 299, in _commit
    return self.connection.commit()
           ^^^^^^^^^^^^^^^^^^^^^^^^
sqlite3.IntegrityError: FOREIGN KEY constraint failed

The above exception was the direct cause of the following exception:

Traceback (most recent call last):
  File "C:\Users\kevin\AppData\Roaming\Python\Python312\site-packages\django\core\handlers\exception.py", line 55, in inner
    response = get_response(request)
               ^^^^^^^^^^^^^^^^^^^^^
  File "C:\Users\kevin\AppData\Roaming\Python\Python312\site-packages\django\core\handlers\base.py", line 197, in _get_response
    response = wrapped_callback(request, *callback_args, **callback_kwargs)
               ^^^^^^^^^^^^^^^^^^^^^^^^^^^^^^^^^^^^^^^^^^^^^^^^^^^^^^^^^^^^
  File "C:\Users\kevin\AppData\Roaming\Python\Python312\site-packages\django\contrib\admin\options.py", line 716, in wrapper
    return self.admin_site.admin_view(view)(*args, **kwargs)
           ^^^^^^^^^^^^^^^^^^^^^^^^^^^^^^^^^^^^^^^^^^^^^^^^^
  File "C:\Users\kevin\AppData\Roaming\Python\Python312\site-packages\django\utils\decorators.py", line 188, in _view_wrapper
    result = _process_exception(request, e)
             ^^^^^^^^^^^^^^^^^^^^^^^^^^^^^^
  File "C:\Users\kevin\AppData\Roaming\Python\Python312\site-packages\django\utils\decorators.py", line 186, in _view_wrapper
    response = view_func(request, *args, **kwargs)
               ^^^^^^^^^^^^^^^^^^^^^^^^^^^^^^^^^^^
  File "C:\Users\kevin\AppData\Roaming\Python\Python312\site-packages\django\views\decorators\cache.py", line 80, in _view_wrapper
    response = view_func(request, *args, **kwargs)
               ^^^^^^^^^^^^^^^^^^^^^^^^^^^^^^^^^^^
  File "C:\Users\kevin\AppData\Roaming\Python\Python312\site-packages\django\contrib\admin\sites.py", line 240, in inner
    return view(request, *args, **kwargs)
           ^^^^^^^^^^^^^^^^^^^^^^^^^^^^^^
  File "C:\Users\kevin\AppData\Roaming\Python\Python312\site-packages\django\utils\decorators.py", line 48, in _wrapper
    return bound_method(*args, **kwargs)
           ^^^^^^^^^^^^^^^^^^^^^^^^^^^^^
  File "C:\Users\kevin\AppData\Roaming\Python\Python312\site-packages\django\views\decorators\debug.py", line 143, in sensitive_post_parameters_wrapper
    return view(request, *args, **kwargs)
           ^^^^^^^^^^^^^^^^^^^^^^^^^^^^^^
  File "C:\Users\kevin\AppData\Roaming\Python\Python312\site-packages\django\utils\decorators.py", line 48, in _wrapper
    return bound_method(*args, **kwargs)
           ^^^^^^^^^^^^^^^^^^^^^^^^^^^^^
  File "C:\Users\kevin\AppData\Roaming\Python\Python312\site-packages\django\utils\decorators.py", line 188, in _view_wrapper
    result = _process_exception(request, e)
             ^^^^^^^^^^^^^^^^^^^^^^^^^^^^^^
  File "C:\Users\kevin\AppData\Roaming\Python\Python312\site-packages\django\utils\decorators.py", line 186, in _view_wrapper
    response = view_func(request, *args, **kwargs)
               ^^^^^^^^^^^^^^^^^^^^^^^^^^^^^^^^^^^
  File "C:\Users\kevin\AppData\Roaming\Python\Python312\site-packages\django\contrib\auth\admin.py", line 120, in add_view
    with transaction.atomic(using=router.db_for_write(self.model)):
  File "C:\Users\kevin\AppData\Roaming\Python\Python312\site-packages\django\db\transaction.py", line 263, in __exit__
    connection.commit()
  File "C:\Users\kevin\AppData\Roaming\Python\Python312\site-packages\django\utils\asyncio.py", line 26, in inner
    return func(*args, **kwargs)
           ^^^^^^^^^^^^^^^^^^^^^
  File "C:\Users\kevin\AppData\Roaming\Python\Python312\site-packages\django\db\backends\base\base.py", line 323, in commit
    self._commit()
  File "C:\Users\kevin\AppData\Roaming\Python\Python312\site-packages\django\db\backends\base\base.py", line 298, in _commit
    with debug_transaction(self, "COMMIT"), self.wrap_database_errors:
  File "C:\Users\kevin\AppData\Roaming\Python\Python312\site-packages\django\db\utils.py", line 91, in __exit__
    raise dj_exc_value.with_traceback(traceback) from exc_value
  File "C:\Users\kevin\AppData\Roaming\Python\Python312\site-packages\django\db\backends\base\base.py", line 299, in _commit
    return self.connection.commit()
           ^^^^^^^^^^^^^^^^^^^^^^^^
django.db.utils.IntegrityError: FOREIGN KEY constraint failed
ERROR 2024-10-29 21:55:59,030 basehttp "POST /app/auth/user/add/ HTTP/1.1" 500 158615
ERROR 2024-10-29 21:56:59,885 log Internal Server Error: /app/auth/user/add/
Traceback (most recent call last):
  File "C:\Users\kevin\AppData\Roaming\Python\Python312\site-packages\django\db\backends\base\base.py", line 299, in _commit
    return self.connection.commit()
           ^^^^^^^^^^^^^^^^^^^^^^^^
sqlite3.IntegrityError: FOREIGN KEY constraint failed

The above exception was the direct cause of the following exception:

Traceback (most recent call last):
  File "C:\Users\kevin\AppData\Roaming\Python\Python312\site-packages\django\core\handlers\exception.py", line 55, in inner
    response = get_response(request)
               ^^^^^^^^^^^^^^^^^^^^^
  File "C:\Users\kevin\AppData\Roaming\Python\Python312\site-packages\django\core\handlers\base.py", line 197, in _get_response
    response = wrapped_callback(request, *callback_args, **callback_kwargs)
               ^^^^^^^^^^^^^^^^^^^^^^^^^^^^^^^^^^^^^^^^^^^^^^^^^^^^^^^^^^^^
  File "C:\Users\kevin\AppData\Roaming\Python\Python312\site-packages\django\contrib\admin\options.py", line 716, in wrapper
    return self.admin_site.admin_view(view)(*args, **kwargs)
           ^^^^^^^^^^^^^^^^^^^^^^^^^^^^^^^^^^^^^^^^^^^^^^^^^
  File "C:\Users\kevin\AppData\Roaming\Python\Python312\site-packages\django\utils\decorators.py", line 188, in _view_wrapper
    result = _process_exception(request, e)
             ^^^^^^^^^^^^^^^^^^^^^^^^^^^^^^
  File "C:\Users\kevin\AppData\Roaming\Python\Python312\site-packages\django\utils\decorators.py", line 186, in _view_wrapper
    response = view_func(request, *args, **kwargs)
               ^^^^^^^^^^^^^^^^^^^^^^^^^^^^^^^^^^^
  File "C:\Users\kevin\AppData\Roaming\Python\Python312\site-packages\django\views\decorators\cache.py", line 80, in _view_wrapper
    response = view_func(request, *args, **kwargs)
               ^^^^^^^^^^^^^^^^^^^^^^^^^^^^^^^^^^^
  File "C:\Users\kevin\AppData\Roaming\Python\Python312\site-packages\django\contrib\admin\sites.py", line 240, in inner
    return view(request, *args, **kwargs)
           ^^^^^^^^^^^^^^^^^^^^^^^^^^^^^^
  File "C:\Users\kevin\AppData\Roaming\Python\Python312\site-packages\django\utils\decorators.py", line 48, in _wrapper
    return bound_method(*args, **kwargs)
           ^^^^^^^^^^^^^^^^^^^^^^^^^^^^^
  File "C:\Users\kevin\AppData\Roaming\Python\Python312\site-packages\django\views\decorators\debug.py", line 143, in sensitive_post_parameters_wrapper
    return view(request, *args, **kwargs)
           ^^^^^^^^^^^^^^^^^^^^^^^^^^^^^^
  File "C:\Users\kevin\AppData\Roaming\Python\Python312\site-packages\django\utils\decorators.py", line 48, in _wrapper
    return bound_method(*args, **kwargs)
           ^^^^^^^^^^^^^^^^^^^^^^^^^^^^^
  File "C:\Users\kevin\AppData\Roaming\Python\Python312\site-packages\django\utils\decorators.py", line 188, in _view_wrapper
    result = _process_exception(request, e)
             ^^^^^^^^^^^^^^^^^^^^^^^^^^^^^^
  File "C:\Users\kevin\AppData\Roaming\Python\Python312\site-packages\django\utils\decorators.py", line 186, in _view_wrapper
    response = view_func(request, *args, **kwargs)
               ^^^^^^^^^^^^^^^^^^^^^^^^^^^^^^^^^^^
  File "C:\Users\kevin\AppData\Roaming\Python\Python312\site-packages\django\contrib\auth\admin.py", line 120, in add_view
    with transaction.atomic(using=router.db_for_write(self.model)):
  File "C:\Users\kevin\AppData\Roaming\Python\Python312\site-packages\django\db\transaction.py", line 263, in __exit__
    connection.commit()
  File "C:\Users\kevin\AppData\Roaming\Python\Python312\site-packages\django\utils\asyncio.py", line 26, in inner
    return func(*args, **kwargs)
           ^^^^^^^^^^^^^^^^^^^^^
  File "C:\Users\kevin\AppData\Roaming\Python\Python312\site-packages\django\db\backends\base\base.py", line 323, in commit
    self._commit()
  File "C:\Users\kevin\AppData\Roaming\Python\Python312\site-packages\django\db\backends\base\base.py", line 298, in _commit
    with debug_transaction(self, "COMMIT"), self.wrap_database_errors:
  File "C:\Users\kevin\AppData\Roaming\Python\Python312\site-packages\django\db\utils.py", line 91, in __exit__
    raise dj_exc_value.with_traceback(traceback) from exc_value
  File "C:\Users\kevin\AppData\Roaming\Python\Python312\site-packages\django\db\backends\base\base.py", line 299, in _commit
    return self.connection.commit()
           ^^^^^^^^^^^^^^^^^^^^^^^^
django.db.utils.IntegrityError: FOREIGN KEY constraint failed
ERROR 2024-10-29 21:56:59,890 basehttp "POST /app/auth/user/add/ HTTP/1.1" 500 158982
ERROR 2024-10-29 21:57:34,005 log Internal Server Error: /front/registro/
Traceback (most recent call last):
  File "C:\Users\kevin\AppData\Roaming\Python\Python312\site-packages\django\db\utils.py", line 98, in inner
    return func(*args, **kwargs)
           ^^^^^^^^^^^^^^^^^^^^^
sqlite3.IntegrityError: FOREIGN KEY constraint failed

The above exception was the direct cause of the following exception:

Traceback (most recent call last):
  File "C:\Users\kevin\AppData\Roaming\Python\Python312\site-packages\django\core\handlers\exception.py", line 55, in inner
    response = get_response(request)
               ^^^^^^^^^^^^^^^^^^^^^
  File "C:\Users\kevin\AppData\Roaming\Python\Python312\site-packages\django\core\handlers\base.py", line 197, in _get_response
    response = wrapped_callback(request, *callback_args, **callback_kwargs)
               ^^^^^^^^^^^^^^^^^^^^^^^^^^^^^^^^^^^^^^^^^^^^^^^^^^^^^^^^^^^^
  File "C:\Users\kevin\Desktop\pantutienda-adp\front\views.py", line 453, in registro
    user = User.objects.create_user(username=username, email=email, password=password)
           ^^^^^^^^^^^^^^^^^^^^^^^^^^^^^^^^^^^^^^^^^^^^^^^^^^^^^^^^^^^^^^^^^^^^^^^^^^^
  File "C:\Users\kevin\AppData\Roaming\Python\Python312\site-packages\django\contrib\auth\models.py", line 161, in create_user
    return self._create_user(username, email, password, **extra_fields)
           ^^^^^^^^^^^^^^^^^^^^^^^^^^^^^^^^^^^^^^^^^^^^^^^^^^^^^^^^^^^^
  File "C:\Users\kevin\AppData\Roaming\Python\Python312\site-packages\django\contrib\auth\models.py", line 155, in _create_user
    user.save(using=self._db)
  File "C:\Users\kevin\AppData\Roaming\Python\Python312\site-packages\django\contrib\auth\base_user.py", line 78, in save
    super().save(*args, **kwargs)
  File "C:\Users\kevin\AppData\Roaming\Python\Python312\site-packages\django\db\models\base.py", line 822, in save
    self.save_base(
  File "C:\Users\kevin\AppData\Roaming\Python\Python312\site-packages\django\db\models\base.py", line 924, in save_base
    post_save.send(
  File "C:\Users\kevin\AppData\Roaming\Python\Python312\site-packages\django\dispatch\dispatcher.py", line 189, in send
    response = receiver(signal=self, sender=sender, **named)
               ^^^^^^^^^^^^^^^^^^^^^^^^^^^^^^^^^^^^^^^^^^^^^
  File "C:\Users\kevin\Desktop\pantutienda-adp\agenda\signals.py", line 10, in crear_cliente
    nuevo_cliente=Cliente.objects.create(
                  ^^^^^^^^^^^^^^^^^^^^^^^
  File "C:\Users\kevin\AppData\Roaming\Python\Python312\site-packages\django\db\models\manager.py", line 87, in manager_method
    return getattr(self.get_queryset(), name)(*args, **kwargs)
           ^^^^^^^^^^^^^^^^^^^^^^^^^^^^^^^^^^^^^^^^^^^^^^^^^^^
  File "C:\Users\kevin\AppData\Roaming\Python\Python312\site-packages\django\db\models\query.py", line 679, in create
    obj.save(force_insert=True, using=self.db)
  File "C:\Users\kevin\AppData\Roaming\Python\Python312\site-packages\django\db\models\base.py", line 822, in save
    self.save_base(
  File "C:\Users\kevin\AppData\Roaming\Python\Python312\site-packages\django\db\models\base.py", line 909, in save_base
    updated = self._save_table(
              ^^^^^^^^^^^^^^^^^
  File "C:\Users\kevin\AppData\Roaming\Python\Python312\site-packages\django\db\models\base.py", line 1071, in _save_table
    results = self._do_insert(
              ^^^^^^^^^^^^^^^^
  File "C:\Users\kevin\AppData\Roaming\Python\Python312\site-packages\django\db\models\base.py", line 1112, in _do_insert
    return manager._insert(
           ^^^^^^^^^^^^^^^^
  File "C:\Users\kevin\AppData\Roaming\Python\Python312\site-packages\django\db\models\manager.py", line 87, in manager_method
    return getattr(self.get_queryset(), name)(*args, **kwargs)
           ^^^^^^^^^^^^^^^^^^^^^^^^^^^^^^^^^^^^^^^^^^^^^^^^^^^
  File "C:\Users\kevin\AppData\Roaming\Python\Python312\site-packages\django\db\models\query.py", line 1847, in _insert
    return query.get_compiler(using=using).execute_sql(returning_fields)
           ^^^^^^^^^^^^^^^^^^^^^^^^^^^^^^^^^^^^^^^^^^^^^^^^^^^^^^^^^^^^^
  File "C:\Users\kevin\AppData\Roaming\Python\Python312\site-packages\django\db\models\sql\compiler.py", line 1835, in execute_sql
    self.connection.ops.fetch_returned_insert_columns(
  File "C:\Users\kevin\AppData\Roaming\Python\Python312\site-packages\django\db\backends\base\operations.py", line 216, in fetch_returned_insert_columns
    return cursor.fetchone()
           ^^^^^^^^^^^^^^^^^
  File "C:\Users\kevin\AppData\Roaming\Python\Python312\site-packages\django\db\utils.py", line 97, in inner
    with self:
  File "C:\Users\kevin\AppData\Roaming\Python\Python312\site-packages\django\db\utils.py", line 91, in __exit__
    raise dj_exc_value.with_traceback(traceback) from exc_value
  File "C:\Users\kevin\AppData\Roaming\Python\Python312\site-packages\django\db\utils.py", line 98, in inner
    return func(*args, **kwargs)
           ^^^^^^^^^^^^^^^^^^^^^
django.db.utils.IntegrityError: FOREIGN KEY constraint failed
ERROR 2024-10-29 21:57:34,017 basehttp "POST /front/registro/ HTTP/1.1" 500 182088
ERROR 2024-10-29 22:06:30,313 log Internal Server Error: /app/auth/user/add/
Traceback (most recent call last):
  File "C:\Users\kevin\AppData\Roaming\Python\Python312\site-packages\django\db\backends\base\base.py", line 299, in _commit
    return self.connection.commit()
           ^^^^^^^^^^^^^^^^^^^^^^^^
sqlite3.IntegrityError: FOREIGN KEY constraint failed

The above exception was the direct cause of the following exception:

Traceback (most recent call last):
  File "C:\Users\kevin\AppData\Roaming\Python\Python312\site-packages\django\core\handlers\exception.py", line 55, in inner
    response = get_response(request)
               ^^^^^^^^^^^^^^^^^^^^^
  File "C:\Users\kevin\AppData\Roaming\Python\Python312\site-packages\django\core\handlers\base.py", line 197, in _get_response
    response = wrapped_callback(request, *callback_args, **callback_kwargs)
               ^^^^^^^^^^^^^^^^^^^^^^^^^^^^^^^^^^^^^^^^^^^^^^^^^^^^^^^^^^^^
  File "C:\Users\kevin\AppData\Roaming\Python\Python312\site-packages\django\contrib\admin\options.py", line 716, in wrapper
    return self.admin_site.admin_view(view)(*args, **kwargs)
           ^^^^^^^^^^^^^^^^^^^^^^^^^^^^^^^^^^^^^^^^^^^^^^^^^
  File "C:\Users\kevin\AppData\Roaming\Python\Python312\site-packages\django\utils\decorators.py", line 188, in _view_wrapper
    result = _process_exception(request, e)
             ^^^^^^^^^^^^^^^^^^^^^^^^^^^^^^
  File "C:\Users\kevin\AppData\Roaming\Python\Python312\site-packages\django\utils\decorators.py", line 186, in _view_wrapper
    response = view_func(request, *args, **kwargs)
               ^^^^^^^^^^^^^^^^^^^^^^^^^^^^^^^^^^^
  File "C:\Users\kevin\AppData\Roaming\Python\Python312\site-packages\django\views\decorators\cache.py", line 80, in _view_wrapper
    response = view_func(request, *args, **kwargs)
               ^^^^^^^^^^^^^^^^^^^^^^^^^^^^^^^^^^^
  File "C:\Users\kevin\AppData\Roaming\Python\Python312\site-packages\django\contrib\admin\sites.py", line 240, in inner
    return view(request, *args, **kwargs)
           ^^^^^^^^^^^^^^^^^^^^^^^^^^^^^^
  File "C:\Users\kevin\AppData\Roaming\Python\Python312\site-packages\django\utils\decorators.py", line 48, in _wrapper
    return bound_method(*args, **kwargs)
           ^^^^^^^^^^^^^^^^^^^^^^^^^^^^^
  File "C:\Users\kevin\AppData\Roaming\Python\Python312\site-packages\django\views\decorators\debug.py", line 143, in sensitive_post_parameters_wrapper
    return view(request, *args, **kwargs)
           ^^^^^^^^^^^^^^^^^^^^^^^^^^^^^^
  File "C:\Users\kevin\AppData\Roaming\Python\Python312\site-packages\django\utils\decorators.py", line 48, in _wrapper
    return bound_method(*args, **kwargs)
           ^^^^^^^^^^^^^^^^^^^^^^^^^^^^^
  File "C:\Users\kevin\AppData\Roaming\Python\Python312\site-packages\django\utils\decorators.py", line 188, in _view_wrapper
    result = _process_exception(request, e)
             ^^^^^^^^^^^^^^^^^^^^^^^^^^^^^^
  File "C:\Users\kevin\AppData\Roaming\Python\Python312\site-packages\django\utils\decorators.py", line 186, in _view_wrapper
    response = view_func(request, *args, **kwargs)
               ^^^^^^^^^^^^^^^^^^^^^^^^^^^^^^^^^^^
  File "C:\Users\kevin\AppData\Roaming\Python\Python312\site-packages\django\contrib\auth\admin.py", line 120, in add_view
    with transaction.atomic(using=router.db_for_write(self.model)):
  File "C:\Users\kevin\AppData\Roaming\Python\Python312\site-packages\django\db\transaction.py", line 263, in __exit__
    connection.commit()
  File "C:\Users\kevin\AppData\Roaming\Python\Python312\site-packages\django\utils\asyncio.py", line 26, in inner
    return func(*args, **kwargs)
           ^^^^^^^^^^^^^^^^^^^^^
  File "C:\Users\kevin\AppData\Roaming\Python\Python312\site-packages\django\db\backends\base\base.py", line 323, in commit
    self._commit()
  File "C:\Users\kevin\AppData\Roaming\Python\Python312\site-packages\django\db\backends\base\base.py", line 298, in _commit
    with debug_transaction(self, "COMMIT"), self.wrap_database_errors:
  File "C:\Users\kevin\AppData\Roaming\Python\Python312\site-packages\django\db\utils.py", line 91, in __exit__
    raise dj_exc_value.with_traceback(traceback) from exc_value
  File "C:\Users\kevin\AppData\Roaming\Python\Python312\site-packages\django\db\backends\base\base.py", line 299, in _commit
    return self.connection.commit()
           ^^^^^^^^^^^^^^^^^^^^^^^^
django.db.utils.IntegrityError: FOREIGN KEY constraint failed
ERROR 2024-10-29 22:06:30,318 basehttp "POST /app/auth/user/add/ HTTP/1.1" 500 158609
ERROR 2024-10-29 22:09:39,436 log Internal Server Error: /app/auth/user/add/
Traceback (most recent call last):
  File "C:\Users\kevin\AppData\Roaming\Python\Python312\site-packages\django\db\backends\base\base.py", line 299, in _commit
    return self.connection.commit()
           ^^^^^^^^^^^^^^^^^^^^^^^^
sqlite3.IntegrityError: FOREIGN KEY constraint failed

The above exception was the direct cause of the following exception:

Traceback (most recent call last):
  File "C:\Users\kevin\AppData\Roaming\Python\Python312\site-packages\django\core\handlers\exception.py", line 55, in inner
    response = get_response(request)
               ^^^^^^^^^^^^^^^^^^^^^
  File "C:\Users\kevin\AppData\Roaming\Python\Python312\site-packages\django\core\handlers\base.py", line 197, in _get_response
    response = wrapped_callback(request, *callback_args, **callback_kwargs)
               ^^^^^^^^^^^^^^^^^^^^^^^^^^^^^^^^^^^^^^^^^^^^^^^^^^^^^^^^^^^^
  File "C:\Users\kevin\AppData\Roaming\Python\Python312\site-packages\django\contrib\admin\options.py", line 716, in wrapper
    return self.admin_site.admin_view(view)(*args, **kwargs)
           ^^^^^^^^^^^^^^^^^^^^^^^^^^^^^^^^^^^^^^^^^^^^^^^^^
  File "C:\Users\kevin\AppData\Roaming\Python\Python312\site-packages\django\utils\decorators.py", line 188, in _view_wrapper
    result = _process_exception(request, e)
             ^^^^^^^^^^^^^^^^^^^^^^^^^^^^^^
  File "C:\Users\kevin\AppData\Roaming\Python\Python312\site-packages\django\utils\decorators.py", line 186, in _view_wrapper
    response = view_func(request, *args, **kwargs)
               ^^^^^^^^^^^^^^^^^^^^^^^^^^^^^^^^^^^
  File "C:\Users\kevin\AppData\Roaming\Python\Python312\site-packages\django\views\decorators\cache.py", line 80, in _view_wrapper
    response = view_func(request, *args, **kwargs)
               ^^^^^^^^^^^^^^^^^^^^^^^^^^^^^^^^^^^
  File "C:\Users\kevin\AppData\Roaming\Python\Python312\site-packages\django\contrib\admin\sites.py", line 240, in inner
    return view(request, *args, **kwargs)
           ^^^^^^^^^^^^^^^^^^^^^^^^^^^^^^
  File "C:\Users\kevin\AppData\Roaming\Python\Python312\site-packages\django\utils\decorators.py", line 48, in _wrapper
    return bound_method(*args, **kwargs)
           ^^^^^^^^^^^^^^^^^^^^^^^^^^^^^
  File "C:\Users\kevin\AppData\Roaming\Python\Python312\site-packages\django\views\decorators\debug.py", line 143, in sensitive_post_parameters_wrapper
    return view(request, *args, **kwargs)
           ^^^^^^^^^^^^^^^^^^^^^^^^^^^^^^
  File "C:\Users\kevin\AppData\Roaming\Python\Python312\site-packages\django\utils\decorators.py", line 48, in _wrapper
    return bound_method(*args, **kwargs)
           ^^^^^^^^^^^^^^^^^^^^^^^^^^^^^
  File "C:\Users\kevin\AppData\Roaming\Python\Python312\site-packages\django\utils\decorators.py", line 188, in _view_wrapper
    result = _process_exception(request, e)
             ^^^^^^^^^^^^^^^^^^^^^^^^^^^^^^
  File "C:\Users\kevin\AppData\Roaming\Python\Python312\site-packages\django\utils\decorators.py", line 186, in _view_wrapper
    response = view_func(request, *args, **kwargs)
               ^^^^^^^^^^^^^^^^^^^^^^^^^^^^^^^^^^^
  File "C:\Users\kevin\AppData\Roaming\Python\Python312\site-packages\django\contrib\auth\admin.py", line 120, in add_view
    with transaction.atomic(using=router.db_for_write(self.model)):
  File "C:\Users\kevin\AppData\Roaming\Python\Python312\site-packages\django\db\transaction.py", line 263, in __exit__
    connection.commit()
  File "C:\Users\kevin\AppData\Roaming\Python\Python312\site-packages\django\utils\asyncio.py", line 26, in inner
    return func(*args, **kwargs)
           ^^^^^^^^^^^^^^^^^^^^^
  File "C:\Users\kevin\AppData\Roaming\Python\Python312\site-packages\django\db\backends\base\base.py", line 323, in commit
    self._commit()
  File "C:\Users\kevin\AppData\Roaming\Python\Python312\site-packages\django\db\backends\base\base.py", line 298, in _commit
    with debug_transaction(self, "COMMIT"), self.wrap_database_errors:
  File "C:\Users\kevin\AppData\Roaming\Python\Python312\site-packages\django\db\utils.py", line 91, in __exit__
    raise dj_exc_value.with_traceback(traceback) from exc_value
  File "C:\Users\kevin\AppData\Roaming\Python\Python312\site-packages\django\db\backends\base\base.py", line 299, in _commit
    return self.connection.commit()
           ^^^^^^^^^^^^^^^^^^^^^^^^
django.db.utils.IntegrityError: FOREIGN KEY constraint failed
ERROR 2024-10-29 22:09:39,440 basehttp "POST /app/auth/user/add/ HTTP/1.1" 500 158610
ERROR 2024-10-29 22:12:49,469 log Internal Server Error: /app/auth/user/add/
Traceback (most recent call last):
  File "C:\Users\kevin\AppData\Roaming\Python\Python312\site-packages\django\db\utils.py", line 98, in inner
    return func(*args, **kwargs)
           ^^^^^^^^^^^^^^^^^^^^^
sqlite3.IntegrityError: FOREIGN KEY constraint failed

The above exception was the direct cause of the following exception:

Traceback (most recent call last):
  File "C:\Users\kevin\AppData\Roaming\Python\Python312\site-packages\django\core\handlers\exception.py", line 55, in inner
    response = get_response(request)
               ^^^^^^^^^^^^^^^^^^^^^
  File "C:\Users\kevin\AppData\Roaming\Python\Python312\site-packages\django\core\handlers\base.py", line 197, in _get_response
    response = wrapped_callback(request, *callback_args, **callback_kwargs)
               ^^^^^^^^^^^^^^^^^^^^^^^^^^^^^^^^^^^^^^^^^^^^^^^^^^^^^^^^^^^^
  File "C:\Users\kevin\AppData\Roaming\Python\Python312\site-packages\django\contrib\admin\options.py", line 716, in wrapper
    return self.admin_site.admin_view(view)(*args, **kwargs)
           ^^^^^^^^^^^^^^^^^^^^^^^^^^^^^^^^^^^^^^^^^^^^^^^^^
  File "C:\Users\kevin\AppData\Roaming\Python\Python312\site-packages\django\utils\decorators.py", line 188, in _view_wrapper
    result = _process_exception(request, e)
             ^^^^^^^^^^^^^^^^^^^^^^^^^^^^^^
  File "C:\Users\kevin\AppData\Roaming\Python\Python312\site-packages\django\utils\decorators.py", line 186, in _view_wrapper
    response = view_func(request, *args, **kwargs)
               ^^^^^^^^^^^^^^^^^^^^^^^^^^^^^^^^^^^
  File "C:\Users\kevin\AppData\Roaming\Python\Python312\site-packages\django\views\decorators\cache.py", line 80, in _view_wrapper
    response = view_func(request, *args, **kwargs)
               ^^^^^^^^^^^^^^^^^^^^^^^^^^^^^^^^^^^
  File "C:\Users\kevin\AppData\Roaming\Python\Python312\site-packages\django\contrib\admin\sites.py", line 240, in inner
    return view(request, *args, **kwargs)
           ^^^^^^^^^^^^^^^^^^^^^^^^^^^^^^
  File "C:\Users\kevin\AppData\Roaming\Python\Python312\site-packages\django\utils\decorators.py", line 48, in _wrapper
    return bound_method(*args, **kwargs)
           ^^^^^^^^^^^^^^^^^^^^^^^^^^^^^
  File "C:\Users\kevin\AppData\Roaming\Python\Python312\site-packages\django\views\decorators\debug.py", line 143, in sensitive_post_parameters_wrapper
    return view(request, *args, **kwargs)
           ^^^^^^^^^^^^^^^^^^^^^^^^^^^^^^
  File "C:\Users\kevin\AppData\Roaming\Python\Python312\site-packages\django\utils\decorators.py", line 48, in _wrapper
    return bound_method(*args, **kwargs)
           ^^^^^^^^^^^^^^^^^^^^^^^^^^^^^
  File "C:\Users\kevin\AppData\Roaming\Python\Python312\site-packages\django\utils\decorators.py", line 188, in _view_wrapper
    result = _process_exception(request, e)
             ^^^^^^^^^^^^^^^^^^^^^^^^^^^^^^
  File "C:\Users\kevin\AppData\Roaming\Python\Python312\site-packages\django\utils\decorators.py", line 186, in _view_wrapper
    response = view_func(request, *args, **kwargs)
               ^^^^^^^^^^^^^^^^^^^^^^^^^^^^^^^^^^^
  File "C:\Users\kevin\AppData\Roaming\Python\Python312\site-packages\django\contrib\auth\admin.py", line 120, in add_view
    with transaction.atomic(using=router.db_for_write(self.model)):
  File "C:\Users\kevin\AppData\Roaming\Python\Python312\site-packages\django\db\transaction.py", line 307, in __exit__
    connection.set_autocommit(True)
  File "C:\Users\kevin\AppData\Roaming\Python\Python312\site-packages\django\db\backends\base\base.py", line 487, in set_autocommit
    self.run_and_clear_commit_hooks()
  File "C:\Users\kevin\AppData\Roaming\Python\Python312\site-packages\django\db\backends\base\base.py", line 765, in run_and_clear_commit_hooks
    func()
  File "C:\Users\kevin\Desktop\pantutienda-adp\agenda\signals.py", line 11, in <lambda>
    transaction.on_commit(lambda: Cliente.objects.create(usuario=instance))
                                  ^^^^^^^^^^^^^^^^^^^^^^^^^^^^^^^^^^^^^^^^
  File "C:\Users\kevin\AppData\Roaming\Python\Python312\site-packages\django\db\models\manager.py", line 87, in manager_method
    return getattr(self.get_queryset(), name)(*args, **kwargs)
           ^^^^^^^^^^^^^^^^^^^^^^^^^^^^^^^^^^^^^^^^^^^^^^^^^^^
  File "C:\Users\kevin\AppData\Roaming\Python\Python312\site-packages\django\db\models\query.py", line 679, in create
    obj.save(force_insert=True, using=self.db)
  File "C:\Users\kevin\AppData\Roaming\Python\Python312\site-packages\django\db\models\base.py", line 822, in save
    self.save_base(
  File "C:\Users\kevin\AppData\Roaming\Python\Python312\site-packages\django\db\models\base.py", line 909, in save_base
    updated = self._save_table(
              ^^^^^^^^^^^^^^^^^
  File "C:\Users\kevin\AppData\Roaming\Python\Python312\site-packages\django\db\models\base.py", line 1071, in _save_table
    results = self._do_insert(
              ^^^^^^^^^^^^^^^^
  File "C:\Users\kevin\AppData\Roaming\Python\Python312\site-packages\django\db\models\base.py", line 1112, in _do_insert
    return manager._insert(
           ^^^^^^^^^^^^^^^^
  File "C:\Users\kevin\AppData\Roaming\Python\Python312\site-packages\django\db\models\manager.py", line 87, in manager_method
    return getattr(self.get_queryset(), name)(*args, **kwargs)
           ^^^^^^^^^^^^^^^^^^^^^^^^^^^^^^^^^^^^^^^^^^^^^^^^^^^
  File "C:\Users\kevin\AppData\Roaming\Python\Python312\site-packages\django\db\models\query.py", line 1847, in _insert
    return query.get_compiler(using=using).execute_sql(returning_fields)
           ^^^^^^^^^^^^^^^^^^^^^^^^^^^^^^^^^^^^^^^^^^^^^^^^^^^^^^^^^^^^^
  File "C:\Users\kevin\AppData\Roaming\Python\Python312\site-packages\django\db\models\sql\compiler.py", line 1835, in execute_sql
    self.connection.ops.fetch_returned_insert_columns(
  File "C:\Users\kevin\AppData\Roaming\Python\Python312\site-packages\django\db\backends\base\operations.py", line 216, in fetch_returned_insert_columns
    return cursor.fetchone()
           ^^^^^^^^^^^^^^^^^
  File "C:\Users\kevin\AppData\Roaming\Python\Python312\site-packages\django\db\utils.py", line 97, in inner
    with self:
  File "C:\Users\kevin\AppData\Roaming\Python\Python312\site-packages\django\db\utils.py", line 91, in __exit__
    raise dj_exc_value.with_traceback(traceback) from exc_value
  File "C:\Users\kevin\AppData\Roaming\Python\Python312\site-packages\django\db\utils.py", line 98, in inner
    return func(*args, **kwargs)
           ^^^^^^^^^^^^^^^^^^^^^
django.db.utils.IntegrityError: FOREIGN KEY constraint failed
ERROR 2024-10-29 22:12:49,476 basehttp "POST /app/auth/user/add/ HTTP/1.1" 500 215701
ERROR 2024-10-31 01:32:19,828 exception Invalid HTTP_HOST header: 'hotmail-com.olc.protection.outlook.com:25'. You may need to add 'hotmail-com.olc.protection.outlook.com' to ALLOWED_HOSTS.
Traceback (most recent call last):
  File "/home/ubuntu/aplicaciones/django_env/lib/python3.10/site-packages/django/core/handlers/exception.py", line 55, in inner
    response = get_response(request)
  File "/home/ubuntu/aplicaciones/django_env/lib/python3.10/site-packages/django/utils/deprecation.py", line 133, in __call__
    response = self.process_request(request)
  File "/home/ubuntu/aplicaciones/django_env/lib/python3.10/site-packages/django/middleware/common.py", line 48, in process_request
    host = request.get_host()
  File "/home/ubuntu/aplicaciones/django_env/lib/python3.10/site-packages/django/http/request.py", line 151, in get_host
    raise DisallowedHost(msg)
django.core.exceptions.DisallowedHost: Invalid HTTP_HOST header: 'hotmail-com.olc.protection.outlook.com:25'. You may need to add 'hotmail-com.olc.protection.outlook.com' to ALLOWED_HOSTS.
ERROR 2024-10-31 04:19:06,608 exception Invalid HTTP_HOST header: '80.66.83.47:80'. You may need to add '80.66.83.47' to ALLOWED_HOSTS.
Traceback (most recent call last):
  File "/home/ubuntu/aplicaciones/django_env/lib/python3.10/site-packages/django/core/handlers/exception.py", line 55, in inner
    response = get_response(request)
  File "/home/ubuntu/aplicaciones/django_env/lib/python3.10/site-packages/django/utils/deprecation.py", line 133, in __call__
    response = self.process_request(request)
  File "/home/ubuntu/aplicaciones/django_env/lib/python3.10/site-packages/django/middleware/common.py", line 48, in process_request
    host = request.get_host()
  File "/home/ubuntu/aplicaciones/django_env/lib/python3.10/site-packages/django/http/request.py", line 151, in get_host
    raise DisallowedHost(msg)
django.core.exceptions.DisallowedHost: Invalid HTTP_HOST header: '80.66.83.47:80'. You may need to add '80.66.83.47' to ALLOWED_HOSTS.
ERROR 2024-10-31 09:45:18,111 log Internal Server Error: /front/home/
Traceback (most recent call last):
  File "/home/ubuntu/aplicaciones/django_env/lib/python3.10/site-packages/django/template/base.py", line 875, in _resolve_lookup
    current = current[bit]
TypeError: 'ImageFieldFile' object is not subscriptable

During handling of the above exception, another exception occurred:

Traceback (most recent call last):
  File "/home/ubuntu/aplicaciones/django_env/lib/python3.10/site-packages/django/core/handlers/exception.py", line 55, in inner
    response = get_response(request)
  File "/home/ubuntu/aplicaciones/django_env/lib/python3.10/site-packages/django/core/handlers/base.py", line 197, in _get_response
    response = wrapped_callback(request, *callback_args, **callback_kwargs)
  File "/home/ubuntu/aplicaciones/pantutienda-adp/front/views.py", line 186, in home
    return render(request, 'landing/index.html', context)
  File "/home/ubuntu/aplicaciones/django_env/lib/python3.10/site-packages/django/shortcuts.py", line 24, in render
    content = loader.render_to_string(template_name, context, request, using=using)
  File "/home/ubuntu/aplicaciones/django_env/lib/python3.10/site-packages/django/template/loader.py", line 62, in render_to_string
    return template.render(context, request)
  File "/home/ubuntu/aplicaciones/django_env/lib/python3.10/site-packages/django/template/backends/django.py", line 61, in render
    return self.template.render(context)
  File "/home/ubuntu/aplicaciones/django_env/lib/python3.10/site-packages/django/template/base.py", line 171, in render
    return self._render(context)
  File "/home/ubuntu/aplicaciones/django_env/lib/python3.10/site-packages/django/template/base.py", line 163, in _render
    return self.nodelist.render(context)
  File "/home/ubuntu/aplicaciones/django_env/lib/python3.10/site-packages/django/template/base.py", line 1000, in render
    return SafeString("".join([node.render_annotated(context) for node in self]))
  File "/home/ubuntu/aplicaciones/django_env/lib/python3.10/site-packages/django/template/base.py", line 1000, in <listcomp>
    return SafeString("".join([node.render_annotated(context) for node in self]))
  File "/home/ubuntu/aplicaciones/django_env/lib/python3.10/site-packages/django/template/base.py", line 961, in render_annotated
    return self.render(context)
  File "/home/ubuntu/aplicaciones/django_env/lib/python3.10/site-packages/django/template/loader_tags.py", line 159, in render
    return compiled_parent._render(context)
  File "/home/ubuntu/aplicaciones/django_env/lib/python3.10/site-packages/django/template/base.py", line 163, in _render
    return self.nodelist.render(context)
  File "/home/ubuntu/aplicaciones/django_env/lib/python3.10/site-packages/django/template/base.py", line 1000, in render
    return SafeString("".join([node.render_annotated(context) for node in self]))
  File "/home/ubuntu/aplicaciones/django_env/lib/python3.10/site-packages/django/template/base.py", line 1000, in <listcomp>
    return SafeString("".join([node.render_annotated(context) for node in self]))
  File "/home/ubuntu/aplicaciones/django_env/lib/python3.10/site-packages/django/template/base.py", line 961, in render_annotated
    return self.render(context)
  File "/home/ubuntu/aplicaciones/django_env/lib/python3.10/site-packages/django/template/loader_tags.py", line 65, in render
    result = block.nodelist.render(context)
  File "/home/ubuntu/aplicaciones/django_env/lib/python3.10/site-packages/django/template/base.py", line 1000, in render
    return SafeString("".join([node.render_annotated(context) for node in self]))
  File "/home/ubuntu/aplicaciones/django_env/lib/python3.10/site-packages/django/template/base.py", line 1000, in <listcomp>
    return SafeString("".join([node.render_annotated(context) for node in self]))
  File "/home/ubuntu/aplicaciones/django_env/lib/python3.10/site-packages/django/template/base.py", line 961, in render_annotated
    return self.render(context)
  File "/home/ubuntu/aplicaciones/django_env/lib/python3.10/site-packages/django/template/defaulttags.py", line 241, in render
    nodelist.append(node.render_annotated(context))
  File "/home/ubuntu/aplicaciones/django_env/lib/python3.10/site-packages/django/template/base.py", line 961, in render_annotated
    return self.render(context)
  File "/home/ubuntu/aplicaciones/django_env/lib/python3.10/site-packages/django/template/defaulttags.py", line 325, in render
    return nodelist.render(context)
  File "/home/ubuntu/aplicaciones/django_env/lib/python3.10/site-packages/django/template/base.py", line 1000, in render
    return SafeString("".join([node.render_annotated(context) for node in self]))
  File "/home/ubuntu/aplicaciones/django_env/lib/python3.10/site-packages/django/template/base.py", line 1000, in <listcomp>
    return SafeString("".join([node.render_annotated(context) for node in self]))
  File "/home/ubuntu/aplicaciones/django_env/lib/python3.10/site-packages/django/template/base.py", line 961, in render_annotated
    return self.render(context)
  File "/home/ubuntu/aplicaciones/django_env/lib/python3.10/site-packages/django/template/loader_tags.py", line 210, in render
    return template.render(context)
  File "/home/ubuntu/aplicaciones/django_env/lib/python3.10/site-packages/django/template/base.py", line 173, in render
    return self._render(context)
  File "/home/ubuntu/aplicaciones/django_env/lib/python3.10/site-packages/django/template/base.py", line 163, in _render
    return self.nodelist.render(context)
  File "/home/ubuntu/aplicaciones/django_env/lib/python3.10/site-packages/django/template/base.py", line 1000, in render
    return SafeString("".join([node.render_annotated(context) for node in self]))
  File "/home/ubuntu/aplicaciones/django_env/lib/python3.10/site-packages/django/template/base.py", line 1000, in <listcomp>
    return SafeString("".join([node.render_annotated(context) for node in self]))
  File "/home/ubuntu/aplicaciones/django_env/lib/python3.10/site-packages/django/template/base.py", line 961, in render_annotated
    return self.render(context)
  File "/home/ubuntu/aplicaciones/django_env/lib/python3.10/site-packages/django/template/base.py", line 1059, in render
    output = self.filter_expression.resolve(context)
  File "/home/ubuntu/aplicaciones/django_env/lib/python3.10/site-packages/django/template/base.py", line 710, in resolve
    obj = self.var.resolve(context)
  File "/home/ubuntu/aplicaciones/django_env/lib/python3.10/site-packages/django/template/base.py", line 842, in resolve
    value = self._resolve_lookup(context)
  File "/home/ubuntu/aplicaciones/django_env/lib/python3.10/site-packages/django/template/base.py", line 885, in _resolve_lookup
    current = getattr(current, bit)
  File "/home/ubuntu/aplicaciones/django_env/lib/python3.10/site-packages/django/db/models/fields/files.py", line 66, in url
    self._require_file()
  File "/home/ubuntu/aplicaciones/django_env/lib/python3.10/site-packages/django/db/models/fields/files.py", line 41, in _require_file
    raise ValueError(
ValueError: The 'clients_logo_1' attribute has no file associated with it.
ERROR 2024-10-31 09:45:19,586 log Internal Server Error: /front/home/
Traceback (most recent call last):
  File "/home/ubuntu/aplicaciones/django_env/lib/python3.10/site-packages/django/template/base.py", line 875, in _resolve_lookup
    current = current[bit]
TypeError: 'ImageFieldFile' object is not subscriptable

During handling of the above exception, another exception occurred:

Traceback (most recent call last):
  File "/home/ubuntu/aplicaciones/django_env/lib/python3.10/site-packages/django/core/handlers/exception.py", line 55, in inner
    response = get_response(request)
  File "/home/ubuntu/aplicaciones/django_env/lib/python3.10/site-packages/django/core/handlers/base.py", line 197, in _get_response
    response = wrapped_callback(request, *callback_args, **callback_kwargs)
  File "/home/ubuntu/aplicaciones/pantutienda-adp/front/views.py", line 186, in home
    return render(request, 'landing/index.html', context)
  File "/home/ubuntu/aplicaciones/django_env/lib/python3.10/site-packages/django/shortcuts.py", line 24, in render
    content = loader.render_to_string(template_name, context, request, using=using)
  File "/home/ubuntu/aplicaciones/django_env/lib/python3.10/site-packages/django/template/loader.py", line 62, in render_to_string
    return template.render(context, request)
  File "/home/ubuntu/aplicaciones/django_env/lib/python3.10/site-packages/django/template/backends/django.py", line 61, in render
    return self.template.render(context)
  File "/home/ubuntu/aplicaciones/django_env/lib/python3.10/site-packages/django/template/base.py", line 171, in render
    return self._render(context)
  File "/home/ubuntu/aplicaciones/django_env/lib/python3.10/site-packages/django/template/base.py", line 163, in _render
    return self.nodelist.render(context)
  File "/home/ubuntu/aplicaciones/django_env/lib/python3.10/site-packages/django/template/base.py", line 1000, in render
    return SafeString("".join([node.render_annotated(context) for node in self]))
  File "/home/ubuntu/aplicaciones/django_env/lib/python3.10/site-packages/django/template/base.py", line 1000, in <listcomp>
    return SafeString("".join([node.render_annotated(context) for node in self]))
  File "/home/ubuntu/aplicaciones/django_env/lib/python3.10/site-packages/django/template/base.py", line 961, in render_annotated
    return self.render(context)
  File "/home/ubuntu/aplicaciones/django_env/lib/python3.10/site-packages/django/template/loader_tags.py", line 159, in render
    return compiled_parent._render(context)
  File "/home/ubuntu/aplicaciones/django_env/lib/python3.10/site-packages/django/template/base.py", line 163, in _render
    return self.nodelist.render(context)
  File "/home/ubuntu/aplicaciones/django_env/lib/python3.10/site-packages/django/template/base.py", line 1000, in render
    return SafeString("".join([node.render_annotated(context) for node in self]))
  File "/home/ubuntu/aplicaciones/django_env/lib/python3.10/site-packages/django/template/base.py", line 1000, in <listcomp>
    return SafeString("".join([node.render_annotated(context) for node in self]))
  File "/home/ubuntu/aplicaciones/django_env/lib/python3.10/site-packages/django/template/base.py", line 961, in render_annotated
    return self.render(context)
  File "/home/ubuntu/aplicaciones/django_env/lib/python3.10/site-packages/django/template/loader_tags.py", line 65, in render
    result = block.nodelist.render(context)
  File "/home/ubuntu/aplicaciones/django_env/lib/python3.10/site-packages/django/template/base.py", line 1000, in render
    return SafeString("".join([node.render_annotated(context) for node in self]))
  File "/home/ubuntu/aplicaciones/django_env/lib/python3.10/site-packages/django/template/base.py", line 1000, in <listcomp>
    return SafeString("".join([node.render_annotated(context) for node in self]))
  File "/home/ubuntu/aplicaciones/django_env/lib/python3.10/site-packages/django/template/base.py", line 961, in render_annotated
    return self.render(context)
  File "/home/ubuntu/aplicaciones/django_env/lib/python3.10/site-packages/django/template/defaulttags.py", line 241, in render
    nodelist.append(node.render_annotated(context))
  File "/home/ubuntu/aplicaciones/django_env/lib/python3.10/site-packages/django/template/base.py", line 961, in render_annotated
    return self.render(context)
  File "/home/ubuntu/aplicaciones/django_env/lib/python3.10/site-packages/django/template/defaulttags.py", line 325, in render
    return nodelist.render(context)
  File "/home/ubuntu/aplicaciones/django_env/lib/python3.10/site-packages/django/template/base.py", line 1000, in render
    return SafeString("".join([node.render_annotated(context) for node in self]))
  File "/home/ubuntu/aplicaciones/django_env/lib/python3.10/site-packages/django/template/base.py", line 1000, in <listcomp>
    return SafeString("".join([node.render_annotated(context) for node in self]))
  File "/home/ubuntu/aplicaciones/django_env/lib/python3.10/site-packages/django/template/base.py", line 961, in render_annotated
    return self.render(context)
  File "/home/ubuntu/aplicaciones/django_env/lib/python3.10/site-packages/django/template/loader_tags.py", line 210, in render
    return template.render(context)
  File "/home/ubuntu/aplicaciones/django_env/lib/python3.10/site-packages/django/template/base.py", line 173, in render
    return self._render(context)
  File "/home/ubuntu/aplicaciones/django_env/lib/python3.10/site-packages/django/template/base.py", line 163, in _render
    return self.nodelist.render(context)
  File "/home/ubuntu/aplicaciones/django_env/lib/python3.10/site-packages/django/template/base.py", line 1000, in render
    return SafeString("".join([node.render_annotated(context) for node in self]))
  File "/home/ubuntu/aplicaciones/django_env/lib/python3.10/site-packages/django/template/base.py", line 1000, in <listcomp>
    return SafeString("".join([node.render_annotated(context) for node in self]))
  File "/home/ubuntu/aplicaciones/django_env/lib/python3.10/site-packages/django/template/base.py", line 961, in render_annotated
    return self.render(context)
  File "/home/ubuntu/aplicaciones/django_env/lib/python3.10/site-packages/django/template/base.py", line 1059, in render
    output = self.filter_expression.resolve(context)
  File "/home/ubuntu/aplicaciones/django_env/lib/python3.10/site-packages/django/template/base.py", line 710, in resolve
    obj = self.var.resolve(context)
  File "/home/ubuntu/aplicaciones/django_env/lib/python3.10/site-packages/django/template/base.py", line 842, in resolve
    value = self._resolve_lookup(context)
  File "/home/ubuntu/aplicaciones/django_env/lib/python3.10/site-packages/django/template/base.py", line 885, in _resolve_lookup
    current = getattr(current, bit)
  File "/home/ubuntu/aplicaciones/django_env/lib/python3.10/site-packages/django/db/models/fields/files.py", line 66, in url
    self._require_file()
  File "/home/ubuntu/aplicaciones/django_env/lib/python3.10/site-packages/django/db/models/fields/files.py", line 41, in _require_file
    raise ValueError(
ValueError: The 'clients_logo_1' attribute has no file associated with it.
ERROR 2024-10-31 09:45:20,397 log Internal Server Error: /front/home/
Traceback (most recent call last):
  File "/home/ubuntu/aplicaciones/django_env/lib/python3.10/site-packages/django/template/base.py", line 875, in _resolve_lookup
    current = current[bit]
TypeError: 'ImageFieldFile' object is not subscriptable

During handling of the above exception, another exception occurred:

Traceback (most recent call last):
  File "/home/ubuntu/aplicaciones/django_env/lib/python3.10/site-packages/django/core/handlers/exception.py", line 55, in inner
    response = get_response(request)
  File "/home/ubuntu/aplicaciones/django_env/lib/python3.10/site-packages/django/core/handlers/base.py", line 197, in _get_response
    response = wrapped_callback(request, *callback_args, **callback_kwargs)
  File "/home/ubuntu/aplicaciones/pantutienda-adp/front/views.py", line 186, in home
    return render(request, 'landing/index.html', context)
  File "/home/ubuntu/aplicaciones/django_env/lib/python3.10/site-packages/django/shortcuts.py", line 24, in render
    content = loader.render_to_string(template_name, context, request, using=using)
  File "/home/ubuntu/aplicaciones/django_env/lib/python3.10/site-packages/django/template/loader.py", line 62, in render_to_string
    return template.render(context, request)
  File "/home/ubuntu/aplicaciones/django_env/lib/python3.10/site-packages/django/template/backends/django.py", line 61, in render
    return self.template.render(context)
  File "/home/ubuntu/aplicaciones/django_env/lib/python3.10/site-packages/django/template/base.py", line 171, in render
    return self._render(context)
  File "/home/ubuntu/aplicaciones/django_env/lib/python3.10/site-packages/django/template/base.py", line 163, in _render
    return self.nodelist.render(context)
  File "/home/ubuntu/aplicaciones/django_env/lib/python3.10/site-packages/django/template/base.py", line 1000, in render
    return SafeString("".join([node.render_annotated(context) for node in self]))
  File "/home/ubuntu/aplicaciones/django_env/lib/python3.10/site-packages/django/template/base.py", line 1000, in <listcomp>
    return SafeString("".join([node.render_annotated(context) for node in self]))
  File "/home/ubuntu/aplicaciones/django_env/lib/python3.10/site-packages/django/template/base.py", line 961, in render_annotated
    return self.render(context)
  File "/home/ubuntu/aplicaciones/django_env/lib/python3.10/site-packages/django/template/loader_tags.py", line 159, in render
    return compiled_parent._render(context)
  File "/home/ubuntu/aplicaciones/django_env/lib/python3.10/site-packages/django/template/base.py", line 163, in _render
    return self.nodelist.render(context)
  File "/home/ubuntu/aplicaciones/django_env/lib/python3.10/site-packages/django/template/base.py", line 1000, in render
    return SafeString("".join([node.render_annotated(context) for node in self]))
  File "/home/ubuntu/aplicaciones/django_env/lib/python3.10/site-packages/django/template/base.py", line 1000, in <listcomp>
    return SafeString("".join([node.render_annotated(context) for node in self]))
  File "/home/ubuntu/aplicaciones/django_env/lib/python3.10/site-packages/django/template/base.py", line 961, in render_annotated
    return self.render(context)
  File "/home/ubuntu/aplicaciones/django_env/lib/python3.10/site-packages/django/template/loader_tags.py", line 65, in render
    result = block.nodelist.render(context)
  File "/home/ubuntu/aplicaciones/django_env/lib/python3.10/site-packages/django/template/base.py", line 1000, in render
    return SafeString("".join([node.render_annotated(context) for node in self]))
  File "/home/ubuntu/aplicaciones/django_env/lib/python3.10/site-packages/django/template/base.py", line 1000, in <listcomp>
    return SafeString("".join([node.render_annotated(context) for node in self]))
  File "/home/ubuntu/aplicaciones/django_env/lib/python3.10/site-packages/django/template/base.py", line 961, in render_annotated
    return self.render(context)
  File "/home/ubuntu/aplicaciones/django_env/lib/python3.10/site-packages/django/template/defaulttags.py", line 241, in render
    nodelist.append(node.render_annotated(context))
  File "/home/ubuntu/aplicaciones/django_env/lib/python3.10/site-packages/django/template/base.py", line 961, in render_annotated
    return self.render(context)
  File "/home/ubuntu/aplicaciones/django_env/lib/python3.10/site-packages/django/template/defaulttags.py", line 325, in render
    return nodelist.render(context)
  File "/home/ubuntu/aplicaciones/django_env/lib/python3.10/site-packages/django/template/base.py", line 1000, in render
    return SafeString("".join([node.render_annotated(context) for node in self]))
  File "/home/ubuntu/aplicaciones/django_env/lib/python3.10/site-packages/django/template/base.py", line 1000, in <listcomp>
    return SafeString("".join([node.render_annotated(context) for node in self]))
  File "/home/ubuntu/aplicaciones/django_env/lib/python3.10/site-packages/django/template/base.py", line 961, in render_annotated
    return self.render(context)
  File "/home/ubuntu/aplicaciones/django_env/lib/python3.10/site-packages/django/template/loader_tags.py", line 210, in render
    return template.render(context)
  File "/home/ubuntu/aplicaciones/django_env/lib/python3.10/site-packages/django/template/base.py", line 173, in render
    return self._render(context)
  File "/home/ubuntu/aplicaciones/django_env/lib/python3.10/site-packages/django/template/base.py", line 163, in _render
    return self.nodelist.render(context)
  File "/home/ubuntu/aplicaciones/django_env/lib/python3.10/site-packages/django/template/base.py", line 1000, in render
    return SafeString("".join([node.render_annotated(context) for node in self]))
  File "/home/ubuntu/aplicaciones/django_env/lib/python3.10/site-packages/django/template/base.py", line 1000, in <listcomp>
    return SafeString("".join([node.render_annotated(context) for node in self]))
  File "/home/ubuntu/aplicaciones/django_env/lib/python3.10/site-packages/django/template/base.py", line 961, in render_annotated
    return self.render(context)
  File "/home/ubuntu/aplicaciones/django_env/lib/python3.10/site-packages/django/template/base.py", line 1059, in render
    output = self.filter_expression.resolve(context)
  File "/home/ubuntu/aplicaciones/django_env/lib/python3.10/site-packages/django/template/base.py", line 710, in resolve
    obj = self.var.resolve(context)
  File "/home/ubuntu/aplicaciones/django_env/lib/python3.10/site-packages/django/template/base.py", line 842, in resolve
    value = self._resolve_lookup(context)
  File "/home/ubuntu/aplicaciones/django_env/lib/python3.10/site-packages/django/template/base.py", line 885, in _resolve_lookup
    current = getattr(current, bit)
  File "/home/ubuntu/aplicaciones/django_env/lib/python3.10/site-packages/django/db/models/fields/files.py", line 66, in url
    self._require_file()
  File "/home/ubuntu/aplicaciones/django_env/lib/python3.10/site-packages/django/db/models/fields/files.py", line 41, in _require_file
    raise ValueError(
ValueError: The 'clients_logo_1' attribute has no file associated with it.
ERROR 2024-10-31 22:45:22,235 log Internal Server Error: /front/home/
Traceback (most recent call last):
  File "C:\Users\kevin\AppData\Roaming\Python\Python312\site-packages\django\template\backends\django.py", line 61, in render
    return self.template.render(context)
           ^^^^^^^^^^^^^^^^^^^^^^^^^^^^^
  File "C:\Users\kevin\AppData\Roaming\Python\Python312\site-packages\django\template\base.py", line 171, in render
    return self._render(context)
           ^^^^^^^^^^^^^^^^^^^^^
  File "C:\Users\kevin\AppData\Roaming\Python\Python312\site-packages\django\template\base.py", line 163, in _render
    return self.nodelist.render(context)
           ^^^^^^^^^^^^^^^^^^^^^^^^^^^^^
  File "C:\Users\kevin\AppData\Roaming\Python\Python312\site-packages\django\template\base.py", line 1000, in render
    return SafeString("".join([node.render_annotated(context) for node in self]))
                               ^^^^^^^^^^^^^^^^^^^^^^^^^^^^^^
  File "C:\Users\kevin\AppData\Roaming\Python\Python312\site-packages\django\template\base.py", line 961, in render_annotated
    return self.render(context)
           ^^^^^^^^^^^^^^^^^^^^
  File "C:\Users\kevin\AppData\Roaming\Python\Python312\site-packages\django\template\loader_tags.py", line 159, in render
    return compiled_parent._render(context)
           ^^^^^^^^^^^^^^^^^^^^^^^^^^^^^^^^
  File "C:\Users\kevin\AppData\Roaming\Python\Python312\site-packages\django\template\base.py", line 163, in _render
    return self.nodelist.render(context)
           ^^^^^^^^^^^^^^^^^^^^^^^^^^^^^
  File "C:\Users\kevin\AppData\Roaming\Python\Python312\site-packages\django\template\base.py", line 1000, in render
    return SafeString("".join([node.render_annotated(context) for node in self]))
                               ^^^^^^^^^^^^^^^^^^^^^^^^^^^^^^
  File "C:\Users\kevin\AppData\Roaming\Python\Python312\site-packages\django\template\base.py", line 961, in render_annotated
    return self.render(context)
           ^^^^^^^^^^^^^^^^^^^^
  File "C:\Users\kevin\AppData\Roaming\Python\Python312\site-packages\django\template\loader_tags.py", line 65, in render
    result = block.nodelist.render(context)
             ^^^^^^^^^^^^^^^^^^^^^^^^^^^^^^
  File "C:\Users\kevin\AppData\Roaming\Python\Python312\site-packages\django\template\base.py", line 1000, in render
    return SafeString("".join([node.render_annotated(context) for node in self]))
                               ^^^^^^^^^^^^^^^^^^^^^^^^^^^^^^
  File "C:\Users\kevin\AppData\Roaming\Python\Python312\site-packages\django\template\base.py", line 961, in render_annotated
    return self.render(context)
           ^^^^^^^^^^^^^^^^^^^^
  File "C:\Users\kevin\AppData\Roaming\Python\Python312\site-packages\django\template\defaulttags.py", line 242, in render
    nodelist.append(node.render_annotated(context))
                    ^^^^^^^^^^^^^^^^^^^^^^^^^^^^^^
  File "C:\Users\kevin\AppData\Roaming\Python\Python312\site-packages\django\template\base.py", line 961, in render_annotated
    return self.render(context)
           ^^^^^^^^^^^^^^^^^^^^
  File "C:\Users\kevin\AppData\Roaming\Python\Python312\site-packages\django\template\defaulttags.py", line 326, in render
    return nodelist.render(context)
           ^^^^^^^^^^^^^^^^^^^^^^^^
  File "C:\Users\kevin\AppData\Roaming\Python\Python312\site-packages\django\template\base.py", line 1000, in render
    return SafeString("".join([node.render_annotated(context) for node in self]))
                               ^^^^^^^^^^^^^^^^^^^^^^^^^^^^^^
  File "C:\Users\kevin\AppData\Roaming\Python\Python312\site-packages\django\template\base.py", line 961, in render_annotated
    return self.render(context)
           ^^^^^^^^^^^^^^^^^^^^
  File "C:\Users\kevin\AppData\Roaming\Python\Python312\site-packages\django\template\loader_tags.py", line 199, in render
    template = context.template.engine.select_template(template_name)
               ^^^^^^^^^^^^^^^^^^^^^^^^^^^^^^^^^^^^^^^^^^^^^^^^^^^^^^
  File "C:\Users\kevin\AppData\Roaming\Python\Python312\site-packages\django\template\engine.py", line 214, in select_template
    raise TemplateDoesNotExist(", ".join(not_found))
django.template.exceptions.TemplateDoesNotExist: landing/banner.html

The above exception was the direct cause of the following exception:

Traceback (most recent call last):
  File "C:\Users\kevin\AppData\Roaming\Python\Python312\site-packages\django\core\handlers\exception.py", line 55, in inner
    response = get_response(request)
               ^^^^^^^^^^^^^^^^^^^^^
  File "C:\Users\kevin\AppData\Roaming\Python\Python312\site-packages\django\core\handlers\base.py", line 197, in _get_response
    response = wrapped_callback(request, *callback_args, **callback_kwargs)
               ^^^^^^^^^^^^^^^^^^^^^^^^^^^^^^^^^^^^^^^^^^^^^^^^^^^^^^^^^^^^
  File "C:\Users\kevin\Desktop\pantutienda-adp\front\views.py", line 186, in home
    return render(request, 'landing/index.html', context)
           ^^^^^^^^^^^^^^^^^^^^^^^^^^^^^^^^^^^^^^^^^^^^^^
  File "C:\Users\kevin\AppData\Roaming\Python\Python312\site-packages\django\shortcuts.py", line 25, in render
    content = loader.render_to_string(template_name, context, request, using=using)
              ^^^^^^^^^^^^^^^^^^^^^^^^^^^^^^^^^^^^^^^^^^^^^^^^^^^^^^^^^^^^^^^^^^^^^
  File "C:\Users\kevin\AppData\Roaming\Python\Python312\site-packages\django\template\loader.py", line 62, in render_to_string
    return template.render(context, request)
           ^^^^^^^^^^^^^^^^^^^^^^^^^^^^^^^^^
  File "C:\Users\kevin\AppData\Roaming\Python\Python312\site-packages\django\template\backends\django.py", line 63, in render
    reraise(exc, self.backend)
  File "C:\Users\kevin\AppData\Roaming\Python\Python312\site-packages\django\template\backends\django.py", line 84, in reraise
    raise new from exc
django.template.exceptions.TemplateDoesNotExist: landing/banner.html
ERROR 2024-10-31 22:45:22,240 basehttp "GET /front/home/ HTTP/1.1" 500 215457
ERROR 2024-10-31 22:52:01,757 log Internal Server Error: /front/home/
Traceback (most recent call last):
  File "C:\Users\kevin\AppData\Roaming\Python\Python312\site-packages\django\template\backends\django.py", line 61, in render
    return self.template.render(context)
           ^^^^^^^^^^^^^^^^^^^^^^^^^^^^^
  File "C:\Users\kevin\AppData\Roaming\Python\Python312\site-packages\django\template\base.py", line 171, in render
    return self._render(context)
           ^^^^^^^^^^^^^^^^^^^^^
  File "C:\Users\kevin\AppData\Roaming\Python\Python312\site-packages\django\template\base.py", line 163, in _render
    return self.nodelist.render(context)
           ^^^^^^^^^^^^^^^^^^^^^^^^^^^^^
  File "C:\Users\kevin\AppData\Roaming\Python\Python312\site-packages\django\template\base.py", line 1000, in render
    return SafeString("".join([node.render_annotated(context) for node in self]))
                               ^^^^^^^^^^^^^^^^^^^^^^^^^^^^^^
  File "C:\Users\kevin\AppData\Roaming\Python\Python312\site-packages\django\template\base.py", line 961, in render_annotated
    return self.render(context)
           ^^^^^^^^^^^^^^^^^^^^
  File "C:\Users\kevin\AppData\Roaming\Python\Python312\site-packages\django\template\loader_tags.py", line 159, in render
    return compiled_parent._render(context)
           ^^^^^^^^^^^^^^^^^^^^^^^^^^^^^^^^
  File "C:\Users\kevin\AppData\Roaming\Python\Python312\site-packages\django\template\base.py", line 163, in _render
    return self.nodelist.render(context)
           ^^^^^^^^^^^^^^^^^^^^^^^^^^^^^
  File "C:\Users\kevin\AppData\Roaming\Python\Python312\site-packages\django\template\base.py", line 1000, in render
    return SafeString("".join([node.render_annotated(context) for node in self]))
                               ^^^^^^^^^^^^^^^^^^^^^^^^^^^^^^
  File "C:\Users\kevin\AppData\Roaming\Python\Python312\site-packages\django\template\base.py", line 961, in render_annotated
    return self.render(context)
           ^^^^^^^^^^^^^^^^^^^^
  File "C:\Users\kevin\AppData\Roaming\Python\Python312\site-packages\django\template\loader_tags.py", line 65, in render
    result = block.nodelist.render(context)
             ^^^^^^^^^^^^^^^^^^^^^^^^^^^^^^
  File "C:\Users\kevin\AppData\Roaming\Python\Python312\site-packages\django\template\base.py", line 1000, in render
    return SafeString("".join([node.render_annotated(context) for node in self]))
                               ^^^^^^^^^^^^^^^^^^^^^^^^^^^^^^
  File "C:\Users\kevin\AppData\Roaming\Python\Python312\site-packages\django\template\base.py", line 961, in render_annotated
    return self.render(context)
           ^^^^^^^^^^^^^^^^^^^^
  File "C:\Users\kevin\AppData\Roaming\Python\Python312\site-packages\django\template\defaulttags.py", line 242, in render
    nodelist.append(node.render_annotated(context))
                    ^^^^^^^^^^^^^^^^^^^^^^^^^^^^^^
  File "C:\Users\kevin\AppData\Roaming\Python\Python312\site-packages\django\template\base.py", line 961, in render_annotated
    return self.render(context)
           ^^^^^^^^^^^^^^^^^^^^
  File "C:\Users\kevin\AppData\Roaming\Python\Python312\site-packages\django\template\defaulttags.py", line 326, in render
    return nodelist.render(context)
           ^^^^^^^^^^^^^^^^^^^^^^^^
  File "C:\Users\kevin\AppData\Roaming\Python\Python312\site-packages\django\template\base.py", line 1000, in render
    return SafeString("".join([node.render_annotated(context) for node in self]))
                               ^^^^^^^^^^^^^^^^^^^^^^^^^^^^^^
  File "C:\Users\kevin\AppData\Roaming\Python\Python312\site-packages\django\template\base.py", line 961, in render_annotated
    return self.render(context)
           ^^^^^^^^^^^^^^^^^^^^
  File "C:\Users\kevin\AppData\Roaming\Python\Python312\site-packages\django\template\loader_tags.py", line 199, in render
    template = context.template.engine.select_template(template_name)
               ^^^^^^^^^^^^^^^^^^^^^^^^^^^^^^^^^^^^^^^^^^^^^^^^^^^^^^
  File "C:\Users\kevin\AppData\Roaming\Python\Python312\site-packages\django\template\engine.py", line 214, in select_template
    raise TemplateDoesNotExist(", ".join(not_found))
django.template.exceptions.TemplateDoesNotExist: landing/banner.html

The above exception was the direct cause of the following exception:

Traceback (most recent call last):
  File "C:\Users\kevin\AppData\Roaming\Python\Python312\site-packages\django\core\handlers\exception.py", line 55, in inner
    response = get_response(request)
               ^^^^^^^^^^^^^^^^^^^^^
  File "C:\Users\kevin\AppData\Roaming\Python\Python312\site-packages\django\core\handlers\base.py", line 197, in _get_response
    response = wrapped_callback(request, *callback_args, **callback_kwargs)
               ^^^^^^^^^^^^^^^^^^^^^^^^^^^^^^^^^^^^^^^^^^^^^^^^^^^^^^^^^^^^
  File "C:\Users\kevin\Desktop\pantutienda-adp\front\views.py", line 186, in home
    return render(request, 'landing/index.html', context)
           ^^^^^^^^^^^^^^^^^^^^^^^^^^^^^^^^^^^^^^^^^^^^^^
  File "C:\Users\kevin\AppData\Roaming\Python\Python312\site-packages\django\shortcuts.py", line 25, in render
    content = loader.render_to_string(template_name, context, request, using=using)
              ^^^^^^^^^^^^^^^^^^^^^^^^^^^^^^^^^^^^^^^^^^^^^^^^^^^^^^^^^^^^^^^^^^^^^
  File "C:\Users\kevin\AppData\Roaming\Python\Python312\site-packages\django\template\loader.py", line 62, in render_to_string
    return template.render(context, request)
           ^^^^^^^^^^^^^^^^^^^^^^^^^^^^^^^^^
  File "C:\Users\kevin\AppData\Roaming\Python\Python312\site-packages\django\template\backends\django.py", line 63, in render
    reraise(exc, self.backend)
  File "C:\Users\kevin\AppData\Roaming\Python\Python312\site-packages\django\template\backends\django.py", line 84, in reraise
    raise new from exc
django.template.exceptions.TemplateDoesNotExist: landing/banner.html
ERROR 2024-10-31 22:52:01,761 basehttp "GET /front/home/ HTTP/1.1" 500 215585
ERROR 2024-10-31 22:52:15,112 log Internal Server Error: /front/home/
Traceback (most recent call last):
  File "C:\Users\kevin\AppData\Roaming\Python\Python312\site-packages\django\template\base.py", line 875, in _resolve_lookup
    current = current[bit]
              ~~~~~~~^^^^^
TypeError: 'ImageFieldFile' object is not subscriptable

During handling of the above exception, another exception occurred:

Traceback (most recent call last):
  File "C:\Users\kevin\AppData\Roaming\Python\Python312\site-packages\django\core\handlers\exception.py", line 55, in inner
    response = get_response(request)
               ^^^^^^^^^^^^^^^^^^^^^
  File "C:\Users\kevin\AppData\Roaming\Python\Python312\site-packages\django\core\handlers\base.py", line 197, in _get_response
    response = wrapped_callback(request, *callback_args, **callback_kwargs)
               ^^^^^^^^^^^^^^^^^^^^^^^^^^^^^^^^^^^^^^^^^^^^^^^^^^^^^^^^^^^^
  File "C:\Users\kevin\Desktop\pantutienda-adp\front\views.py", line 186, in home
    return render(request, 'landing/index.html', context)
           ^^^^^^^^^^^^^^^^^^^^^^^^^^^^^^^^^^^^^^^^^^^^^^
  File "C:\Users\kevin\AppData\Roaming\Python\Python312\site-packages\django\shortcuts.py", line 25, in render
    content = loader.render_to_string(template_name, context, request, using=using)
              ^^^^^^^^^^^^^^^^^^^^^^^^^^^^^^^^^^^^^^^^^^^^^^^^^^^^^^^^^^^^^^^^^^^^^
  File "C:\Users\kevin\AppData\Roaming\Python\Python312\site-packages\django\template\loader.py", line 62, in render_to_string
    return template.render(context, request)
           ^^^^^^^^^^^^^^^^^^^^^^^^^^^^^^^^^
  File "C:\Users\kevin\AppData\Roaming\Python\Python312\site-packages\django\template\backends\django.py", line 61, in render
    return self.template.render(context)
           ^^^^^^^^^^^^^^^^^^^^^^^^^^^^^
  File "C:\Users\kevin\AppData\Roaming\Python\Python312\site-packages\django\template\base.py", line 171, in render
    return self._render(context)
           ^^^^^^^^^^^^^^^^^^^^^
  File "C:\Users\kevin\AppData\Roaming\Python\Python312\site-packages\django\template\base.py", line 163, in _render
    return self.nodelist.render(context)
           ^^^^^^^^^^^^^^^^^^^^^^^^^^^^^
  File "C:\Users\kevin\AppData\Roaming\Python\Python312\site-packages\django\template\base.py", line 1000, in render
    return SafeString("".join([node.render_annotated(context) for node in self]))
                               ^^^^^^^^^^^^^^^^^^^^^^^^^^^^^^
  File "C:\Users\kevin\AppData\Roaming\Python\Python312\site-packages\django\template\base.py", line 961, in render_annotated
    return self.render(context)
           ^^^^^^^^^^^^^^^^^^^^
  File "C:\Users\kevin\AppData\Roaming\Python\Python312\site-packages\django\template\loader_tags.py", line 159, in render
    return compiled_parent._render(context)
           ^^^^^^^^^^^^^^^^^^^^^^^^^^^^^^^^
  File "C:\Users\kevin\AppData\Roaming\Python\Python312\site-packages\django\template\base.py", line 163, in _render
    return self.nodelist.render(context)
           ^^^^^^^^^^^^^^^^^^^^^^^^^^^^^
  File "C:\Users\kevin\AppData\Roaming\Python\Python312\site-packages\django\template\base.py", line 1000, in render
    return SafeString("".join([node.render_annotated(context) for node in self]))
                               ^^^^^^^^^^^^^^^^^^^^^^^^^^^^^^
  File "C:\Users\kevin\AppData\Roaming\Python\Python312\site-packages\django\template\base.py", line 961, in render_annotated
    return self.render(context)
           ^^^^^^^^^^^^^^^^^^^^
  File "C:\Users\kevin\AppData\Roaming\Python\Python312\site-packages\django\template\loader_tags.py", line 65, in render
    result = block.nodelist.render(context)
             ^^^^^^^^^^^^^^^^^^^^^^^^^^^^^^
  File "C:\Users\kevin\AppData\Roaming\Python\Python312\site-packages\django\template\base.py", line 1000, in render
    return SafeString("".join([node.render_annotated(context) for node in self]))
                               ^^^^^^^^^^^^^^^^^^^^^^^^^^^^^^
  File "C:\Users\kevin\AppData\Roaming\Python\Python312\site-packages\django\template\base.py", line 961, in render_annotated
    return self.render(context)
           ^^^^^^^^^^^^^^^^^^^^
  File "C:\Users\kevin\AppData\Roaming\Python\Python312\site-packages\django\template\defaulttags.py", line 242, in render
    nodelist.append(node.render_annotated(context))
                    ^^^^^^^^^^^^^^^^^^^^^^^^^^^^^^
  File "C:\Users\kevin\AppData\Roaming\Python\Python312\site-packages\django\template\base.py", line 961, in render_annotated
    return self.render(context)
           ^^^^^^^^^^^^^^^^^^^^
  File "C:\Users\kevin\AppData\Roaming\Python\Python312\site-packages\django\template\defaulttags.py", line 326, in render
    return nodelist.render(context)
           ^^^^^^^^^^^^^^^^^^^^^^^^
  File "C:\Users\kevin\AppData\Roaming\Python\Python312\site-packages\django\template\base.py", line 1000, in render
    return SafeString("".join([node.render_annotated(context) for node in self]))
                               ^^^^^^^^^^^^^^^^^^^^^^^^^^^^^^
  File "C:\Users\kevin\AppData\Roaming\Python\Python312\site-packages\django\template\base.py", line 961, in render_annotated
    return self.render(context)
           ^^^^^^^^^^^^^^^^^^^^
  File "C:\Users\kevin\AppData\Roaming\Python\Python312\site-packages\django\template\loader_tags.py", line 210, in render
    return template.render(context)
           ^^^^^^^^^^^^^^^^^^^^^^^^
  File "C:\Users\kevin\AppData\Roaming\Python\Python312\site-packages\django\template\base.py", line 173, in render
    return self._render(context)
           ^^^^^^^^^^^^^^^^^^^^^
  File "C:\Users\kevin\AppData\Roaming\Python\Python312\site-packages\django\template\base.py", line 163, in _render
    return self.nodelist.render(context)
           ^^^^^^^^^^^^^^^^^^^^^^^^^^^^^
  File "C:\Users\kevin\AppData\Roaming\Python\Python312\site-packages\django\template\base.py", line 1000, in render
    return SafeString("".join([node.render_annotated(context) for node in self]))
                               ^^^^^^^^^^^^^^^^^^^^^^^^^^^^^^
  File "C:\Users\kevin\AppData\Roaming\Python\Python312\site-packages\django\template\base.py", line 961, in render_annotated
    return self.render(context)
           ^^^^^^^^^^^^^^^^^^^^
  File "C:\Users\kevin\AppData\Roaming\Python\Python312\site-packages\django\template\base.py", line 1059, in render
    output = self.filter_expression.resolve(context)
             ^^^^^^^^^^^^^^^^^^^^^^^^^^^^^^^^^^^^^^^
  File "C:\Users\kevin\AppData\Roaming\Python\Python312\site-packages\django\template\base.py", line 710, in resolve
    obj = self.var.resolve(context)
          ^^^^^^^^^^^^^^^^^^^^^^^^^
  File "C:\Users\kevin\AppData\Roaming\Python\Python312\site-packages\django\template\base.py", line 842, in resolve
    value = self._resolve_lookup(context)
            ^^^^^^^^^^^^^^^^^^^^^^^^^^^^^
  File "C:\Users\kevin\AppData\Roaming\Python\Python312\site-packages\django\template\base.py", line 885, in _resolve_lookup
    current = getattr(current, bit)
              ^^^^^^^^^^^^^^^^^^^^^
  File "C:\Users\kevin\AppData\Roaming\Python\Python312\site-packages\django\db\models\fields\files.py", line 66, in url
    self._require_file()
  File "C:\Users\kevin\AppData\Roaming\Python\Python312\site-packages\django\db\models\fields\files.py", line 41, in _require_file
    raise ValueError(
ValueError: The 'banner_1_image' attribute has no file associated with it.
ERROR 2024-10-31 22:52:15,119 basehttp "GET /front/home/ HTTP/1.1" 500 254957
ERROR 2024-10-31 22:52:48,900 log Internal Server Error: /front/home/
Traceback (most recent call last):
  File "C:\Users\kevin\AppData\Roaming\Python\Python312\site-packages\django\template\base.py", line 875, in _resolve_lookup
    current = current[bit]
              ~~~~~~~^^^^^
TypeError: 'ImageFieldFile' object is not subscriptable

During handling of the above exception, another exception occurred:

Traceback (most recent call last):
  File "C:\Users\kevin\AppData\Roaming\Python\Python312\site-packages\django\core\handlers\exception.py", line 55, in inner
    response = get_response(request)
               ^^^^^^^^^^^^^^^^^^^^^
  File "C:\Users\kevin\AppData\Roaming\Python\Python312\site-packages\django\core\handlers\base.py", line 197, in _get_response
    response = wrapped_callback(request, *callback_args, **callback_kwargs)
               ^^^^^^^^^^^^^^^^^^^^^^^^^^^^^^^^^^^^^^^^^^^^^^^^^^^^^^^^^^^^
  File "C:\Users\kevin\Desktop\pantutienda-adp\front\views.py", line 186, in home
    return render(request, 'landing/index.html', context)
           ^^^^^^^^^^^^^^^^^^^^^^^^^^^^^^^^^^^^^^^^^^^^^^
  File "C:\Users\kevin\AppData\Roaming\Python\Python312\site-packages\django\shortcuts.py", line 25, in render
    content = loader.render_to_string(template_name, context, request, using=using)
              ^^^^^^^^^^^^^^^^^^^^^^^^^^^^^^^^^^^^^^^^^^^^^^^^^^^^^^^^^^^^^^^^^^^^^
  File "C:\Users\kevin\AppData\Roaming\Python\Python312\site-packages\django\template\loader.py", line 62, in render_to_string
    return template.render(context, request)
           ^^^^^^^^^^^^^^^^^^^^^^^^^^^^^^^^^
  File "C:\Users\kevin\AppData\Roaming\Python\Python312\site-packages\django\template\backends\django.py", line 61, in render
    return self.template.render(context)
           ^^^^^^^^^^^^^^^^^^^^^^^^^^^^^
  File "C:\Users\kevin\AppData\Roaming\Python\Python312\site-packages\django\template\base.py", line 171, in render
    return self._render(context)
           ^^^^^^^^^^^^^^^^^^^^^
  File "C:\Users\kevin\AppData\Roaming\Python\Python312\site-packages\django\template\base.py", line 163, in _render
    return self.nodelist.render(context)
           ^^^^^^^^^^^^^^^^^^^^^^^^^^^^^
  File "C:\Users\kevin\AppData\Roaming\Python\Python312\site-packages\django\template\base.py", line 1000, in render
    return SafeString("".join([node.render_annotated(context) for node in self]))
                               ^^^^^^^^^^^^^^^^^^^^^^^^^^^^^^
  File "C:\Users\kevin\AppData\Roaming\Python\Python312\site-packages\django\template\base.py", line 961, in render_annotated
    return self.render(context)
           ^^^^^^^^^^^^^^^^^^^^
  File "C:\Users\kevin\AppData\Roaming\Python\Python312\site-packages\django\template\loader_tags.py", line 159, in render
    return compiled_parent._render(context)
           ^^^^^^^^^^^^^^^^^^^^^^^^^^^^^^^^
  File "C:\Users\kevin\AppData\Roaming\Python\Python312\site-packages\django\template\base.py", line 163, in _render
    return self.nodelist.render(context)
           ^^^^^^^^^^^^^^^^^^^^^^^^^^^^^
  File "C:\Users\kevin\AppData\Roaming\Python\Python312\site-packages\django\template\base.py", line 1000, in render
    return SafeString("".join([node.render_annotated(context) for node in self]))
                               ^^^^^^^^^^^^^^^^^^^^^^^^^^^^^^
  File "C:\Users\kevin\AppData\Roaming\Python\Python312\site-packages\django\template\base.py", line 961, in render_annotated
    return self.render(context)
           ^^^^^^^^^^^^^^^^^^^^
  File "C:\Users\kevin\AppData\Roaming\Python\Python312\site-packages\django\template\loader_tags.py", line 65, in render
    result = block.nodelist.render(context)
             ^^^^^^^^^^^^^^^^^^^^^^^^^^^^^^
  File "C:\Users\kevin\AppData\Roaming\Python\Python312\site-packages\django\template\base.py", line 1000, in render
    return SafeString("".join([node.render_annotated(context) for node in self]))
                               ^^^^^^^^^^^^^^^^^^^^^^^^^^^^^^
  File "C:\Users\kevin\AppData\Roaming\Python\Python312\site-packages\django\template\base.py", line 961, in render_annotated
    return self.render(context)
           ^^^^^^^^^^^^^^^^^^^^
  File "C:\Users\kevin\AppData\Roaming\Python\Python312\site-packages\django\template\defaulttags.py", line 242, in render
    nodelist.append(node.render_annotated(context))
                    ^^^^^^^^^^^^^^^^^^^^^^^^^^^^^^
  File "C:\Users\kevin\AppData\Roaming\Python\Python312\site-packages\django\template\base.py", line 961, in render_annotated
    return self.render(context)
           ^^^^^^^^^^^^^^^^^^^^
  File "C:\Users\kevin\AppData\Roaming\Python\Python312\site-packages\django\template\defaulttags.py", line 326, in render
    return nodelist.render(context)
           ^^^^^^^^^^^^^^^^^^^^^^^^
  File "C:\Users\kevin\AppData\Roaming\Python\Python312\site-packages\django\template\base.py", line 1000, in render
    return SafeString("".join([node.render_annotated(context) for node in self]))
                               ^^^^^^^^^^^^^^^^^^^^^^^^^^^^^^
  File "C:\Users\kevin\AppData\Roaming\Python\Python312\site-packages\django\template\base.py", line 961, in render_annotated
    return self.render(context)
           ^^^^^^^^^^^^^^^^^^^^
  File "C:\Users\kevin\AppData\Roaming\Python\Python312\site-packages\django\template\loader_tags.py", line 210, in render
    return template.render(context)
           ^^^^^^^^^^^^^^^^^^^^^^^^
  File "C:\Users\kevin\AppData\Roaming\Python\Python312\site-packages\django\template\base.py", line 173, in render
    return self._render(context)
           ^^^^^^^^^^^^^^^^^^^^^
  File "C:\Users\kevin\AppData\Roaming\Python\Python312\site-packages\django\template\base.py", line 163, in _render
    return self.nodelist.render(context)
           ^^^^^^^^^^^^^^^^^^^^^^^^^^^^^
  File "C:\Users\kevin\AppData\Roaming\Python\Python312\site-packages\django\template\base.py", line 1000, in render
    return SafeString("".join([node.render_annotated(context) for node in self]))
                               ^^^^^^^^^^^^^^^^^^^^^^^^^^^^^^
  File "C:\Users\kevin\AppData\Roaming\Python\Python312\site-packages\django\template\base.py", line 961, in render_annotated
    return self.render(context)
           ^^^^^^^^^^^^^^^^^^^^
  File "C:\Users\kevin\AppData\Roaming\Python\Python312\site-packages\django\template\base.py", line 1059, in render
    output = self.filter_expression.resolve(context)
             ^^^^^^^^^^^^^^^^^^^^^^^^^^^^^^^^^^^^^^^
  File "C:\Users\kevin\AppData\Roaming\Python\Python312\site-packages\django\template\base.py", line 710, in resolve
    obj = self.var.resolve(context)
          ^^^^^^^^^^^^^^^^^^^^^^^^^
  File "C:\Users\kevin\AppData\Roaming\Python\Python312\site-packages\django\template\base.py", line 842, in resolve
    value = self._resolve_lookup(context)
            ^^^^^^^^^^^^^^^^^^^^^^^^^^^^^
  File "C:\Users\kevin\AppData\Roaming\Python\Python312\site-packages\django\template\base.py", line 885, in _resolve_lookup
    current = getattr(current, bit)
              ^^^^^^^^^^^^^^^^^^^^^
  File "C:\Users\kevin\AppData\Roaming\Python\Python312\site-packages\django\db\models\fields\files.py", line 66, in url
    self._require_file()
  File "C:\Users\kevin\AppData\Roaming\Python\Python312\site-packages\django\db\models\fields\files.py", line 41, in _require_file
    raise ValueError(
ValueError: The 'banner_2_image' attribute has no file associated with it.
ERROR 2024-10-31 22:52:48,903 basehttp "GET /front/home/ HTTP/1.1" 500 254887
ERROR 2024-10-31 22:52:49,398 log Internal Server Error: /front/home/
Traceback (most recent call last):
  File "C:\Users\kevin\AppData\Roaming\Python\Python312\site-packages\django\template\base.py", line 875, in _resolve_lookup
    current = current[bit]
              ~~~~~~~^^^^^
TypeError: 'ImageFieldFile' object is not subscriptable

During handling of the above exception, another exception occurred:

Traceback (most recent call last):
  File "C:\Users\kevin\AppData\Roaming\Python\Python312\site-packages\django\core\handlers\exception.py", line 55, in inner
    response = get_response(request)
               ^^^^^^^^^^^^^^^^^^^^^
  File "C:\Users\kevin\AppData\Roaming\Python\Python312\site-packages\django\core\handlers\base.py", line 197, in _get_response
    response = wrapped_callback(request, *callback_args, **callback_kwargs)
               ^^^^^^^^^^^^^^^^^^^^^^^^^^^^^^^^^^^^^^^^^^^^^^^^^^^^^^^^^^^^
  File "C:\Users\kevin\Desktop\pantutienda-adp\front\views.py", line 186, in home
    return render(request, 'landing/index.html', context)
           ^^^^^^^^^^^^^^^^^^^^^^^^^^^^^^^^^^^^^^^^^^^^^^
  File "C:\Users\kevin\AppData\Roaming\Python\Python312\site-packages\django\shortcuts.py", line 25, in render
    content = loader.render_to_string(template_name, context, request, using=using)
              ^^^^^^^^^^^^^^^^^^^^^^^^^^^^^^^^^^^^^^^^^^^^^^^^^^^^^^^^^^^^^^^^^^^^^
  File "C:\Users\kevin\AppData\Roaming\Python\Python312\site-packages\django\template\loader.py", line 62, in render_to_string
    return template.render(context, request)
           ^^^^^^^^^^^^^^^^^^^^^^^^^^^^^^^^^
  File "C:\Users\kevin\AppData\Roaming\Python\Python312\site-packages\django\template\backends\django.py", line 61, in render
    return self.template.render(context)
           ^^^^^^^^^^^^^^^^^^^^^^^^^^^^^
  File "C:\Users\kevin\AppData\Roaming\Python\Python312\site-packages\django\template\base.py", line 171, in render
    return self._render(context)
           ^^^^^^^^^^^^^^^^^^^^^
  File "C:\Users\kevin\AppData\Roaming\Python\Python312\site-packages\django\template\base.py", line 163, in _render
    return self.nodelist.render(context)
           ^^^^^^^^^^^^^^^^^^^^^^^^^^^^^
  File "C:\Users\kevin\AppData\Roaming\Python\Python312\site-packages\django\template\base.py", line 1000, in render
    return SafeString("".join([node.render_annotated(context) for node in self]))
                               ^^^^^^^^^^^^^^^^^^^^^^^^^^^^^^
  File "C:\Users\kevin\AppData\Roaming\Python\Python312\site-packages\django\template\base.py", line 961, in render_annotated
    return self.render(context)
           ^^^^^^^^^^^^^^^^^^^^
  File "C:\Users\kevin\AppData\Roaming\Python\Python312\site-packages\django\template\loader_tags.py", line 159, in render
    return compiled_parent._render(context)
           ^^^^^^^^^^^^^^^^^^^^^^^^^^^^^^^^
  File "C:\Users\kevin\AppData\Roaming\Python\Python312\site-packages\django\template\base.py", line 163, in _render
    return self.nodelist.render(context)
           ^^^^^^^^^^^^^^^^^^^^^^^^^^^^^
  File "C:\Users\kevin\AppData\Roaming\Python\Python312\site-packages\django\template\base.py", line 1000, in render
    return SafeString("".join([node.render_annotated(context) for node in self]))
                               ^^^^^^^^^^^^^^^^^^^^^^^^^^^^^^
  File "C:\Users\kevin\AppData\Roaming\Python\Python312\site-packages\django\template\base.py", line 961, in render_annotated
    return self.render(context)
           ^^^^^^^^^^^^^^^^^^^^
  File "C:\Users\kevin\AppData\Roaming\Python\Python312\site-packages\django\template\loader_tags.py", line 65, in render
    result = block.nodelist.render(context)
             ^^^^^^^^^^^^^^^^^^^^^^^^^^^^^^
  File "C:\Users\kevin\AppData\Roaming\Python\Python312\site-packages\django\template\base.py", line 1000, in render
    return SafeString("".join([node.render_annotated(context) for node in self]))
                               ^^^^^^^^^^^^^^^^^^^^^^^^^^^^^^
  File "C:\Users\kevin\AppData\Roaming\Python\Python312\site-packages\django\template\base.py", line 961, in render_annotated
    return self.render(context)
           ^^^^^^^^^^^^^^^^^^^^
  File "C:\Users\kevin\AppData\Roaming\Python\Python312\site-packages\django\template\defaulttags.py", line 242, in render
    nodelist.append(node.render_annotated(context))
                    ^^^^^^^^^^^^^^^^^^^^^^^^^^^^^^
  File "C:\Users\kevin\AppData\Roaming\Python\Python312\site-packages\django\template\base.py", line 961, in render_annotated
    return self.render(context)
           ^^^^^^^^^^^^^^^^^^^^
  File "C:\Users\kevin\AppData\Roaming\Python\Python312\site-packages\django\template\defaulttags.py", line 326, in render
    return nodelist.render(context)
           ^^^^^^^^^^^^^^^^^^^^^^^^
  File "C:\Users\kevin\AppData\Roaming\Python\Python312\site-packages\django\template\base.py", line 1000, in render
    return SafeString("".join([node.render_annotated(context) for node in self]))
                               ^^^^^^^^^^^^^^^^^^^^^^^^^^^^^^
  File "C:\Users\kevin\AppData\Roaming\Python\Python312\site-packages\django\template\base.py", line 961, in render_annotated
    return self.render(context)
           ^^^^^^^^^^^^^^^^^^^^
  File "C:\Users\kevin\AppData\Roaming\Python\Python312\site-packages\django\template\loader_tags.py", line 210, in render
    return template.render(context)
           ^^^^^^^^^^^^^^^^^^^^^^^^
  File "C:\Users\kevin\AppData\Roaming\Python\Python312\site-packages\django\template\base.py", line 173, in render
    return self._render(context)
           ^^^^^^^^^^^^^^^^^^^^^
  File "C:\Users\kevin\AppData\Roaming\Python\Python312\site-packages\django\template\base.py", line 163, in _render
    return self.nodelist.render(context)
           ^^^^^^^^^^^^^^^^^^^^^^^^^^^^^
  File "C:\Users\kevin\AppData\Roaming\Python\Python312\site-packages\django\template\base.py", line 1000, in render
    return SafeString("".join([node.render_annotated(context) for node in self]))
                               ^^^^^^^^^^^^^^^^^^^^^^^^^^^^^^
  File "C:\Users\kevin\AppData\Roaming\Python\Python312\site-packages\django\template\base.py", line 961, in render_annotated
    return self.render(context)
           ^^^^^^^^^^^^^^^^^^^^
  File "C:\Users\kevin\AppData\Roaming\Python\Python312\site-packages\django\template\base.py", line 1059, in render
    output = self.filter_expression.resolve(context)
             ^^^^^^^^^^^^^^^^^^^^^^^^^^^^^^^^^^^^^^^
  File "C:\Users\kevin\AppData\Roaming\Python\Python312\site-packages\django\template\base.py", line 710, in resolve
    obj = self.var.resolve(context)
          ^^^^^^^^^^^^^^^^^^^^^^^^^
  File "C:\Users\kevin\AppData\Roaming\Python\Python312\site-packages\django\template\base.py", line 842, in resolve
    value = self._resolve_lookup(context)
            ^^^^^^^^^^^^^^^^^^^^^^^^^^^^^
  File "C:\Users\kevin\AppData\Roaming\Python\Python312\site-packages\django\template\base.py", line 885, in _resolve_lookup
    current = getattr(current, bit)
              ^^^^^^^^^^^^^^^^^^^^^
  File "C:\Users\kevin\AppData\Roaming\Python\Python312\site-packages\django\db\models\fields\files.py", line 66, in url
    self._require_file()
  File "C:\Users\kevin\AppData\Roaming\Python\Python312\site-packages\django\db\models\fields\files.py", line 41, in _require_file
    raise ValueError(
ValueError: The 'banner_2_image' attribute has no file associated with it.
ERROR 2024-10-31 22:52:49,400 basehttp "GET /front/home/ HTTP/1.1" 500 254887
ERROR 2024-10-31 22:52:49,647 log Internal Server Error: /front/home/
Traceback (most recent call last):
  File "C:\Users\kevin\AppData\Roaming\Python\Python312\site-packages\django\template\base.py", line 875, in _resolve_lookup
    current = current[bit]
              ~~~~~~~^^^^^
TypeError: 'ImageFieldFile' object is not subscriptable

During handling of the above exception, another exception occurred:

Traceback (most recent call last):
  File "C:\Users\kevin\AppData\Roaming\Python\Python312\site-packages\django\core\handlers\exception.py", line 55, in inner
    response = get_response(request)
               ^^^^^^^^^^^^^^^^^^^^^
  File "C:\Users\kevin\AppData\Roaming\Python\Python312\site-packages\django\core\handlers\base.py", line 197, in _get_response
    response = wrapped_callback(request, *callback_args, **callback_kwargs)
               ^^^^^^^^^^^^^^^^^^^^^^^^^^^^^^^^^^^^^^^^^^^^^^^^^^^^^^^^^^^^
  File "C:\Users\kevin\Desktop\pantutienda-adp\front\views.py", line 186, in home
    return render(request, 'landing/index.html', context)
           ^^^^^^^^^^^^^^^^^^^^^^^^^^^^^^^^^^^^^^^^^^^^^^
  File "C:\Users\kevin\AppData\Roaming\Python\Python312\site-packages\django\shortcuts.py", line 25, in render
    content = loader.render_to_string(template_name, context, request, using=using)
              ^^^^^^^^^^^^^^^^^^^^^^^^^^^^^^^^^^^^^^^^^^^^^^^^^^^^^^^^^^^^^^^^^^^^^
  File "C:\Users\kevin\AppData\Roaming\Python\Python312\site-packages\django\template\loader.py", line 62, in render_to_string
    return template.render(context, request)
           ^^^^^^^^^^^^^^^^^^^^^^^^^^^^^^^^^
  File "C:\Users\kevin\AppData\Roaming\Python\Python312\site-packages\django\template\backends\django.py", line 61, in render
    return self.template.render(context)
           ^^^^^^^^^^^^^^^^^^^^^^^^^^^^^
  File "C:\Users\kevin\AppData\Roaming\Python\Python312\site-packages\django\template\base.py", line 171, in render
    return self._render(context)
           ^^^^^^^^^^^^^^^^^^^^^
  File "C:\Users\kevin\AppData\Roaming\Python\Python312\site-packages\django\template\base.py", line 163, in _render
    return self.nodelist.render(context)
           ^^^^^^^^^^^^^^^^^^^^^^^^^^^^^
  File "C:\Users\kevin\AppData\Roaming\Python\Python312\site-packages\django\template\base.py", line 1000, in render
    return SafeString("".join([node.render_annotated(context) for node in self]))
                               ^^^^^^^^^^^^^^^^^^^^^^^^^^^^^^
  File "C:\Users\kevin\AppData\Roaming\Python\Python312\site-packages\django\template\base.py", line 961, in render_annotated
    return self.render(context)
           ^^^^^^^^^^^^^^^^^^^^
  File "C:\Users\kevin\AppData\Roaming\Python\Python312\site-packages\django\template\loader_tags.py", line 159, in render
    return compiled_parent._render(context)
           ^^^^^^^^^^^^^^^^^^^^^^^^^^^^^^^^
  File "C:\Users\kevin\AppData\Roaming\Python\Python312\site-packages\django\template\base.py", line 163, in _render
    return self.nodelist.render(context)
           ^^^^^^^^^^^^^^^^^^^^^^^^^^^^^
  File "C:\Users\kevin\AppData\Roaming\Python\Python312\site-packages\django\template\base.py", line 1000, in render
    return SafeString("".join([node.render_annotated(context) for node in self]))
                               ^^^^^^^^^^^^^^^^^^^^^^^^^^^^^^
  File "C:\Users\kevin\AppData\Roaming\Python\Python312\site-packages\django\template\base.py", line 961, in render_annotated
    return self.render(context)
           ^^^^^^^^^^^^^^^^^^^^
  File "C:\Users\kevin\AppData\Roaming\Python\Python312\site-packages\django\template\loader_tags.py", line 65, in render
    result = block.nodelist.render(context)
             ^^^^^^^^^^^^^^^^^^^^^^^^^^^^^^
  File "C:\Users\kevin\AppData\Roaming\Python\Python312\site-packages\django\template\base.py", line 1000, in render
    return SafeString("".join([node.render_annotated(context) for node in self]))
                               ^^^^^^^^^^^^^^^^^^^^^^^^^^^^^^
  File "C:\Users\kevin\AppData\Roaming\Python\Python312\site-packages\django\template\base.py", line 961, in render_annotated
    return self.render(context)
           ^^^^^^^^^^^^^^^^^^^^
  File "C:\Users\kevin\AppData\Roaming\Python\Python312\site-packages\django\template\defaulttags.py", line 242, in render
    nodelist.append(node.render_annotated(context))
                    ^^^^^^^^^^^^^^^^^^^^^^^^^^^^^^
  File "C:\Users\kevin\AppData\Roaming\Python\Python312\site-packages\django\template\base.py", line 961, in render_annotated
    return self.render(context)
           ^^^^^^^^^^^^^^^^^^^^
  File "C:\Users\kevin\AppData\Roaming\Python\Python312\site-packages\django\template\defaulttags.py", line 326, in render
    return nodelist.render(context)
           ^^^^^^^^^^^^^^^^^^^^^^^^
  File "C:\Users\kevin\AppData\Roaming\Python\Python312\site-packages\django\template\base.py", line 1000, in render
    return SafeString("".join([node.render_annotated(context) for node in self]))
                               ^^^^^^^^^^^^^^^^^^^^^^^^^^^^^^
  File "C:\Users\kevin\AppData\Roaming\Python\Python312\site-packages\django\template\base.py", line 961, in render_annotated
    return self.render(context)
           ^^^^^^^^^^^^^^^^^^^^
  File "C:\Users\kevin\AppData\Roaming\Python\Python312\site-packages\django\template\loader_tags.py", line 210, in render
    return template.render(context)
           ^^^^^^^^^^^^^^^^^^^^^^^^
  File "C:\Users\kevin\AppData\Roaming\Python\Python312\site-packages\django\template\base.py", line 173, in render
    return self._render(context)
           ^^^^^^^^^^^^^^^^^^^^^
  File "C:\Users\kevin\AppData\Roaming\Python\Python312\site-packages\django\template\base.py", line 163, in _render
    return self.nodelist.render(context)
           ^^^^^^^^^^^^^^^^^^^^^^^^^^^^^
  File "C:\Users\kevin\AppData\Roaming\Python\Python312\site-packages\django\template\base.py", line 1000, in render
    return SafeString("".join([node.render_annotated(context) for node in self]))
                               ^^^^^^^^^^^^^^^^^^^^^^^^^^^^^^
  File "C:\Users\kevin\AppData\Roaming\Python\Python312\site-packages\django\template\base.py", line 961, in render_annotated
    return self.render(context)
           ^^^^^^^^^^^^^^^^^^^^
  File "C:\Users\kevin\AppData\Roaming\Python\Python312\site-packages\django\template\base.py", line 1059, in render
    output = self.filter_expression.resolve(context)
             ^^^^^^^^^^^^^^^^^^^^^^^^^^^^^^^^^^^^^^^
  File "C:\Users\kevin\AppData\Roaming\Python\Python312\site-packages\django\template\base.py", line 710, in resolve
    obj = self.var.resolve(context)
          ^^^^^^^^^^^^^^^^^^^^^^^^^
  File "C:\Users\kevin\AppData\Roaming\Python\Python312\site-packages\django\template\base.py", line 842, in resolve
    value = self._resolve_lookup(context)
            ^^^^^^^^^^^^^^^^^^^^^^^^^^^^^
  File "C:\Users\kevin\AppData\Roaming\Python\Python312\site-packages\django\template\base.py", line 885, in _resolve_lookup
    current = getattr(current, bit)
              ^^^^^^^^^^^^^^^^^^^^^
  File "C:\Users\kevin\AppData\Roaming\Python\Python312\site-packages\django\db\models\fields\files.py", line 66, in url
    self._require_file()
  File "C:\Users\kevin\AppData\Roaming\Python\Python312\site-packages\django\db\models\fields\files.py", line 41, in _require_file
    raise ValueError(
ValueError: The 'banner_2_image' attribute has no file associated with it.
ERROR 2024-10-31 22:52:49,650 basehttp "GET /front/home/ HTTP/1.1" 500 254887
ERROR 2024-10-31 23:14:38,549 log Internal Server Error: /front/home/
Traceback (most recent call last):
  File "C:\Users\kevin\AppData\Roaming\Python\Python312\site-packages\django\core\handlers\exception.py", line 55, in inner
    response = get_response(request)
               ^^^^^^^^^^^^^^^^^^^^^
  File "C:\Users\kevin\AppData\Roaming\Python\Python312\site-packages\django\core\handlers\base.py", line 197, in _get_response
    response = wrapped_callback(request, *callback_args, **callback_kwargs)
               ^^^^^^^^^^^^^^^^^^^^^^^^^^^^^^^^^^^^^^^^^^^^^^^^^^^^^^^^^^^^
  File "C:\Users\kevin\Desktop\pantutienda-adp\front\views.py", line 186, in home
    return render(request, 'landing/index.html', context)
           ^^^^^^^^^^^^^^^^^^^^^^^^^^^^^^^^^^^^^^^^^^^^^^
  File "C:\Users\kevin\AppData\Roaming\Python\Python312\site-packages\django\shortcuts.py", line 25, in render
    content = loader.render_to_string(template_name, context, request, using=using)
              ^^^^^^^^^^^^^^^^^^^^^^^^^^^^^^^^^^^^^^^^^^^^^^^^^^^^^^^^^^^^^^^^^^^^^
  File "C:\Users\kevin\AppData\Roaming\Python\Python312\site-packages\django\template\loader.py", line 62, in render_to_string
    return template.render(context, request)
           ^^^^^^^^^^^^^^^^^^^^^^^^^^^^^^^^^
  File "C:\Users\kevin\AppData\Roaming\Python\Python312\site-packages\django\template\backends\django.py", line 61, in render
    return self.template.render(context)
           ^^^^^^^^^^^^^^^^^^^^^^^^^^^^^
  File "C:\Users\kevin\AppData\Roaming\Python\Python312\site-packages\django\template\base.py", line 171, in render
    return self._render(context)
           ^^^^^^^^^^^^^^^^^^^^^
  File "C:\Users\kevin\AppData\Roaming\Python\Python312\site-packages\django\template\base.py", line 163, in _render
    return self.nodelist.render(context)
           ^^^^^^^^^^^^^^^^^^^^^^^^^^^^^
  File "C:\Users\kevin\AppData\Roaming\Python\Python312\site-packages\django\template\base.py", line 1000, in render
    return SafeString("".join([node.render_annotated(context) for node in self]))
                               ^^^^^^^^^^^^^^^^^^^^^^^^^^^^^^
  File "C:\Users\kevin\AppData\Roaming\Python\Python312\site-packages\django\template\base.py", line 961, in render_annotated
    return self.render(context)
           ^^^^^^^^^^^^^^^^^^^^
  File "C:\Users\kevin\AppData\Roaming\Python\Python312\site-packages\django\template\loader_tags.py", line 159, in render
    return compiled_parent._render(context)
           ^^^^^^^^^^^^^^^^^^^^^^^^^^^^^^^^
  File "C:\Users\kevin\AppData\Roaming\Python\Python312\site-packages\django\template\base.py", line 163, in _render
    return self.nodelist.render(context)
           ^^^^^^^^^^^^^^^^^^^^^^^^^^^^^
  File "C:\Users\kevin\AppData\Roaming\Python\Python312\site-packages\django\template\base.py", line 1000, in render
    return SafeString("".join([node.render_annotated(context) for node in self]))
                               ^^^^^^^^^^^^^^^^^^^^^^^^^^^^^^
  File "C:\Users\kevin\AppData\Roaming\Python\Python312\site-packages\django\template\base.py", line 961, in render_annotated
    return self.render(context)
           ^^^^^^^^^^^^^^^^^^^^
  File "C:\Users\kevin\AppData\Roaming\Python\Python312\site-packages\django\template\loader_tags.py", line 65, in render
    result = block.nodelist.render(context)
             ^^^^^^^^^^^^^^^^^^^^^^^^^^^^^^
  File "C:\Users\kevin\AppData\Roaming\Python\Python312\site-packages\django\template\base.py", line 1000, in render
    return SafeString("".join([node.render_annotated(context) for node in self]))
                               ^^^^^^^^^^^^^^^^^^^^^^^^^^^^^^
  File "C:\Users\kevin\AppData\Roaming\Python\Python312\site-packages\django\template\base.py", line 961, in render_annotated
    return self.render(context)
           ^^^^^^^^^^^^^^^^^^^^
  File "C:\Users\kevin\AppData\Roaming\Python\Python312\site-packages\django\template\defaulttags.py", line 242, in render
    nodelist.append(node.render_annotated(context))
                    ^^^^^^^^^^^^^^^^^^^^^^^^^^^^^^
  File "C:\Users\kevin\AppData\Roaming\Python\Python312\site-packages\django\template\base.py", line 961, in render_annotated
    return self.render(context)
           ^^^^^^^^^^^^^^^^^^^^
  File "C:\Users\kevin\AppData\Roaming\Python\Python312\site-packages\django\template\defaulttags.py", line 326, in render
    return nodelist.render(context)
           ^^^^^^^^^^^^^^^^^^^^^^^^
  File "C:\Users\kevin\AppData\Roaming\Python\Python312\site-packages\django\template\base.py", line 1000, in render
    return SafeString("".join([node.render_annotated(context) for node in self]))
                               ^^^^^^^^^^^^^^^^^^^^^^^^^^^^^^
  File "C:\Users\kevin\AppData\Roaming\Python\Python312\site-packages\django\template\base.py", line 961, in render_annotated
    return self.render(context)
           ^^^^^^^^^^^^^^^^^^^^
  File "C:\Users\kevin\AppData\Roaming\Python\Python312\site-packages\django\template\loader_tags.py", line 199, in render
    template = context.template.engine.select_template(template_name)
               ^^^^^^^^^^^^^^^^^^^^^^^^^^^^^^^^^^^^^^^^^^^^^^^^^^^^^^
  File "C:\Users\kevin\AppData\Roaming\Python\Python312\site-packages\django\template\engine.py", line 208, in select_template
    return self.get_template(template_name)
           ^^^^^^^^^^^^^^^^^^^^^^^^^^^^^^^^
  File "C:\Users\kevin\AppData\Roaming\Python\Python312\site-packages\django\template\engine.py", line 177, in get_template
    template, origin = self.find_template(template_name)
                       ^^^^^^^^^^^^^^^^^^^^^^^^^^^^^^^^^
  File "C:\Users\kevin\AppData\Roaming\Python\Python312\site-packages\django\template\engine.py", line 159, in find_template
    template = loader.get_template(name, skip=skip)
               ^^^^^^^^^^^^^^^^^^^^^^^^^^^^^^^^^^^^
  File "C:\Users\kevin\AppData\Roaming\Python\Python312\site-packages\django\template\loaders\cached.py", line 57, in get_template
    template = super().get_template(template_name, skip)
               ^^^^^^^^^^^^^^^^^^^^^^^^^^^^^^^^^^^^^^^^^
  File "C:\Users\kevin\AppData\Roaming\Python\Python312\site-packages\django\template\loaders\base.py", line 28, in get_template
    return Template(
           ^^^^^^^^^
  File "C:\Users\kevin\AppData\Roaming\Python\Python312\site-packages\django\template\base.py", line 154, in __init__
    self.nodelist = self.compile_nodelist()
                    ^^^^^^^^^^^^^^^^^^^^^^^
  File "C:\Users\kevin\AppData\Roaming\Python\Python312\site-packages\django\template\base.py", line 196, in compile_nodelist
    return parser.parse()
           ^^^^^^^^^^^^^^
  File "C:\Users\kevin\AppData\Roaming\Python\Python312\site-packages\django\template\base.py", line 510, in parse
    raise self.error(token, e)
  File "C:\Users\kevin\AppData\Roaming\Python\Python312\site-packages\django\template\base.py", line 508, in parse
    compiled_result = compile_func(self, token)
                      ^^^^^^^^^^^^^^^^^^^^^^^^^
  File "C:\Users\kevin\AppData\Roaming\Python\Python312\site-packages\django\template\defaulttags.py", line 861, in do_for
    nodelist_loop = parser.parse(
                    ^^^^^^^^^^^^^
  File "C:\Users\kevin\AppData\Roaming\Python\Python312\site-packages\django\template\base.py", line 481, in parse
    raise self.error(token, e)
  File "C:\Users\kevin\AppData\Roaming\Python\Python312\site-packages\django\template\base.py", line 479, in parse
    filter_expression = self.compile_filter(token.contents)
                        ^^^^^^^^^^^^^^^^^^^^^^^^^^^^^^^^^^^
  File "C:\Users\kevin\AppData\Roaming\Python\Python312\site-packages\django\template\base.py", line 597, in compile_filter
    return FilterExpression(token, self)
           ^^^^^^^^^^^^^^^^^^^^^^^^^^^^^
  File "C:\Users\kevin\AppData\Roaming\Python\Python312\site-packages\django\template\base.py", line 693, in __init__
    filter_func = parser.find_filter(filter_name)
                  ^^^^^^^^^^^^^^^^^^^^^^^^^^^^^^^
  File "C:\Users\kevin\AppData\Roaming\Python\Python312\site-packages\django\template\base.py", line 603, in find_filter
    raise TemplateSyntaxError("Invalid filter: '%s'" % filter_name)
django.template.exceptions.TemplateSyntaxError: Invalid filter: 'getattr'
ERROR 2024-10-31 23:14:38,553 basehttp "GET /front/home/ HTTP/1.1" 500 288128
ERROR 2024-10-31 23:24:12,768 log Internal Server Error: /app/front/landing/1/change/
Traceback (most recent call last):
  File "C:\Users\kevin\AppData\Roaming\Python\Python312\site-packages\django\db\backends\utils.py", line 105, in _execute
    return self.cursor.execute(sql, params)
           ^^^^^^^^^^^^^^^^^^^^^^^^^^^^^^^^
  File "C:\Users\kevin\AppData\Roaming\Python\Python312\site-packages\django\db\backends\sqlite3\base.py", line 329, in execute
    return super().execute(query, params)
           ^^^^^^^^^^^^^^^^^^^^^^^^^^^^^^
sqlite3.OperationalError: no such column: front_landing.background_color_hww

The above exception was the direct cause of the following exception:

Traceback (most recent call last):
  File "C:\Users\kevin\AppData\Roaming\Python\Python312\site-packages\django\core\handlers\exception.py", line 55, in inner
    response = get_response(request)
               ^^^^^^^^^^^^^^^^^^^^^
  File "C:\Users\kevin\AppData\Roaming\Python\Python312\site-packages\django\core\handlers\base.py", line 197, in _get_response
    response = wrapped_callback(request, *callback_args, **callback_kwargs)
               ^^^^^^^^^^^^^^^^^^^^^^^^^^^^^^^^^^^^^^^^^^^^^^^^^^^^^^^^^^^^
  File "C:\Users\kevin\AppData\Roaming\Python\Python312\site-packages\django\contrib\admin\options.py", line 716, in wrapper
    return self.admin_site.admin_view(view)(*args, **kwargs)
           ^^^^^^^^^^^^^^^^^^^^^^^^^^^^^^^^^^^^^^^^^^^^^^^^^
  File "C:\Users\kevin\AppData\Roaming\Python\Python312\site-packages\django\utils\decorators.py", line 188, in _view_wrapper
    result = _process_exception(request, e)
             ^^^^^^^^^^^^^^^^^^^^^^^^^^^^^^
  File "C:\Users\kevin\AppData\Roaming\Python\Python312\site-packages\django\utils\decorators.py", line 186, in _view_wrapper
    response = view_func(request, *args, **kwargs)
               ^^^^^^^^^^^^^^^^^^^^^^^^^^^^^^^^^^^
  File "C:\Users\kevin\AppData\Roaming\Python\Python312\site-packages\django\views\decorators\cache.py", line 80, in _view_wrapper
    response = view_func(request, *args, **kwargs)
               ^^^^^^^^^^^^^^^^^^^^^^^^^^^^^^^^^^^
  File "C:\Users\kevin\AppData\Roaming\Python\Python312\site-packages\django\contrib\admin\sites.py", line 240, in inner
    return view(request, *args, **kwargs)
           ^^^^^^^^^^^^^^^^^^^^^^^^^^^^^^
  File "C:\Users\kevin\AppData\Roaming\Python\Python312\site-packages\django\contrib\admin\options.py", line 1948, in change_view
    return self.changeform_view(request, object_id, form_url, extra_context)
           ^^^^^^^^^^^^^^^^^^^^^^^^^^^^^^^^^^^^^^^^^^^^^^^^^^^^^^^^^^^^^^^^^
  File "C:\Users\kevin\AppData\Roaming\Python\Python312\site-packages\django\utils\decorators.py", line 48, in _wrapper
    return bound_method(*args, **kwargs)
           ^^^^^^^^^^^^^^^^^^^^^^^^^^^^^
  File "C:\Users\kevin\AppData\Roaming\Python\Python312\site-packages\django\utils\decorators.py", line 188, in _view_wrapper
    result = _process_exception(request, e)
             ^^^^^^^^^^^^^^^^^^^^^^^^^^^^^^
  File "C:\Users\kevin\AppData\Roaming\Python\Python312\site-packages\django\utils\decorators.py", line 186, in _view_wrapper
    response = view_func(request, *args, **kwargs)
               ^^^^^^^^^^^^^^^^^^^^^^^^^^^^^^^^^^^
  File "C:\Users\kevin\AppData\Roaming\Python\Python312\site-packages\django\contrib\admin\options.py", line 1804, in changeform_view
    return self._changeform_view(request, object_id, form_url, extra_context)
           ^^^^^^^^^^^^^^^^^^^^^^^^^^^^^^^^^^^^^^^^^^^^^^^^^^^^^^^^^^^^^^^^^^
  File "C:\Users\kevin\AppData\Roaming\Python\Python312\site-packages\django\contrib\admin\options.py", line 1824, in _changeform_view
    obj = self.get_object(request, unquote(object_id), to_field)
          ^^^^^^^^^^^^^^^^^^^^^^^^^^^^^^^^^^^^^^^^^^^^^^^^^^^^^^
  File "C:\Users\kevin\AppData\Roaming\Python\Python312\site-packages\django\contrib\admin\options.py", line 894, in get_object
    return queryset.get(**{field.name: object_id})
           ^^^^^^^^^^^^^^^^^^^^^^^^^^^^^^^^^^^^^^^
  File "C:\Users\kevin\AppData\Roaming\Python\Python312\site-packages\django\db\models\query.py", line 645, in get
    num = len(clone)
          ^^^^^^^^^^
  File "C:\Users\kevin\AppData\Roaming\Python\Python312\site-packages\django\db\models\query.py", line 382, in __len__
    self._fetch_all()
  File "C:\Users\kevin\AppData\Roaming\Python\Python312\site-packages\django\db\models\query.py", line 1928, in _fetch_all
    self._result_cache = list(self._iterable_class(self))
                         ^^^^^^^^^^^^^^^^^^^^^^^^^^^^^^^^
  File "C:\Users\kevin\AppData\Roaming\Python\Python312\site-packages\django\db\models\query.py", line 91, in __iter__
    results = compiler.execute_sql(
              ^^^^^^^^^^^^^^^^^^^^^
  File "C:\Users\kevin\AppData\Roaming\Python\Python312\site-packages\django\db\models\sql\compiler.py", line 1562, in execute_sql
    cursor.execute(sql, params)
  File "C:\Users\kevin\AppData\Roaming\Python\Python312\site-packages\django\db\backends\utils.py", line 122, in execute
    return super().execute(sql, params)
           ^^^^^^^^^^^^^^^^^^^^^^^^^^^^
  File "C:\Users\kevin\AppData\Roaming\Python\Python312\site-packages\django\db\backends\utils.py", line 79, in execute
    return self._execute_with_wrappers(
           ^^^^^^^^^^^^^^^^^^^^^^^^^^^^
  File "C:\Users\kevin\AppData\Roaming\Python\Python312\site-packages\django\db\backends\utils.py", line 92, in _execute_with_wrappers
    return executor(sql, params, many, context)
           ^^^^^^^^^^^^^^^^^^^^^^^^^^^^^^^^^^^^
  File "C:\Users\kevin\AppData\Roaming\Python\Python312\site-packages\django\db\backends\utils.py", line 100, in _execute
    with self.db.wrap_database_errors:
  File "C:\Users\kevin\AppData\Roaming\Python\Python312\site-packages\django\db\utils.py", line 91, in __exit__
    raise dj_exc_value.with_traceback(traceback) from exc_value
  File "C:\Users\kevin\AppData\Roaming\Python\Python312\site-packages\django\db\backends\utils.py", line 105, in _execute
    return self.cursor.execute(sql, params)
           ^^^^^^^^^^^^^^^^^^^^^^^^^^^^^^^^
  File "C:\Users\kevin\AppData\Roaming\Python\Python312\site-packages\django\db\backends\sqlite3\base.py", line 329, in execute
    return super().execute(query, params)
           ^^^^^^^^^^^^^^^^^^^^^^^^^^^^^^
django.db.utils.OperationalError: no such column: front_landing.background_color_hww
ERROR 2024-10-31 23:24:12,768 basehttp "GET /app/front/landing/1/change/ HTTP/1.1" 500 251088
ERROR 2024-10-31 23:24:13,370 log Internal Server Error: /front/home/
Traceback (most recent call last):
  File "C:\Users\kevin\AppData\Roaming\Python\Python312\site-packages\django\db\backends\utils.py", line 105, in _execute
    return self.cursor.execute(sql, params)
           ^^^^^^^^^^^^^^^^^^^^^^^^^^^^^^^^
  File "C:\Users\kevin\AppData\Roaming\Python\Python312\site-packages\django\db\backends\sqlite3\base.py", line 329, in execute
    return super().execute(query, params)
           ^^^^^^^^^^^^^^^^^^^^^^^^^^^^^^
sqlite3.OperationalError: no such column: front_landing.background_color_hww

The above exception was the direct cause of the following exception:

Traceback (most recent call last):
  File "C:\Users\kevin\AppData\Roaming\Python\Python312\site-packages\django\core\handlers\exception.py", line 55, in inner
    response = get_response(request)
               ^^^^^^^^^^^^^^^^^^^^^
  File "C:\Users\kevin\AppData\Roaming\Python\Python312\site-packages\django\core\handlers\base.py", line 197, in _get_response
    response = wrapped_callback(request, *callback_args, **callback_kwargs)
               ^^^^^^^^^^^^^^^^^^^^^^^^^^^^^^^^^^^^^^^^^^^^^^^^^^^^^^^^^^^^
  File "C:\Users\kevin\Desktop\pantutienda-adp\front\views.py", line 147, in home
    landing = Landing.objects.first()  # Asegúrate de que haya una landing en la base de datos
              ^^^^^^^^^^^^^^^^^^^^^^^
  File "C:\Users\kevin\AppData\Roaming\Python\Python312\site-packages\django\db\models\manager.py", line 87, in manager_method
    return getattr(self.get_queryset(), name)(*args, **kwargs)
           ^^^^^^^^^^^^^^^^^^^^^^^^^^^^^^^^^^^^^^^^^^^^^^^^^^^
  File "C:\Users\kevin\AppData\Roaming\Python\Python312\site-packages\django\db\models\query.py", line 1097, in first
    for obj in queryset[:1]:
  File "C:\Users\kevin\AppData\Roaming\Python\Python312\site-packages\django\db\models\query.py", line 400, in __iter__
    self._fetch_all()
  File "C:\Users\kevin\AppData\Roaming\Python\Python312\site-packages\django\db\models\query.py", line 1928, in _fetch_all
    self._result_cache = list(self._iterable_class(self))
                         ^^^^^^^^^^^^^^^^^^^^^^^^^^^^^^^^
  File "C:\Users\kevin\AppData\Roaming\Python\Python312\site-packages\django\db\models\query.py", line 91, in __iter__
    results = compiler.execute_sql(
              ^^^^^^^^^^^^^^^^^^^^^
  File "C:\Users\kevin\AppData\Roaming\Python\Python312\site-packages\django\db\models\sql\compiler.py", line 1562, in execute_sql
    cursor.execute(sql, params)
  File "C:\Users\kevin\AppData\Roaming\Python\Python312\site-packages\django\db\backends\utils.py", line 122, in execute
    return super().execute(sql, params)
           ^^^^^^^^^^^^^^^^^^^^^^^^^^^^
  File "C:\Users\kevin\AppData\Roaming\Python\Python312\site-packages\django\db\backends\utils.py", line 79, in execute
    return self._execute_with_wrappers(
           ^^^^^^^^^^^^^^^^^^^^^^^^^^^^
  File "C:\Users\kevin\AppData\Roaming\Python\Python312\site-packages\django\db\backends\utils.py", line 92, in _execute_with_wrappers
    return executor(sql, params, many, context)
           ^^^^^^^^^^^^^^^^^^^^^^^^^^^^^^^^^^^^
  File "C:\Users\kevin\AppData\Roaming\Python\Python312\site-packages\django\db\backends\utils.py", line 100, in _execute
    with self.db.wrap_database_errors:
  File "C:\Users\kevin\AppData\Roaming\Python\Python312\site-packages\django\db\utils.py", line 91, in __exit__
    raise dj_exc_value.with_traceback(traceback) from exc_value
  File "C:\Users\kevin\AppData\Roaming\Python\Python312\site-packages\django\db\backends\utils.py", line 105, in _execute
    return self.cursor.execute(sql, params)
           ^^^^^^^^^^^^^^^^^^^^^^^^^^^^^^^^
  File "C:\Users\kevin\AppData\Roaming\Python\Python312\site-packages\django\db\backends\sqlite3\base.py", line 329, in execute
    return super().execute(query, params)
           ^^^^^^^^^^^^^^^^^^^^^^^^^^^^^^
django.db.utils.OperationalError: no such column: front_landing.background_color_hww
ERROR 2024-10-31 23:24:13,370 basehttp "GET /front/home/ HTTP/1.1" 500 198363
ERROR 2024-10-31 23:24:36,863 log Internal Server Error: /app/front/landing/1/change/
Traceback (most recent call last):
  File "C:\Users\kevin\AppData\Roaming\Python\Python312\site-packages\django\contrib\admin\options.py", line 837, in get_form
    return modelform_factory(self.model, **defaults)
           ^^^^^^^^^^^^^^^^^^^^^^^^^^^^^^^^^^^^^^^^^
  File "C:\Users\kevin\AppData\Roaming\Python\Python312\site-packages\django\forms\models.py", line 652, in modelform_factory
    return type(form)(class_name, (form,), form_class_attrs)
           ^^^^^^^^^^^^^^^^^^^^^^^^^^^^^^^^^^^^^^^^^^^^^^^^^
  File "C:\Users\kevin\AppData\Roaming\Python\Python312\site-packages\django\forms\models.py", line 332, in __new__
    raise FieldError(message)
django.core.exceptions.FieldError: Unknown field(s) (background_color) specified for Landing

During handling of the above exception, another exception occurred:

Traceback (most recent call last):
  File "C:\Users\kevin\AppData\Roaming\Python\Python312\site-packages\django\core\handlers\exception.py", line 55, in inner
    response = get_response(request)
               ^^^^^^^^^^^^^^^^^^^^^
  File "C:\Users\kevin\AppData\Roaming\Python\Python312\site-packages\django\core\handlers\base.py", line 197, in _get_response
    response = wrapped_callback(request, *callback_args, **callback_kwargs)
               ^^^^^^^^^^^^^^^^^^^^^^^^^^^^^^^^^^^^^^^^^^^^^^^^^^^^^^^^^^^^
  File "C:\Users\kevin\AppData\Roaming\Python\Python312\site-packages\django\contrib\admin\options.py", line 716, in wrapper
    return self.admin_site.admin_view(view)(*args, **kwargs)
           ^^^^^^^^^^^^^^^^^^^^^^^^^^^^^^^^^^^^^^^^^^^^^^^^^
  File "C:\Users\kevin\AppData\Roaming\Python\Python312\site-packages\django\utils\decorators.py", line 188, in _view_wrapper
    result = _process_exception(request, e)
             ^^^^^^^^^^^^^^^^^^^^^^^^^^^^^^
  File "C:\Users\kevin\AppData\Roaming\Python\Python312\site-packages\django\utils\decorators.py", line 186, in _view_wrapper
    response = view_func(request, *args, **kwargs)
               ^^^^^^^^^^^^^^^^^^^^^^^^^^^^^^^^^^^
  File "C:\Users\kevin\AppData\Roaming\Python\Python312\site-packages\django\views\decorators\cache.py", line 80, in _view_wrapper
    response = view_func(request, *args, **kwargs)
               ^^^^^^^^^^^^^^^^^^^^^^^^^^^^^^^^^^^
  File "C:\Users\kevin\AppData\Roaming\Python\Python312\site-packages\django\contrib\admin\sites.py", line 240, in inner
    return view(request, *args, **kwargs)
           ^^^^^^^^^^^^^^^^^^^^^^^^^^^^^^
  File "C:\Users\kevin\AppData\Roaming\Python\Python312\site-packages\django\contrib\admin\options.py", line 1948, in change_view
    return self.changeform_view(request, object_id, form_url, extra_context)
           ^^^^^^^^^^^^^^^^^^^^^^^^^^^^^^^^^^^^^^^^^^^^^^^^^^^^^^^^^^^^^^^^^
  File "C:\Users\kevin\AppData\Roaming\Python\Python312\site-packages\django\utils\decorators.py", line 48, in _wrapper
    return bound_method(*args, **kwargs)
           ^^^^^^^^^^^^^^^^^^^^^^^^^^^^^
  File "C:\Users\kevin\AppData\Roaming\Python\Python312\site-packages\django\utils\decorators.py", line 188, in _view_wrapper
    result = _process_exception(request, e)
             ^^^^^^^^^^^^^^^^^^^^^^^^^^^^^^
  File "C:\Users\kevin\AppData\Roaming\Python\Python312\site-packages\django\utils\decorators.py", line 186, in _view_wrapper
    response = view_func(request, *args, **kwargs)
               ^^^^^^^^^^^^^^^^^^^^^^^^^^^^^^^^^^^
  File "C:\Users\kevin\AppData\Roaming\Python\Python312\site-packages\django\contrib\admin\options.py", line 1804, in changeform_view
    return self._changeform_view(request, object_id, form_url, extra_context)
           ^^^^^^^^^^^^^^^^^^^^^^^^^^^^^^^^^^^^^^^^^^^^^^^^^^^^^^^^^^^^^^^^^^
  File "C:\Users\kevin\AppData\Roaming\Python\Python312\site-packages\django\contrib\admin\options.py", line 1839, in _changeform_view
    ModelForm = self.get_form(
                ^^^^^^^^^^^^^^
  File "C:\Users\kevin\AppData\Roaming\Python\Python312\site-packages\django\contrib\admin\options.py", line 839, in get_form
    raise FieldError(
django.core.exceptions.FieldError: Unknown field(s) (background_color) specified for Landing. Check fields/fieldsets/exclude attributes of class LandingAdmin.
ERROR 2024-10-31 23:24:36,867 basehttp "GET /app/front/landing/1/change/ HTTP/1.1" 500 183451
