ERROR 2024-10-29 15:11:14,326 log Internal Server Error: /front/home/
Traceback (most recent call last):
  File "C:\Users\kevin\AppData\Roaming\Python\Python312\site-packages\django\core\handlers\exception.py", line 55, in inner
    response = get_response(request)
               ^^^^^^^^^^^^^^^^^^^^^
  File "C:\Users\kevin\AppData\Roaming\Python\Python312\site-packages\django\core\handlers\base.py", line 197, in _get_response
    response = wrapped_callback(request, *callback_args, **callback_kwargs)
               ^^^^^^^^^^^^^^^^^^^^^^^^^^^^^^^^^^^^^^^^^^^^^^^^^^^^^^^^^^^^
  File "C:\Users\kevin\Desktop\pantutienda-adp\front\views.py", line 132, in home
    return render(request, '404.html')  # Si no hay un objeto landing, renderiza una página de error o similar.
           ^^^^^^^^^^^^^^^^^^^^^^^^^^^
  File "C:\Users\kevin\AppData\Roaming\Python\Python312\site-packages\django\shortcuts.py", line 25, in render
    content = loader.render_to_string(template_name, context, request, using=using)
              ^^^^^^^^^^^^^^^^^^^^^^^^^^^^^^^^^^^^^^^^^^^^^^^^^^^^^^^^^^^^^^^^^^^^^
  File "C:\Users\kevin\AppData\Roaming\Python\Python312\site-packages\django\template\loader.py", line 61, in render_to_string
    template = get_template(template_name, using=using)
               ^^^^^^^^^^^^^^^^^^^^^^^^^^^^^^^^^^^^^^^^
  File "C:\Users\kevin\AppData\Roaming\Python\Python312\site-packages\django\template\loader.py", line 19, in get_template
    raise TemplateDoesNotExist(template_name, chain=chain)
django.template.exceptions.TemplateDoesNotExist: 404.html
ERROR 2024-10-29 15:11:14,330 basehttp "GET /front/home/ HTTP/1.1" 500 93898
ERROR 2024-10-29 15:11:14,437 log Internal Server Error: /front/home/
Traceback (most recent call last):
  File "C:\Users\kevin\AppData\Roaming\Python\Python312\site-packages\django\core\handlers\exception.py", line 55, in inner
    response = get_response(request)
               ^^^^^^^^^^^^^^^^^^^^^
  File "C:\Users\kevin\AppData\Roaming\Python\Python312\site-packages\django\core\handlers\base.py", line 197, in _get_response
    response = wrapped_callback(request, *callback_args, **callback_kwargs)
               ^^^^^^^^^^^^^^^^^^^^^^^^^^^^^^^^^^^^^^^^^^^^^^^^^^^^^^^^^^^^
  File "C:\Users\kevin\Desktop\pantutienda-adp\front\views.py", line 132, in home
    return render(request, '404.html')  # Si no hay un objeto landing, renderiza una página de error o similar.
           ^^^^^^^^^^^^^^^^^^^^^^^^^^^
  File "C:\Users\kevin\AppData\Roaming\Python\Python312\site-packages\django\shortcuts.py", line 25, in render
    content = loader.render_to_string(template_name, context, request, using=using)
              ^^^^^^^^^^^^^^^^^^^^^^^^^^^^^^^^^^^^^^^^^^^^^^^^^^^^^^^^^^^^^^^^^^^^^
  File "C:\Users\kevin\AppData\Roaming\Python\Python312\site-packages\django\template\loader.py", line 61, in render_to_string
    template = get_template(template_name, using=using)
               ^^^^^^^^^^^^^^^^^^^^^^^^^^^^^^^^^^^^^^^^
  File "C:\Users\kevin\AppData\Roaming\Python\Python312\site-packages\django\template\loader.py", line 19, in get_template
    raise TemplateDoesNotExist(template_name, chain=chain)
django.template.exceptions.TemplateDoesNotExist: 404.html
ERROR 2024-10-29 15:11:14,438 basehttp "GET /front/home/ HTTP/1.1" 500 93624
ERROR 2024-10-29 15:11:45,034 log Internal Server Error: /front/home/
Traceback (most recent call last):
  File "C:\Users\kevin\AppData\Roaming\Python\Python312\site-packages\django\core\handlers\exception.py", line 55, in inner
    response = get_response(request)
               ^^^^^^^^^^^^^^^^^^^^^
  File "C:\Users\kevin\AppData\Roaming\Python\Python312\site-packages\django\core\handlers\base.py", line 197, in _get_response
    response = wrapped_callback(request, *callback_args, **callback_kwargs)
               ^^^^^^^^^^^^^^^^^^^^^^^^^^^^^^^^^^^^^^^^^^^^^^^^^^^^^^^^^^^^
  File "C:\Users\kevin\Desktop\pantutienda-adp\front\views.py", line 132, in home
    return render(request, '404.html')  # Si no hay un objeto landing, renderiza una página de error o similar.
           ^^^^^^^^^^^^^^^^^^^^^^^^^^^
  File "C:\Users\kevin\AppData\Roaming\Python\Python312\site-packages\django\shortcuts.py", line 25, in render
    content = loader.render_to_string(template_name, context, request, using=using)
              ^^^^^^^^^^^^^^^^^^^^^^^^^^^^^^^^^^^^^^^^^^^^^^^^^^^^^^^^^^^^^^^^^^^^^
  File "C:\Users\kevin\AppData\Roaming\Python\Python312\site-packages\django\template\loader.py", line 61, in render_to_string
    template = get_template(template_name, using=using)
               ^^^^^^^^^^^^^^^^^^^^^^^^^^^^^^^^^^^^^^^^
  File "C:\Users\kevin\AppData\Roaming\Python\Python312\site-packages\django\template\loader.py", line 19, in get_template
    raise TemplateDoesNotExist(template_name, chain=chain)
django.template.exceptions.TemplateDoesNotExist: 404.html
ERROR 2024-10-29 15:11:45,034 basehttp "GET /front/home/ HTTP/1.1" 500 93898
ERROR 2024-10-29 15:11:55,083 log Internal Server Error: /front/home/
Traceback (most recent call last):
  File "C:\Users\kevin\AppData\Roaming\Python\Python312\site-packages\django\core\handlers\exception.py", line 55, in inner
    response = get_response(request)
               ^^^^^^^^^^^^^^^^^^^^^
  File "C:\Users\kevin\AppData\Roaming\Python\Python312\site-packages\django\core\handlers\base.py", line 197, in _get_response
    response = wrapped_callback(request, *callback_args, **callback_kwargs)
               ^^^^^^^^^^^^^^^^^^^^^^^^^^^^^^^^^^^^^^^^^^^^^^^^^^^^^^^^^^^^
  File "C:\Users\kevin\Desktop\pantutienda-adp\front\views.py", line 132, in home
    return render(request, '404.html')  # Si no hay un objeto landing, renderiza una página de error o similar.
           ^^^^^^^^^^^^^^^^^^^^^^^^^^^
  File "C:\Users\kevin\AppData\Roaming\Python\Python312\site-packages\django\shortcuts.py", line 25, in render
    content = loader.render_to_string(template_name, context, request, using=using)
              ^^^^^^^^^^^^^^^^^^^^^^^^^^^^^^^^^^^^^^^^^^^^^^^^^^^^^^^^^^^^^^^^^^^^^
  File "C:\Users\kevin\AppData\Roaming\Python\Python312\site-packages\django\template\loader.py", line 61, in render_to_string
    template = get_template(template_name, using=using)
               ^^^^^^^^^^^^^^^^^^^^^^^^^^^^^^^^^^^^^^^^
  File "C:\Users\kevin\AppData\Roaming\Python\Python312\site-packages\django\template\loader.py", line 19, in get_template
    raise TemplateDoesNotExist(template_name, chain=chain)
django.template.exceptions.TemplateDoesNotExist: 404.html
ERROR 2024-10-29 15:11:55,086 basehttp "GET /front/home/ HTTP/1.1" 500 93761
ERROR 2024-10-29 18:55:52,168 log Internal Server Error: /front/home/
Traceback (most recent call last):
  File "C:\Users\kevin\AppData\Roaming\Python\Python312\site-packages\django\core\handlers\exception.py", line 55, in inner
    response = get_response(request)
               ^^^^^^^^^^^^^^^^^^^^^
  File "C:\Users\kevin\AppData\Roaming\Python\Python312\site-packages\django\core\handlers\base.py", line 197, in _get_response
    response = wrapped_callback(request, *callback_args, **callback_kwargs)
               ^^^^^^^^^^^^^^^^^^^^^^^^^^^^^^^^^^^^^^^^^^^^^^^^^^^^^^^^^^^^
  File "C:\Users\kevin\Desktop\pantutienda-adp\front\views.py", line 145, in home
    return render(request, 'onboarding_2.html',context)  # Si no hay un objeto landing, renderiza una página de error o similar.
           ^^^^^^^^^^^^^^^^^^^^^^^^^^^^^^^^^^^^^^^^^^^^
  File "C:\Users\kevin\AppData\Roaming\Python\Python312\site-packages\django\shortcuts.py", line 25, in render
    content = loader.render_to_string(template_name, context, request, using=using)
              ^^^^^^^^^^^^^^^^^^^^^^^^^^^^^^^^^^^^^^^^^^^^^^^^^^^^^^^^^^^^^^^^^^^^^
  File "C:\Users\kevin\AppData\Roaming\Python\Python312\site-packages\django\template\loader.py", line 62, in render_to_string
    return template.render(context, request)
           ^^^^^^^^^^^^^^^^^^^^^^^^^^^^^^^^^
  File "C:\Users\kevin\AppData\Roaming\Python\Python312\site-packages\django\template\backends\django.py", line 61, in render
    return self.template.render(context)
           ^^^^^^^^^^^^^^^^^^^^^^^^^^^^^
  File "C:\Users\kevin\AppData\Roaming\Python\Python312\site-packages\django\template\base.py", line 171, in render
    return self._render(context)
           ^^^^^^^^^^^^^^^^^^^^^
  File "C:\Users\kevin\AppData\Roaming\Python\Python312\site-packages\django\template\base.py", line 163, in _render
    return self.nodelist.render(context)
           ^^^^^^^^^^^^^^^^^^^^^^^^^^^^^
  File "C:\Users\kevin\AppData\Roaming\Python\Python312\site-packages\django\template\base.py", line 1000, in render
    return SafeString("".join([node.render_annotated(context) for node in self]))
                               ^^^^^^^^^^^^^^^^^^^^^^^^^^^^^^
  File "C:\Users\kevin\AppData\Roaming\Python\Python312\site-packages\django\template\base.py", line 961, in render_annotated
    return self.render(context)
           ^^^^^^^^^^^^^^^^^^^^
  File "C:\Users\kevin\AppData\Roaming\Python\Python312\site-packages\django\template\defaulttags.py", line 479, in render
    url = reverse(view_name, args=args, kwargs=kwargs, current_app=current_app)
          ^^^^^^^^^^^^^^^^^^^^^^^^^^^^^^^^^^^^^^^^^^^^^^^^^^^^^^^^^^^^^^^^^^^^^
  File "C:\Users\kevin\AppData\Roaming\Python\Python312\site-packages\django\urls\base.py", line 88, in reverse
    return resolver._reverse_with_prefix(view, prefix, *args, **kwargs)
           ^^^^^^^^^^^^^^^^^^^^^^^^^^^^^^^^^^^^^^^^^^^^^^^^^^^^^^^^^^^^
  File "C:\Users\kevin\AppData\Roaming\Python\Python312\site-packages\django\urls\resolvers.py", line 851, in _reverse_with_prefix
    raise NoReverseMatch(msg)
django.urls.exceptions.NoReverseMatch: Reverse for 'onboarding' not found. 'onboarding' is not a valid view function or pattern name.
ERROR 2024-10-29 18:55:52,173 basehttp "GET /front/home/ HTTP/1.1" 500 133483
ERROR 2024-10-29 19:24:07,457 log Internal Server Error: /front/onboarding/
Traceback (most recent call last):
  File "C:\Users\kevin\AppData\Roaming\Python\Python312\site-packages\django\core\handlers\exception.py", line 55, in inner
    response = get_response(request)
               ^^^^^^^^^^^^^^^^^^^^^
  File "C:\Users\kevin\AppData\Roaming\Python\Python312\site-packages\django\core\handlers\base.py", line 197, in _get_response
    response = wrapped_callback(request, *callback_args, **callback_kwargs)
               ^^^^^^^^^^^^^^^^^^^^^^^^^^^^^^^^^^^^^^^^^^^^^^^^^^^^^^^^^^^^
  File "C:\Users\kevin\Desktop\pantutienda-adp\configuracion\views.py", line 31, in onboarding
    return render(request, 'onboarding_1.html', context)
           ^^^^^^^^^^^^^^^^^^^^^^^^^^^^^^^^^^^^^^^^^^^^^
  File "C:\Users\kevin\AppData\Roaming\Python\Python312\site-packages\django\shortcuts.py", line 25, in render
    content = loader.render_to_string(template_name, context, request, using=using)
              ^^^^^^^^^^^^^^^^^^^^^^^^^^^^^^^^^^^^^^^^^^^^^^^^^^^^^^^^^^^^^^^^^^^^^
  File "C:\Users\kevin\AppData\Roaming\Python\Python312\site-packages\django\template\loader.py", line 61, in render_to_string
    template = get_template(template_name, using=using)
               ^^^^^^^^^^^^^^^^^^^^^^^^^^^^^^^^^^^^^^^^
  File "C:\Users\kevin\AppData\Roaming\Python\Python312\site-packages\django\template\loader.py", line 19, in get_template
    raise TemplateDoesNotExist(template_name, chain=chain)
django.template.exceptions.TemplateDoesNotExist: onboarding_1.html
ERROR 2024-10-29 19:24:07,460 basehttp "POST /front/onboarding/ HTTP/1.1" 500 96528
ERROR 2024-10-29 19:43:00,882 log Internal Server Error: /front/home/
Traceback (most recent call last):
  File "C:\Users\kevin\AppData\Roaming\Python\Python312\site-packages\django\core\handlers\exception.py", line 55, in inner
    response = get_response(request)
               ^^^^^^^^^^^^^^^^^^^^^
  File "C:\Users\kevin\AppData\Roaming\Python\Python312\site-packages\django\core\handlers\base.py", line 197, in _get_response
    response = wrapped_callback(request, *callback_args, **callback_kwargs)
               ^^^^^^^^^^^^^^^^^^^^^^^^^^^^^^^^^^^^^^^^^^^^^^^^^^^^^^^^^^^^
  File "C:\Users\kevin\Desktop\pantutienda-adp\front\views.py", line 132, in home
    configuracion = configuracion.objects.first()  # Asegúrate de que haya una landing en la base de datos
                    ^^^^^^^^^^^^^
UnboundLocalError: cannot access local variable 'configuracion' where it is not associated with a value
ERROR 2024-10-29 19:43:00,882 basehttp "GET /front/home/ HTTP/1.1" 500 77242
ERROR 2024-10-29 19:43:50,362 log Internal Server Error: /front/home/
Traceback (most recent call last):
  File "C:\Users\kevin\AppData\Roaming\Python\Python312\site-packages\django\core\handlers\exception.py", line 55, in inner
    response = get_response(request)
               ^^^^^^^^^^^^^^^^^^^^^
  File "C:\Users\kevin\AppData\Roaming\Python\Python312\site-packages\django\core\handlers\base.py", line 197, in _get_response
    response = wrapped_callback(request, *callback_args, **callback_kwargs)
               ^^^^^^^^^^^^^^^^^^^^^^^^^^^^^^^^^^^^^^^^^^^^^^^^^^^^^^^^^^^^
  File "C:\Users\kevin\Desktop\pantutienda-adp\front\views.py", line 132, in home
    configuracion = configuracion.objects.first()  # Asegúrate de que haya una landing en la base de datos
                    ^^^^^^^^^^^^^
UnboundLocalError: cannot access local variable 'configuracion' where it is not associated with a value
ERROR 2024-10-29 19:43:50,363 basehttp "GET /front/home/ HTTP/1.1" 500 77242
ERROR 2024-10-29 19:43:50,896 log Internal Server Error: /front/home/
Traceback (most recent call last):
  File "C:\Users\kevin\AppData\Roaming\Python\Python312\site-packages\django\core\handlers\exception.py", line 55, in inner
    response = get_response(request)
               ^^^^^^^^^^^^^^^^^^^^^
  File "C:\Users\kevin\AppData\Roaming\Python\Python312\site-packages\django\core\handlers\base.py", line 197, in _get_response
    response = wrapped_callback(request, *callback_args, **callback_kwargs)
               ^^^^^^^^^^^^^^^^^^^^^^^^^^^^^^^^^^^^^^^^^^^^^^^^^^^^^^^^^^^^
  File "C:\Users\kevin\Desktop\pantutienda-adp\front\views.py", line 132, in home
    configuracion = configuracion.objects.first()  # Asegúrate de que haya una landing en la base de datos
                    ^^^^^^^^^^^^^
UnboundLocalError: cannot access local variable 'configuracion' where it is not associated with a value
ERROR 2024-10-29 19:43:50,897 basehttp "GET /front/home/ HTTP/1.1" 500 76968
ERROR 2024-10-29 20:49:47,221 log Internal Server Error: /app/inventario/producto/
Traceback (most recent call last):
  File "C:\Users\kevin\AppData\Roaming\Python\Python312\site-packages\django\core\handlers\exception.py", line 55, in inner
    response = get_response(request)
               ^^^^^^^^^^^^^^^^^^^^^
  File "C:\Users\kevin\AppData\Roaming\Python\Python312\site-packages\django\core\handlers\base.py", line 197, in _get_response
    response = wrapped_callback(request, *callback_args, **callback_kwargs)
               ^^^^^^^^^^^^^^^^^^^^^^^^^^^^^^^^^^^^^^^^^^^^^^^^^^^^^^^^^^^^
  File "C:\Users\kevin\AppData\Roaming\Python\Python312\site-packages\django\contrib\admin\options.py", line 716, in wrapper
    return self.admin_site.admin_view(view)(*args, **kwargs)
           ^^^^^^^^^^^^^^^^^^^^^^^^^^^^^^^^^^^^^^^^^^^^^^^^^
  File "C:\Users\kevin\AppData\Roaming\Python\Python312\site-packages\django\utils\decorators.py", line 188, in _view_wrapper
    result = _process_exception(request, e)
             ^^^^^^^^^^^^^^^^^^^^^^^^^^^^^^
  File "C:\Users\kevin\AppData\Roaming\Python\Python312\site-packages\django\utils\decorators.py", line 186, in _view_wrapper
    response = view_func(request, *args, **kwargs)
               ^^^^^^^^^^^^^^^^^^^^^^^^^^^^^^^^^^^
  File "C:\Users\kevin\AppData\Roaming\Python\Python312\site-packages\django\views\decorators\cache.py", line 80, in _view_wrapper
    response = view_func(request, *args, **kwargs)
               ^^^^^^^^^^^^^^^^^^^^^^^^^^^^^^^^^^^
  File "C:\Users\kevin\AppData\Roaming\Python\Python312\site-packages\django\contrib\admin\sites.py", line 240, in inner
    return view(request, *args, **kwargs)
           ^^^^^^^^^^^^^^^^^^^^^^^^^^^^^^
  File "C:\Users\kevin\Desktop\pantutienda-adp\inventario\admin.py", line 333, in changelist_view
    moneda=configuracion.objects.first().Moneda.signo
           ^^^^^^^^^^^^^^^^^^^^^^^^^^^^^^^^^^^^
AttributeError: 'NoneType' object has no attribute 'Moneda'
ERROR 2024-10-29 20:49:47,252 basehttp "GET /app/inventario/producto/ HTTP/1.1" 500 101783
ERROR 2024-10-29 21:55:18,426 log Internal Server Error: /app/auth/user/add/
Traceback (most recent call last):
  File "C:\Users\kevin\AppData\Roaming\Python\Python312\site-packages\django\db\backends\base\base.py", line 299, in _commit
    return self.connection.commit()
           ^^^^^^^^^^^^^^^^^^^^^^^^
sqlite3.IntegrityError: FOREIGN KEY constraint failed

The above exception was the direct cause of the following exception:

Traceback (most recent call last):
  File "C:\Users\kevin\AppData\Roaming\Python\Python312\site-packages\django\core\handlers\exception.py", line 55, in inner
    response = get_response(request)
               ^^^^^^^^^^^^^^^^^^^^^
  File "C:\Users\kevin\AppData\Roaming\Python\Python312\site-packages\django\core\handlers\base.py", line 197, in _get_response
    response = wrapped_callback(request, *callback_args, **callback_kwargs)
               ^^^^^^^^^^^^^^^^^^^^^^^^^^^^^^^^^^^^^^^^^^^^^^^^^^^^^^^^^^^^
  File "C:\Users\kevin\AppData\Roaming\Python\Python312\site-packages\django\contrib\admin\options.py", line 716, in wrapper
    return self.admin_site.admin_view(view)(*args, **kwargs)
           ^^^^^^^^^^^^^^^^^^^^^^^^^^^^^^^^^^^^^^^^^^^^^^^^^
  File "C:\Users\kevin\AppData\Roaming\Python\Python312\site-packages\django\utils\decorators.py", line 188, in _view_wrapper
    result = _process_exception(request, e)
             ^^^^^^^^^^^^^^^^^^^^^^^^^^^^^^
  File "C:\Users\kevin\AppData\Roaming\Python\Python312\site-packages\django\utils\decorators.py", line 186, in _view_wrapper
    response = view_func(request, *args, **kwargs)
               ^^^^^^^^^^^^^^^^^^^^^^^^^^^^^^^^^^^
  File "C:\Users\kevin\AppData\Roaming\Python\Python312\site-packages\django\views\decorators\cache.py", line 80, in _view_wrapper
    response = view_func(request, *args, **kwargs)
               ^^^^^^^^^^^^^^^^^^^^^^^^^^^^^^^^^^^
  File "C:\Users\kevin\AppData\Roaming\Python\Python312\site-packages\django\contrib\admin\sites.py", line 240, in inner
    return view(request, *args, **kwargs)
           ^^^^^^^^^^^^^^^^^^^^^^^^^^^^^^
  File "C:\Users\kevin\AppData\Roaming\Python\Python312\site-packages\django\utils\decorators.py", line 48, in _wrapper
    return bound_method(*args, **kwargs)
           ^^^^^^^^^^^^^^^^^^^^^^^^^^^^^
  File "C:\Users\kevin\AppData\Roaming\Python\Python312\site-packages\django\views\decorators\debug.py", line 143, in sensitive_post_parameters_wrapper
    return view(request, *args, **kwargs)
           ^^^^^^^^^^^^^^^^^^^^^^^^^^^^^^
  File "C:\Users\kevin\AppData\Roaming\Python\Python312\site-packages\django\utils\decorators.py", line 48, in _wrapper
    return bound_method(*args, **kwargs)
           ^^^^^^^^^^^^^^^^^^^^^^^^^^^^^
  File "C:\Users\kevin\AppData\Roaming\Python\Python312\site-packages\django\utils\decorators.py", line 188, in _view_wrapper
    result = _process_exception(request, e)
             ^^^^^^^^^^^^^^^^^^^^^^^^^^^^^^
  File "C:\Users\kevin\AppData\Roaming\Python\Python312\site-packages\django\utils\decorators.py", line 186, in _view_wrapper
    response = view_func(request, *args, **kwargs)
               ^^^^^^^^^^^^^^^^^^^^^^^^^^^^^^^^^^^
  File "C:\Users\kevin\AppData\Roaming\Python\Python312\site-packages\django\contrib\auth\admin.py", line 120, in add_view
    with transaction.atomic(using=router.db_for_write(self.model)):
  File "C:\Users\kevin\AppData\Roaming\Python\Python312\site-packages\django\db\transaction.py", line 263, in __exit__
    connection.commit()
  File "C:\Users\kevin\AppData\Roaming\Python\Python312\site-packages\django\utils\asyncio.py", line 26, in inner
    return func(*args, **kwargs)
           ^^^^^^^^^^^^^^^^^^^^^
  File "C:\Users\kevin\AppData\Roaming\Python\Python312\site-packages\django\db\backends\base\base.py", line 323, in commit
    self._commit()
  File "C:\Users\kevin\AppData\Roaming\Python\Python312\site-packages\django\db\backends\base\base.py", line 298, in _commit
    with debug_transaction(self, "COMMIT"), self.wrap_database_errors:
  File "C:\Users\kevin\AppData\Roaming\Python\Python312\site-packages\django\db\utils.py", line 91, in __exit__
    raise dj_exc_value.with_traceback(traceback) from exc_value
  File "C:\Users\kevin\AppData\Roaming\Python\Python312\site-packages\django\db\backends\base\base.py", line 299, in _commit
    return self.connection.commit()
           ^^^^^^^^^^^^^^^^^^^^^^^^
django.db.utils.IntegrityError: FOREIGN KEY constraint failed
ERROR 2024-10-29 21:55:18,431 basehttp "POST /app/auth/user/add/?_to_field=id&_popup=1 HTTP/1.1" 500 159622
ERROR 2024-10-29 21:55:42,024 log Internal Server Error: /app/auth/user/add/
Traceback (most recent call last):
  File "C:\Users\kevin\AppData\Roaming\Python\Python312\site-packages\django\db\backends\base\base.py", line 299, in _commit
    return self.connection.commit()
           ^^^^^^^^^^^^^^^^^^^^^^^^
sqlite3.IntegrityError: FOREIGN KEY constraint failed

The above exception was the direct cause of the following exception:

Traceback (most recent call last):
  File "C:\Users\kevin\AppData\Roaming\Python\Python312\site-packages\django\core\handlers\exception.py", line 55, in inner
    response = get_response(request)
               ^^^^^^^^^^^^^^^^^^^^^
  File "C:\Users\kevin\AppData\Roaming\Python\Python312\site-packages\django\core\handlers\base.py", line 197, in _get_response
    response = wrapped_callback(request, *callback_args, **callback_kwargs)
               ^^^^^^^^^^^^^^^^^^^^^^^^^^^^^^^^^^^^^^^^^^^^^^^^^^^^^^^^^^^^
  File "C:\Users\kevin\AppData\Roaming\Python\Python312\site-packages\django\contrib\admin\options.py", line 716, in wrapper
    return self.admin_site.admin_view(view)(*args, **kwargs)
           ^^^^^^^^^^^^^^^^^^^^^^^^^^^^^^^^^^^^^^^^^^^^^^^^^
  File "C:\Users\kevin\AppData\Roaming\Python\Python312\site-packages\django\utils\decorators.py", line 188, in _view_wrapper
    result = _process_exception(request, e)
             ^^^^^^^^^^^^^^^^^^^^^^^^^^^^^^
  File "C:\Users\kevin\AppData\Roaming\Python\Python312\site-packages\django\utils\decorators.py", line 186, in _view_wrapper
    response = view_func(request, *args, **kwargs)
               ^^^^^^^^^^^^^^^^^^^^^^^^^^^^^^^^^^^
  File "C:\Users\kevin\AppData\Roaming\Python\Python312\site-packages\django\views\decorators\cache.py", line 80, in _view_wrapper
    response = view_func(request, *args, **kwargs)
               ^^^^^^^^^^^^^^^^^^^^^^^^^^^^^^^^^^^
  File "C:\Users\kevin\AppData\Roaming\Python\Python312\site-packages\django\contrib\admin\sites.py", line 240, in inner
    return view(request, *args, **kwargs)
           ^^^^^^^^^^^^^^^^^^^^^^^^^^^^^^
  File "C:\Users\kevin\AppData\Roaming\Python\Python312\site-packages\django\utils\decorators.py", line 48, in _wrapper
    return bound_method(*args, **kwargs)
           ^^^^^^^^^^^^^^^^^^^^^^^^^^^^^
  File "C:\Users\kevin\AppData\Roaming\Python\Python312\site-packages\django\views\decorators\debug.py", line 143, in sensitive_post_parameters_wrapper
    return view(request, *args, **kwargs)
           ^^^^^^^^^^^^^^^^^^^^^^^^^^^^^^
  File "C:\Users\kevin\AppData\Roaming\Python\Python312\site-packages\django\utils\decorators.py", line 48, in _wrapper
    return bound_method(*args, **kwargs)
           ^^^^^^^^^^^^^^^^^^^^^^^^^^^^^
  File "C:\Users\kevin\AppData\Roaming\Python\Python312\site-packages\django\utils\decorators.py", line 188, in _view_wrapper
    result = _process_exception(request, e)
             ^^^^^^^^^^^^^^^^^^^^^^^^^^^^^^
  File "C:\Users\kevin\AppData\Roaming\Python\Python312\site-packages\django\utils\decorators.py", line 186, in _view_wrapper
    response = view_func(request, *args, **kwargs)
               ^^^^^^^^^^^^^^^^^^^^^^^^^^^^^^^^^^^
  File "C:\Users\kevin\AppData\Roaming\Python\Python312\site-packages\django\contrib\auth\admin.py", line 120, in add_view
    with transaction.atomic(using=router.db_for_write(self.model)):
  File "C:\Users\kevin\AppData\Roaming\Python\Python312\site-packages\django\db\transaction.py", line 263, in __exit__
    connection.commit()
  File "C:\Users\kevin\AppData\Roaming\Python\Python312\site-packages\django\utils\asyncio.py", line 26, in inner
    return func(*args, **kwargs)
           ^^^^^^^^^^^^^^^^^^^^^
  File "C:\Users\kevin\AppData\Roaming\Python\Python312\site-packages\django\db\backends\base\base.py", line 323, in commit
    self._commit()
  File "C:\Users\kevin\AppData\Roaming\Python\Python312\site-packages\django\db\backends\base\base.py", line 298, in _commit
    with debug_transaction(self, "COMMIT"), self.wrap_database_errors:
  File "C:\Users\kevin\AppData\Roaming\Python\Python312\site-packages\django\db\utils.py", line 91, in __exit__
    raise dj_exc_value.with_traceback(traceback) from exc_value
  File "C:\Users\kevin\AppData\Roaming\Python\Python312\site-packages\django\db\backends\base\base.py", line 299, in _commit
    return self.connection.commit()
           ^^^^^^^^^^^^^^^^^^^^^^^^
django.db.utils.IntegrityError: FOREIGN KEY constraint failed
ERROR 2024-10-29 21:55:42,026 basehttp "POST /app/auth/user/add/?_to_field=id&_popup=1 HTTP/1.1" 500 159615
ERROR 2024-10-29 21:55:59,027 log Internal Server Error: /app/auth/user/add/
Traceback (most recent call last):
  File "C:\Users\kevin\AppData\Roaming\Python\Python312\site-packages\django\db\backends\base\base.py", line 299, in _commit
    return self.connection.commit()
           ^^^^^^^^^^^^^^^^^^^^^^^^
sqlite3.IntegrityError: FOREIGN KEY constraint failed

The above exception was the direct cause of the following exception:

Traceback (most recent call last):
  File "C:\Users\kevin\AppData\Roaming\Python\Python312\site-packages\django\core\handlers\exception.py", line 55, in inner
    response = get_response(request)
               ^^^^^^^^^^^^^^^^^^^^^
  File "C:\Users\kevin\AppData\Roaming\Python\Python312\site-packages\django\core\handlers\base.py", line 197, in _get_response
    response = wrapped_callback(request, *callback_args, **callback_kwargs)
               ^^^^^^^^^^^^^^^^^^^^^^^^^^^^^^^^^^^^^^^^^^^^^^^^^^^^^^^^^^^^
  File "C:\Users\kevin\AppData\Roaming\Python\Python312\site-packages\django\contrib\admin\options.py", line 716, in wrapper
    return self.admin_site.admin_view(view)(*args, **kwargs)
           ^^^^^^^^^^^^^^^^^^^^^^^^^^^^^^^^^^^^^^^^^^^^^^^^^
  File "C:\Users\kevin\AppData\Roaming\Python\Python312\site-packages\django\utils\decorators.py", line 188, in _view_wrapper
    result = _process_exception(request, e)
             ^^^^^^^^^^^^^^^^^^^^^^^^^^^^^^
  File "C:\Users\kevin\AppData\Roaming\Python\Python312\site-packages\django\utils\decorators.py", line 186, in _view_wrapper
    response = view_func(request, *args, **kwargs)
               ^^^^^^^^^^^^^^^^^^^^^^^^^^^^^^^^^^^
  File "C:\Users\kevin\AppData\Roaming\Python\Python312\site-packages\django\views\decorators\cache.py", line 80, in _view_wrapper
    response = view_func(request, *args, **kwargs)
               ^^^^^^^^^^^^^^^^^^^^^^^^^^^^^^^^^^^
  File "C:\Users\kevin\AppData\Roaming\Python\Python312\site-packages\django\contrib\admin\sites.py", line 240, in inner
    return view(request, *args, **kwargs)
           ^^^^^^^^^^^^^^^^^^^^^^^^^^^^^^
  File "C:\Users\kevin\AppData\Roaming\Python\Python312\site-packages\django\utils\decorators.py", line 48, in _wrapper
    return bound_method(*args, **kwargs)
           ^^^^^^^^^^^^^^^^^^^^^^^^^^^^^
  File "C:\Users\kevin\AppData\Roaming\Python\Python312\site-packages\django\views\decorators\debug.py", line 143, in sensitive_post_parameters_wrapper
    return view(request, *args, **kwargs)
           ^^^^^^^^^^^^^^^^^^^^^^^^^^^^^^
  File "C:\Users\kevin\AppData\Roaming\Python\Python312\site-packages\django\utils\decorators.py", line 48, in _wrapper
    return bound_method(*args, **kwargs)
           ^^^^^^^^^^^^^^^^^^^^^^^^^^^^^
  File "C:\Users\kevin\AppData\Roaming\Python\Python312\site-packages\django\utils\decorators.py", line 188, in _view_wrapper
    result = _process_exception(request, e)
             ^^^^^^^^^^^^^^^^^^^^^^^^^^^^^^
  File "C:\Users\kevin\AppData\Roaming\Python\Python312\site-packages\django\utils\decorators.py", line 186, in _view_wrapper
    response = view_func(request, *args, **kwargs)
               ^^^^^^^^^^^^^^^^^^^^^^^^^^^^^^^^^^^
  File "C:\Users\kevin\AppData\Roaming\Python\Python312\site-packages\django\contrib\auth\admin.py", line 120, in add_view
    with transaction.atomic(using=router.db_for_write(self.model)):
  File "C:\Users\kevin\AppData\Roaming\Python\Python312\site-packages\django\db\transaction.py", line 263, in __exit__
    connection.commit()
  File "C:\Users\kevin\AppData\Roaming\Python\Python312\site-packages\django\utils\asyncio.py", line 26, in inner
    return func(*args, **kwargs)
           ^^^^^^^^^^^^^^^^^^^^^
  File "C:\Users\kevin\AppData\Roaming\Python\Python312\site-packages\django\db\backends\base\base.py", line 323, in commit
    self._commit()
  File "C:\Users\kevin\AppData\Roaming\Python\Python312\site-packages\django\db\backends\base\base.py", line 298, in _commit
    with debug_transaction(self, "COMMIT"), self.wrap_database_errors:
  File "C:\Users\kevin\AppData\Roaming\Python\Python312\site-packages\django\db\utils.py", line 91, in __exit__
    raise dj_exc_value.with_traceback(traceback) from exc_value
  File "C:\Users\kevin\AppData\Roaming\Python\Python312\site-packages\django\db\backends\base\base.py", line 299, in _commit
    return self.connection.commit()
           ^^^^^^^^^^^^^^^^^^^^^^^^
django.db.utils.IntegrityError: FOREIGN KEY constraint failed
ERROR 2024-10-29 21:55:59,030 basehttp "POST /app/auth/user/add/ HTTP/1.1" 500 158615
ERROR 2024-10-29 21:56:59,885 log Internal Server Error: /app/auth/user/add/
Traceback (most recent call last):
  File "C:\Users\kevin\AppData\Roaming\Python\Python312\site-packages\django\db\backends\base\base.py", line 299, in _commit
    return self.connection.commit()
           ^^^^^^^^^^^^^^^^^^^^^^^^
sqlite3.IntegrityError: FOREIGN KEY constraint failed

The above exception was the direct cause of the following exception:

Traceback (most recent call last):
  File "C:\Users\kevin\AppData\Roaming\Python\Python312\site-packages\django\core\handlers\exception.py", line 55, in inner
    response = get_response(request)
               ^^^^^^^^^^^^^^^^^^^^^
  File "C:\Users\kevin\AppData\Roaming\Python\Python312\site-packages\django\core\handlers\base.py", line 197, in _get_response
    response = wrapped_callback(request, *callback_args, **callback_kwargs)
               ^^^^^^^^^^^^^^^^^^^^^^^^^^^^^^^^^^^^^^^^^^^^^^^^^^^^^^^^^^^^
  File "C:\Users\kevin\AppData\Roaming\Python\Python312\site-packages\django\contrib\admin\options.py", line 716, in wrapper
    return self.admin_site.admin_view(view)(*args, **kwargs)
           ^^^^^^^^^^^^^^^^^^^^^^^^^^^^^^^^^^^^^^^^^^^^^^^^^
  File "C:\Users\kevin\AppData\Roaming\Python\Python312\site-packages\django\utils\decorators.py", line 188, in _view_wrapper
    result = _process_exception(request, e)
             ^^^^^^^^^^^^^^^^^^^^^^^^^^^^^^
  File "C:\Users\kevin\AppData\Roaming\Python\Python312\site-packages\django\utils\decorators.py", line 186, in _view_wrapper
    response = view_func(request, *args, **kwargs)
               ^^^^^^^^^^^^^^^^^^^^^^^^^^^^^^^^^^^
  File "C:\Users\kevin\AppData\Roaming\Python\Python312\site-packages\django\views\decorators\cache.py", line 80, in _view_wrapper
    response = view_func(request, *args, **kwargs)
               ^^^^^^^^^^^^^^^^^^^^^^^^^^^^^^^^^^^
  File "C:\Users\kevin\AppData\Roaming\Python\Python312\site-packages\django\contrib\admin\sites.py", line 240, in inner
    return view(request, *args, **kwargs)
           ^^^^^^^^^^^^^^^^^^^^^^^^^^^^^^
  File "C:\Users\kevin\AppData\Roaming\Python\Python312\site-packages\django\utils\decorators.py", line 48, in _wrapper
    return bound_method(*args, **kwargs)
           ^^^^^^^^^^^^^^^^^^^^^^^^^^^^^
  File "C:\Users\kevin\AppData\Roaming\Python\Python312\site-packages\django\views\decorators\debug.py", line 143, in sensitive_post_parameters_wrapper
    return view(request, *args, **kwargs)
           ^^^^^^^^^^^^^^^^^^^^^^^^^^^^^^
  File "C:\Users\kevin\AppData\Roaming\Python\Python312\site-packages\django\utils\decorators.py", line 48, in _wrapper
    return bound_method(*args, **kwargs)
           ^^^^^^^^^^^^^^^^^^^^^^^^^^^^^
  File "C:\Users\kevin\AppData\Roaming\Python\Python312\site-packages\django\utils\decorators.py", line 188, in _view_wrapper
    result = _process_exception(request, e)
             ^^^^^^^^^^^^^^^^^^^^^^^^^^^^^^
  File "C:\Users\kevin\AppData\Roaming\Python\Python312\site-packages\django\utils\decorators.py", line 186, in _view_wrapper
    response = view_func(request, *args, **kwargs)
               ^^^^^^^^^^^^^^^^^^^^^^^^^^^^^^^^^^^
  File "C:\Users\kevin\AppData\Roaming\Python\Python312\site-packages\django\contrib\auth\admin.py", line 120, in add_view
    with transaction.atomic(using=router.db_for_write(self.model)):
  File "C:\Users\kevin\AppData\Roaming\Python\Python312\site-packages\django\db\transaction.py", line 263, in __exit__
    connection.commit()
  File "C:\Users\kevin\AppData\Roaming\Python\Python312\site-packages\django\utils\asyncio.py", line 26, in inner
    return func(*args, **kwargs)
           ^^^^^^^^^^^^^^^^^^^^^
  File "C:\Users\kevin\AppData\Roaming\Python\Python312\site-packages\django\db\backends\base\base.py", line 323, in commit
    self._commit()
  File "C:\Users\kevin\AppData\Roaming\Python\Python312\site-packages\django\db\backends\base\base.py", line 298, in _commit
    with debug_transaction(self, "COMMIT"), self.wrap_database_errors:
  File "C:\Users\kevin\AppData\Roaming\Python\Python312\site-packages\django\db\utils.py", line 91, in __exit__
    raise dj_exc_value.with_traceback(traceback) from exc_value
  File "C:\Users\kevin\AppData\Roaming\Python\Python312\site-packages\django\db\backends\base\base.py", line 299, in _commit
    return self.connection.commit()
           ^^^^^^^^^^^^^^^^^^^^^^^^
django.db.utils.IntegrityError: FOREIGN KEY constraint failed
ERROR 2024-10-29 21:56:59,890 basehttp "POST /app/auth/user/add/ HTTP/1.1" 500 158982
ERROR 2024-10-29 21:57:34,005 log Internal Server Error: /front/registro/
Traceback (most recent call last):
  File "C:\Users\kevin\AppData\Roaming\Python\Python312\site-packages\django\db\utils.py", line 98, in inner
    return func(*args, **kwargs)
           ^^^^^^^^^^^^^^^^^^^^^
sqlite3.IntegrityError: FOREIGN KEY constraint failed

The above exception was the direct cause of the following exception:

Traceback (most recent call last):
  File "C:\Users\kevin\AppData\Roaming\Python\Python312\site-packages\django\core\handlers\exception.py", line 55, in inner
    response = get_response(request)
               ^^^^^^^^^^^^^^^^^^^^^
  File "C:\Users\kevin\AppData\Roaming\Python\Python312\site-packages\django\core\handlers\base.py", line 197, in _get_response
    response = wrapped_callback(request, *callback_args, **callback_kwargs)
               ^^^^^^^^^^^^^^^^^^^^^^^^^^^^^^^^^^^^^^^^^^^^^^^^^^^^^^^^^^^^
  File "C:\Users\kevin\Desktop\pantutienda-adp\front\views.py", line 453, in registro
    user = User.objects.create_user(username=username, email=email, password=password)
           ^^^^^^^^^^^^^^^^^^^^^^^^^^^^^^^^^^^^^^^^^^^^^^^^^^^^^^^^^^^^^^^^^^^^^^^^^^^
  File "C:\Users\kevin\AppData\Roaming\Python\Python312\site-packages\django\contrib\auth\models.py", line 161, in create_user
    return self._create_user(username, email, password, **extra_fields)
           ^^^^^^^^^^^^^^^^^^^^^^^^^^^^^^^^^^^^^^^^^^^^^^^^^^^^^^^^^^^^
  File "C:\Users\kevin\AppData\Roaming\Python\Python312\site-packages\django\contrib\auth\models.py", line 155, in _create_user
    user.save(using=self._db)
  File "C:\Users\kevin\AppData\Roaming\Python\Python312\site-packages\django\contrib\auth\base_user.py", line 78, in save
    super().save(*args, **kwargs)
  File "C:\Users\kevin\AppData\Roaming\Python\Python312\site-packages\django\db\models\base.py", line 822, in save
    self.save_base(
  File "C:\Users\kevin\AppData\Roaming\Python\Python312\site-packages\django\db\models\base.py", line 924, in save_base
    post_save.send(
  File "C:\Users\kevin\AppData\Roaming\Python\Python312\site-packages\django\dispatch\dispatcher.py", line 189, in send
    response = receiver(signal=self, sender=sender, **named)
               ^^^^^^^^^^^^^^^^^^^^^^^^^^^^^^^^^^^^^^^^^^^^^
  File "C:\Users\kevin\Desktop\pantutienda-adp\agenda\signals.py", line 10, in crear_cliente
    nuevo_cliente=Cliente.objects.create(
                  ^^^^^^^^^^^^^^^^^^^^^^^
  File "C:\Users\kevin\AppData\Roaming\Python\Python312\site-packages\django\db\models\manager.py", line 87, in manager_method
    return getattr(self.get_queryset(), name)(*args, **kwargs)
           ^^^^^^^^^^^^^^^^^^^^^^^^^^^^^^^^^^^^^^^^^^^^^^^^^^^
  File "C:\Users\kevin\AppData\Roaming\Python\Python312\site-packages\django\db\models\query.py", line 679, in create
    obj.save(force_insert=True, using=self.db)
  File "C:\Users\kevin\AppData\Roaming\Python\Python312\site-packages\django\db\models\base.py", line 822, in save
    self.save_base(
  File "C:\Users\kevin\AppData\Roaming\Python\Python312\site-packages\django\db\models\base.py", line 909, in save_base
    updated = self._save_table(
              ^^^^^^^^^^^^^^^^^
  File "C:\Users\kevin\AppData\Roaming\Python\Python312\site-packages\django\db\models\base.py", line 1071, in _save_table
    results = self._do_insert(
              ^^^^^^^^^^^^^^^^
  File "C:\Users\kevin\AppData\Roaming\Python\Python312\site-packages\django\db\models\base.py", line 1112, in _do_insert
    return manager._insert(
           ^^^^^^^^^^^^^^^^
  File "C:\Users\kevin\AppData\Roaming\Python\Python312\site-packages\django\db\models\manager.py", line 87, in manager_method
    return getattr(self.get_queryset(), name)(*args, **kwargs)
           ^^^^^^^^^^^^^^^^^^^^^^^^^^^^^^^^^^^^^^^^^^^^^^^^^^^
  File "C:\Users\kevin\AppData\Roaming\Python\Python312\site-packages\django\db\models\query.py", line 1847, in _insert
    return query.get_compiler(using=using).execute_sql(returning_fields)
           ^^^^^^^^^^^^^^^^^^^^^^^^^^^^^^^^^^^^^^^^^^^^^^^^^^^^^^^^^^^^^
  File "C:\Users\kevin\AppData\Roaming\Python\Python312\site-packages\django\db\models\sql\compiler.py", line 1835, in execute_sql
    self.connection.ops.fetch_returned_insert_columns(
  File "C:\Users\kevin\AppData\Roaming\Python\Python312\site-packages\django\db\backends\base\operations.py", line 216, in fetch_returned_insert_columns
    return cursor.fetchone()
           ^^^^^^^^^^^^^^^^^
  File "C:\Users\kevin\AppData\Roaming\Python\Python312\site-packages\django\db\utils.py", line 97, in inner
    with self:
  File "C:\Users\kevin\AppData\Roaming\Python\Python312\site-packages\django\db\utils.py", line 91, in __exit__
    raise dj_exc_value.with_traceback(traceback) from exc_value
  File "C:\Users\kevin\AppData\Roaming\Python\Python312\site-packages\django\db\utils.py", line 98, in inner
    return func(*args, **kwargs)
           ^^^^^^^^^^^^^^^^^^^^^
django.db.utils.IntegrityError: FOREIGN KEY constraint failed
ERROR 2024-10-29 21:57:34,017 basehttp "POST /front/registro/ HTTP/1.1" 500 182088
ERROR 2024-10-29 22:06:30,313 log Internal Server Error: /app/auth/user/add/
Traceback (most recent call last):
  File "C:\Users\kevin\AppData\Roaming\Python\Python312\site-packages\django\db\backends\base\base.py", line 299, in _commit
    return self.connection.commit()
           ^^^^^^^^^^^^^^^^^^^^^^^^
sqlite3.IntegrityError: FOREIGN KEY constraint failed

The above exception was the direct cause of the following exception:

Traceback (most recent call last):
  File "C:\Users\kevin\AppData\Roaming\Python\Python312\site-packages\django\core\handlers\exception.py", line 55, in inner
    response = get_response(request)
               ^^^^^^^^^^^^^^^^^^^^^
  File "C:\Users\kevin\AppData\Roaming\Python\Python312\site-packages\django\core\handlers\base.py", line 197, in _get_response
    response = wrapped_callback(request, *callback_args, **callback_kwargs)
               ^^^^^^^^^^^^^^^^^^^^^^^^^^^^^^^^^^^^^^^^^^^^^^^^^^^^^^^^^^^^
  File "C:\Users\kevin\AppData\Roaming\Python\Python312\site-packages\django\contrib\admin\options.py", line 716, in wrapper
    return self.admin_site.admin_view(view)(*args, **kwargs)
           ^^^^^^^^^^^^^^^^^^^^^^^^^^^^^^^^^^^^^^^^^^^^^^^^^
  File "C:\Users\kevin\AppData\Roaming\Python\Python312\site-packages\django\utils\decorators.py", line 188, in _view_wrapper
    result = _process_exception(request, e)
             ^^^^^^^^^^^^^^^^^^^^^^^^^^^^^^
  File "C:\Users\kevin\AppData\Roaming\Python\Python312\site-packages\django\utils\decorators.py", line 186, in _view_wrapper
    response = view_func(request, *args, **kwargs)
               ^^^^^^^^^^^^^^^^^^^^^^^^^^^^^^^^^^^
  File "C:\Users\kevin\AppData\Roaming\Python\Python312\site-packages\django\views\decorators\cache.py", line 80, in _view_wrapper
    response = view_func(request, *args, **kwargs)
               ^^^^^^^^^^^^^^^^^^^^^^^^^^^^^^^^^^^
  File "C:\Users\kevin\AppData\Roaming\Python\Python312\site-packages\django\contrib\admin\sites.py", line 240, in inner
    return view(request, *args, **kwargs)
           ^^^^^^^^^^^^^^^^^^^^^^^^^^^^^^
  File "C:\Users\kevin\AppData\Roaming\Python\Python312\site-packages\django\utils\decorators.py", line 48, in _wrapper
    return bound_method(*args, **kwargs)
           ^^^^^^^^^^^^^^^^^^^^^^^^^^^^^
  File "C:\Users\kevin\AppData\Roaming\Python\Python312\site-packages\django\views\decorators\debug.py", line 143, in sensitive_post_parameters_wrapper
    return view(request, *args, **kwargs)
           ^^^^^^^^^^^^^^^^^^^^^^^^^^^^^^
  File "C:\Users\kevin\AppData\Roaming\Python\Python312\site-packages\django\utils\decorators.py", line 48, in _wrapper
    return bound_method(*args, **kwargs)
           ^^^^^^^^^^^^^^^^^^^^^^^^^^^^^
  File "C:\Users\kevin\AppData\Roaming\Python\Python312\site-packages\django\utils\decorators.py", line 188, in _view_wrapper
    result = _process_exception(request, e)
             ^^^^^^^^^^^^^^^^^^^^^^^^^^^^^^
  File "C:\Users\kevin\AppData\Roaming\Python\Python312\site-packages\django\utils\decorators.py", line 186, in _view_wrapper
    response = view_func(request, *args, **kwargs)
               ^^^^^^^^^^^^^^^^^^^^^^^^^^^^^^^^^^^
  File "C:\Users\kevin\AppData\Roaming\Python\Python312\site-packages\django\contrib\auth\admin.py", line 120, in add_view
    with transaction.atomic(using=router.db_for_write(self.model)):
  File "C:\Users\kevin\AppData\Roaming\Python\Python312\site-packages\django\db\transaction.py", line 263, in __exit__
    connection.commit()
  File "C:\Users\kevin\AppData\Roaming\Python\Python312\site-packages\django\utils\asyncio.py", line 26, in inner
    return func(*args, **kwargs)
           ^^^^^^^^^^^^^^^^^^^^^
  File "C:\Users\kevin\AppData\Roaming\Python\Python312\site-packages\django\db\backends\base\base.py", line 323, in commit
    self._commit()
  File "C:\Users\kevin\AppData\Roaming\Python\Python312\site-packages\django\db\backends\base\base.py", line 298, in _commit
    with debug_transaction(self, "COMMIT"), self.wrap_database_errors:
  File "C:\Users\kevin\AppData\Roaming\Python\Python312\site-packages\django\db\utils.py", line 91, in __exit__
    raise dj_exc_value.with_traceback(traceback) from exc_value
  File "C:\Users\kevin\AppData\Roaming\Python\Python312\site-packages\django\db\backends\base\base.py", line 299, in _commit
    return self.connection.commit()
           ^^^^^^^^^^^^^^^^^^^^^^^^
django.db.utils.IntegrityError: FOREIGN KEY constraint failed
ERROR 2024-10-29 22:06:30,318 basehttp "POST /app/auth/user/add/ HTTP/1.1" 500 158609
ERROR 2024-10-29 22:09:39,436 log Internal Server Error: /app/auth/user/add/
Traceback (most recent call last):
  File "C:\Users\kevin\AppData\Roaming\Python\Python312\site-packages\django\db\backends\base\base.py", line 299, in _commit
    return self.connection.commit()
           ^^^^^^^^^^^^^^^^^^^^^^^^
sqlite3.IntegrityError: FOREIGN KEY constraint failed

The above exception was the direct cause of the following exception:

Traceback (most recent call last):
  File "C:\Users\kevin\AppData\Roaming\Python\Python312\site-packages\django\core\handlers\exception.py", line 55, in inner
    response = get_response(request)
               ^^^^^^^^^^^^^^^^^^^^^
  File "C:\Users\kevin\AppData\Roaming\Python\Python312\site-packages\django\core\handlers\base.py", line 197, in _get_response
    response = wrapped_callback(request, *callback_args, **callback_kwargs)
               ^^^^^^^^^^^^^^^^^^^^^^^^^^^^^^^^^^^^^^^^^^^^^^^^^^^^^^^^^^^^
  File "C:\Users\kevin\AppData\Roaming\Python\Python312\site-packages\django\contrib\admin\options.py", line 716, in wrapper
    return self.admin_site.admin_view(view)(*args, **kwargs)
           ^^^^^^^^^^^^^^^^^^^^^^^^^^^^^^^^^^^^^^^^^^^^^^^^^
  File "C:\Users\kevin\AppData\Roaming\Python\Python312\site-packages\django\utils\decorators.py", line 188, in _view_wrapper
    result = _process_exception(request, e)
             ^^^^^^^^^^^^^^^^^^^^^^^^^^^^^^
  File "C:\Users\kevin\AppData\Roaming\Python\Python312\site-packages\django\utils\decorators.py", line 186, in _view_wrapper
    response = view_func(request, *args, **kwargs)
               ^^^^^^^^^^^^^^^^^^^^^^^^^^^^^^^^^^^
  File "C:\Users\kevin\AppData\Roaming\Python\Python312\site-packages\django\views\decorators\cache.py", line 80, in _view_wrapper
    response = view_func(request, *args, **kwargs)
               ^^^^^^^^^^^^^^^^^^^^^^^^^^^^^^^^^^^
  File "C:\Users\kevin\AppData\Roaming\Python\Python312\site-packages\django\contrib\admin\sites.py", line 240, in inner
    return view(request, *args, **kwargs)
           ^^^^^^^^^^^^^^^^^^^^^^^^^^^^^^
  File "C:\Users\kevin\AppData\Roaming\Python\Python312\site-packages\django\utils\decorators.py", line 48, in _wrapper
    return bound_method(*args, **kwargs)
           ^^^^^^^^^^^^^^^^^^^^^^^^^^^^^
  File "C:\Users\kevin\AppData\Roaming\Python\Python312\site-packages\django\views\decorators\debug.py", line 143, in sensitive_post_parameters_wrapper
    return view(request, *args, **kwargs)
           ^^^^^^^^^^^^^^^^^^^^^^^^^^^^^^
  File "C:\Users\kevin\AppData\Roaming\Python\Python312\site-packages\django\utils\decorators.py", line 48, in _wrapper
    return bound_method(*args, **kwargs)
           ^^^^^^^^^^^^^^^^^^^^^^^^^^^^^
  File "C:\Users\kevin\AppData\Roaming\Python\Python312\site-packages\django\utils\decorators.py", line 188, in _view_wrapper
    result = _process_exception(request, e)
             ^^^^^^^^^^^^^^^^^^^^^^^^^^^^^^
  File "C:\Users\kevin\AppData\Roaming\Python\Python312\site-packages\django\utils\decorators.py", line 186, in _view_wrapper
    response = view_func(request, *args, **kwargs)
               ^^^^^^^^^^^^^^^^^^^^^^^^^^^^^^^^^^^
  File "C:\Users\kevin\AppData\Roaming\Python\Python312\site-packages\django\contrib\auth\admin.py", line 120, in add_view
    with transaction.atomic(using=router.db_for_write(self.model)):
  File "C:\Users\kevin\AppData\Roaming\Python\Python312\site-packages\django\db\transaction.py", line 263, in __exit__
    connection.commit()
  File "C:\Users\kevin\AppData\Roaming\Python\Python312\site-packages\django\utils\asyncio.py", line 26, in inner
    return func(*args, **kwargs)
           ^^^^^^^^^^^^^^^^^^^^^
  File "C:\Users\kevin\AppData\Roaming\Python\Python312\site-packages\django\db\backends\base\base.py", line 323, in commit
    self._commit()
  File "C:\Users\kevin\AppData\Roaming\Python\Python312\site-packages\django\db\backends\base\base.py", line 298, in _commit
    with debug_transaction(self, "COMMIT"), self.wrap_database_errors:
  File "C:\Users\kevin\AppData\Roaming\Python\Python312\site-packages\django\db\utils.py", line 91, in __exit__
    raise dj_exc_value.with_traceback(traceback) from exc_value
  File "C:\Users\kevin\AppData\Roaming\Python\Python312\site-packages\django\db\backends\base\base.py", line 299, in _commit
    return self.connection.commit()
           ^^^^^^^^^^^^^^^^^^^^^^^^
django.db.utils.IntegrityError: FOREIGN KEY constraint failed
ERROR 2024-10-29 22:09:39,440 basehttp "POST /app/auth/user/add/ HTTP/1.1" 500 158610
ERROR 2024-10-29 22:12:49,469 log Internal Server Error: /app/auth/user/add/
Traceback (most recent call last):
  File "C:\Users\kevin\AppData\Roaming\Python\Python312\site-packages\django\db\utils.py", line 98, in inner
    return func(*args, **kwargs)
           ^^^^^^^^^^^^^^^^^^^^^
sqlite3.IntegrityError: FOREIGN KEY constraint failed

The above exception was the direct cause of the following exception:

Traceback (most recent call last):
  File "C:\Users\kevin\AppData\Roaming\Python\Python312\site-packages\django\core\handlers\exception.py", line 55, in inner
    response = get_response(request)
               ^^^^^^^^^^^^^^^^^^^^^
  File "C:\Users\kevin\AppData\Roaming\Python\Python312\site-packages\django\core\handlers\base.py", line 197, in _get_response
    response = wrapped_callback(request, *callback_args, **callback_kwargs)
               ^^^^^^^^^^^^^^^^^^^^^^^^^^^^^^^^^^^^^^^^^^^^^^^^^^^^^^^^^^^^
  File "C:\Users\kevin\AppData\Roaming\Python\Python312\site-packages\django\contrib\admin\options.py", line 716, in wrapper
    return self.admin_site.admin_view(view)(*args, **kwargs)
           ^^^^^^^^^^^^^^^^^^^^^^^^^^^^^^^^^^^^^^^^^^^^^^^^^
  File "C:\Users\kevin\AppData\Roaming\Python\Python312\site-packages\django\utils\decorators.py", line 188, in _view_wrapper
    result = _process_exception(request, e)
             ^^^^^^^^^^^^^^^^^^^^^^^^^^^^^^
  File "C:\Users\kevin\AppData\Roaming\Python\Python312\site-packages\django\utils\decorators.py", line 186, in _view_wrapper
    response = view_func(request, *args, **kwargs)
               ^^^^^^^^^^^^^^^^^^^^^^^^^^^^^^^^^^^
  File "C:\Users\kevin\AppData\Roaming\Python\Python312\site-packages\django\views\decorators\cache.py", line 80, in _view_wrapper
    response = view_func(request, *args, **kwargs)
               ^^^^^^^^^^^^^^^^^^^^^^^^^^^^^^^^^^^
  File "C:\Users\kevin\AppData\Roaming\Python\Python312\site-packages\django\contrib\admin\sites.py", line 240, in inner
    return view(request, *args, **kwargs)
           ^^^^^^^^^^^^^^^^^^^^^^^^^^^^^^
  File "C:\Users\kevin\AppData\Roaming\Python\Python312\site-packages\django\utils\decorators.py", line 48, in _wrapper
    return bound_method(*args, **kwargs)
           ^^^^^^^^^^^^^^^^^^^^^^^^^^^^^
  File "C:\Users\kevin\AppData\Roaming\Python\Python312\site-packages\django\views\decorators\debug.py", line 143, in sensitive_post_parameters_wrapper
    return view(request, *args, **kwargs)
           ^^^^^^^^^^^^^^^^^^^^^^^^^^^^^^
  File "C:\Users\kevin\AppData\Roaming\Python\Python312\site-packages\django\utils\decorators.py", line 48, in _wrapper
    return bound_method(*args, **kwargs)
           ^^^^^^^^^^^^^^^^^^^^^^^^^^^^^
  File "C:\Users\kevin\AppData\Roaming\Python\Python312\site-packages\django\utils\decorators.py", line 188, in _view_wrapper
    result = _process_exception(request, e)
             ^^^^^^^^^^^^^^^^^^^^^^^^^^^^^^
  File "C:\Users\kevin\AppData\Roaming\Python\Python312\site-packages\django\utils\decorators.py", line 186, in _view_wrapper
    response = view_func(request, *args, **kwargs)
               ^^^^^^^^^^^^^^^^^^^^^^^^^^^^^^^^^^^
  File "C:\Users\kevin\AppData\Roaming\Python\Python312\site-packages\django\contrib\auth\admin.py", line 120, in add_view
    with transaction.atomic(using=router.db_for_write(self.model)):
  File "C:\Users\kevin\AppData\Roaming\Python\Python312\site-packages\django\db\transaction.py", line 307, in __exit__
    connection.set_autocommit(True)
  File "C:\Users\kevin\AppData\Roaming\Python\Python312\site-packages\django\db\backends\base\base.py", line 487, in set_autocommit
    self.run_and_clear_commit_hooks()
  File "C:\Users\kevin\AppData\Roaming\Python\Python312\site-packages\django\db\backends\base\base.py", line 765, in run_and_clear_commit_hooks
    func()
  File "C:\Users\kevin\Desktop\pantutienda-adp\agenda\signals.py", line 11, in <lambda>
    transaction.on_commit(lambda: Cliente.objects.create(usuario=instance))
                                  ^^^^^^^^^^^^^^^^^^^^^^^^^^^^^^^^^^^^^^^^
  File "C:\Users\kevin\AppData\Roaming\Python\Python312\site-packages\django\db\models\manager.py", line 87, in manager_method
    return getattr(self.get_queryset(), name)(*args, **kwargs)
           ^^^^^^^^^^^^^^^^^^^^^^^^^^^^^^^^^^^^^^^^^^^^^^^^^^^
  File "C:\Users\kevin\AppData\Roaming\Python\Python312\site-packages\django\db\models\query.py", line 679, in create
    obj.save(force_insert=True, using=self.db)
  File "C:\Users\kevin\AppData\Roaming\Python\Python312\site-packages\django\db\models\base.py", line 822, in save
    self.save_base(
  File "C:\Users\kevin\AppData\Roaming\Python\Python312\site-packages\django\db\models\base.py", line 909, in save_base
    updated = self._save_table(
              ^^^^^^^^^^^^^^^^^
  File "C:\Users\kevin\AppData\Roaming\Python\Python312\site-packages\django\db\models\base.py", line 1071, in _save_table
    results = self._do_insert(
              ^^^^^^^^^^^^^^^^
  File "C:\Users\kevin\AppData\Roaming\Python\Python312\site-packages\django\db\models\base.py", line 1112, in _do_insert
    return manager._insert(
           ^^^^^^^^^^^^^^^^
  File "C:\Users\kevin\AppData\Roaming\Python\Python312\site-packages\django\db\models\manager.py", line 87, in manager_method
    return getattr(self.get_queryset(), name)(*args, **kwargs)
           ^^^^^^^^^^^^^^^^^^^^^^^^^^^^^^^^^^^^^^^^^^^^^^^^^^^
  File "C:\Users\kevin\AppData\Roaming\Python\Python312\site-packages\django\db\models\query.py", line 1847, in _insert
    return query.get_compiler(using=using).execute_sql(returning_fields)
           ^^^^^^^^^^^^^^^^^^^^^^^^^^^^^^^^^^^^^^^^^^^^^^^^^^^^^^^^^^^^^
  File "C:\Users\kevin\AppData\Roaming\Python\Python312\site-packages\django\db\models\sql\compiler.py", line 1835, in execute_sql
    self.connection.ops.fetch_returned_insert_columns(
  File "C:\Users\kevin\AppData\Roaming\Python\Python312\site-packages\django\db\backends\base\operations.py", line 216, in fetch_returned_insert_columns
    return cursor.fetchone()
           ^^^^^^^^^^^^^^^^^
  File "C:\Users\kevin\AppData\Roaming\Python\Python312\site-packages\django\db\utils.py", line 97, in inner
    with self:
  File "C:\Users\kevin\AppData\Roaming\Python\Python312\site-packages\django\db\utils.py", line 91, in __exit__
    raise dj_exc_value.with_traceback(traceback) from exc_value
  File "C:\Users\kevin\AppData\Roaming\Python\Python312\site-packages\django\db\utils.py", line 98, in inner
    return func(*args, **kwargs)
           ^^^^^^^^^^^^^^^^^^^^^
django.db.utils.IntegrityError: FOREIGN KEY constraint failed
ERROR 2024-10-29 22:12:49,476 basehttp "POST /app/auth/user/add/ HTTP/1.1" 500 215701
